Workbook

Sheet Setup
A1: Short-Term Rental Profit Tracker
A2: Manual entry, no sync. Fill your properties in once — every other tab reads from here.
B4: MANUAL ENTRY — this file does not log in to any platform, import calendars or sync with anything. You type eight cells per booking; fees, cleaning, laundry, consumables, net and the whole turnover plan calculate themselves.
B6: START HERE — four steps
B7: 1 · Overwrite the three example properties below with your own. Column L warns you about duplicate names and about characters that break lookups.
B8: 2 · Add your cleaning team in the second table (row 40) — those names become the dropdown in the Cleaning tab.
B9: 3 · Bookings tab: one row per stay. Property, platform, status, guest, check-in, check-out, guests, gross booking value. That is the whole job.
B10: 4 · Dashboard: pick a year and a month and read what each property actually earned. Never type anything else on that tab.
B12: THE THREE RULES THIS FILE COUNTS BY
B13: · Money (booking value, fees, cleaning, consumables) is counted in the month a stay CHECKS OUT. Nights and occupancy are split across months by the actual dates, so a stay over a month border shows nights in both months but money in one.
B14: · Gross booking value = the total the guest paid, including any cleaning fee you charged them. What you pay your cleaner is a cost — it belongs in column E below, never in the Bookings tab.
B15: · Fixed monthly costs (column J) run in EVERY month you look at, including months before you owned the place. Never log them again in the Costs tab; clear the field before you check earlier months.
B17: START EMPTY IN 30 SECONDS — in Bookings clear B5:G16, I5:K16 and S5:S16 (white cells only), in Cleaning clear J5:L16, in Costs clear B5:H9, then overwrite the three example properties below. Nothing else.
B18: GREY CELLS CALCULATE THEMSELVES — never clear or type in one, and leave the numbered # column alone. Deleted a grey cell by accident? Undo with Ctrl+Z / Cmd+Z, or copy the same cell from the row below and paste it back.
... B21: CURRENCY-NEUTRAL — no currency symbol is hard-coded. Select the number columns and apply your own currency format in one click.
A23: YOUR PROPERTIES — fill this in first
A24: Property name | B24: City / label | C24: Bedrooms | D24: Platform fee % (default) | E24: Cleaner pay per turnover | F24: Laundry per turnover | G24: Consumables per stay | H24: Consumables per night | I24: Linen sets per turnover | J24: Fixed monthly costs | K24: Notes | L24: Check
A25: Riverside Loft | B25: Porto | C25: 1 | D25: 0.03 | E25: 45 | F25: 12 | G25: 6 | H25: 1.5 | I25: 2 | J25: 62 | K25: EXAMPLE — overwrite with your own | L25: =IF($A25="","—",IF(COUNTIF($A$25:$A$36,$A25)>1,"⚠ duplicate name",IF(SUMPRODUCT(--ISNUMBER(FIND({"*";"?";"~"},$A25)))>0,"⚠ remove * ? ~ from the name","OK"))) -> OK
A26: Harbour Studio | B26: Porto | C26: 1 | D26: 0.15 | E26: 38 | F26: 9 | G26: 4.5 | H26: 1.2 | I26: 1 | J26: 48 | K26: EXAMPLE — overwrite with your own | L26: =IF($A26="","—",IF(COUNTIF($A$25:$A$36,$A26)>1,"⚠ duplicate name",IF(SUMPRODUCT(--ISNUMBER(FIND({"*";"?";"~"},$A26)))>0,"⚠ remove * ? ~ from the name","OK"))) -> OK
A27: Garden Cottage | B27: Braga | C27: 2 | D27: 0.08 | E27: 60 | F27: 18 | G27: 8 | H27: 2 | I27: 3 | J27: 74 | K27: EXAMPLE — overwrite with your own | L27: =IF($A27="","—",IF(COUNTIF($A$25:$A$36,$A27)>1,"⚠ duplicate name",IF(SUMPRODUCT(--ISNUMBER(FIND({"*";"?";"~"},$A27)))>0,"⚠ remove * ? ~ from the name","OK"))) -> OK
L28: =IF($A28="","—",IF(COUNTIF($A$25:$A$36,$A28)>1,"⚠ duplicate name",IF(SUMPRODUCT(--ISNUMBER(FIND({"*";"?";"~"},$A28)))>0,"⚠ remove * ? ~ from the name","OK"))) -> —
L29: =IF($A29="","—",IF(COUNTIF($A$25:$A$36,$A29)>1,"⚠ duplicate name",IF(SUMPRODUCT(--ISNUMBER(FIND({"*";"?";"~"},$A29)))>0,"⚠ remove * ? ~ from the name","OK"))) -> —
L30: =IF($A30="","—",IF(COUNTIF($A$25:$A$36,$A30)>1,"⚠ duplicate name",IF(SUMPRODUCT(--ISNUMBER(FIND({"*";"?";"~"},$A30)))>0,"⚠ remove * ? ~ from the name","OK"))) -> —
L31: =IF($A31="","—",IF(COUNTIF($A$25:$A$36,$A31)>1,"⚠ duplicate name",IF(SUMPRODUCT(--ISNUMBER(FIND({"*";"?";"~"},$A31)))>0,"⚠ remove * ? ~ from the name","OK"))) -> —
L32: =IF($A32="","—",IF(COUNTIF($A$25:$A$36,$A32)>1,"⚠ duplicate name",IF(SUMPRODUCT(--ISNUMBER(FIND({"*";"?";"~"},$A32)))>0,"⚠ remove * ? ~ from the name","OK"))) -> —
L33: =IF($A33="","—",IF(COUNTIF($A$25:$A$36,$A33)>1,"⚠ duplicate name",IF(SUMPRODUCT(--ISNUMBER(FIND({"*";"?";"~"},$A33)))>0,"⚠ remove * ? ~ from the name","OK"))) -> —
L34: =IF($A34="","—",IF(COUNTIF($A$25:$A$36,$A34)>1,"⚠ duplicate name",IF(SUMPRODUCT(--ISNUMBER(FIND({"*";"?";"~"},$A34)))>0,"⚠ remove * ? ~ from the name","OK"))) -> —
L35: =IF($A35="","—",IF(COUNTIF($A$25:$A$36,$A35)>1,"⚠ duplicate name",IF(SUMPRODUCT(--ISNUMBER(FIND({"*";"?";"~"},$A35)))>0,"⚠ remove * ? ~ from the name","OK"))) -> —
L36: =IF($A36="","—",IF(COUNTIF($A$25:$A$36,$A36)>1,"⚠ duplicate name",IF(SUMPRODUCT(--ISNUMBER(FIND({"*";"?";"~"},$A36)))>0,"⚠ remove * ? ~ from the name","OK"))) -> —
A38: CLEANING TEAM (feeds the dropdown in the Cleaning tab)
A39: Cleaner name | B39: Phone / contact | C39: Rate note
A40: Ana | B40: +351 000 000 000 | C40: EXAMPLE — overwrite
A41: Marco | B41: +351 000 000 000 | C41: EXAMPLE — overwrite
A42: CleanCo (agency) | B42: office@example.com | C42: EXAMPLE — overwrite
A43: Me (owner) | C43: EXAMPLE — overwrite
B49: GOOD TO KNOW
B50: Google Sheets: File ▸ Import ▸ Upload this file. Formulas, dropdowns and colours carry over. The Dashboard's write-protection is an Excel feature and does not — in Google Sheets just avoid typing on that tab.
B51: Excel: the Dashboard is write-protected so you cannot type over a formula by accident. Review ▸ Unprotect Sheet (no password) if you want to restyle it.
B52: Filtering and sorting: use the filter arrows in row 4 to filter. If you want to sort, select the whole table first (Bookings A4:W304, Cleaning A4:L304, 'data has header row') — never sort a single column on its own. The numbered # column keeps Bookings and Cleaning linked either way.
B53: More than 300 bookings? Select the last row of Bookings and drag it down, then do the same in Cleaning so both sheets stay the same length — and widen the ranges in the Dashboard formulas, which read rows 5–304 today.
...

Sheet Dashboard
A1: Dashboard — one month, every property side by side
A2: Pick a year and a month in the two white cells. Everything else on this tab calculates itself from Bookings, Cleaning and Costs. | O2: Period start | P2: =IFERROR(DATE($B$4,MATCH($D$4,Lists!$G$1:$G$12,0),1),DATE(YEAR(TODAY()),MONTH(TODAY()),1)) -> 46204
O3: Period end | P3: =IFERROR(DATE(YEAR($P$2),MONTH($P$2)+1,0),$P$2) -> 46234
A4: Year | B4: =IFERROR(YEAR(TODAY()),2025) -> 2026 | C4: Month | D4: =IFERROR(INDEX(Lists!$G$1:$G$12,MONTH(TODAY())),"January") -> July | F4: =IF(OR(NOT(ISNUMBER($P$2)),NOT(ISNUMBER($P$3))),"Pick a year in B4 and a month in D4.","Showing "&DAY($P$2)&" "&INDEX(Lists!$G$1:$G$12,MONTH($P$2))&" "&YEAR($P$2)&" to "&DAY($P$3)&" "&INDEX(Lists!$G$1:$G$12,MONTH($P$3))&" "&YEAR($P$3)&" · money is counted in the month a stay CHECKS OUT; nights are split by actual date") -> Showing 1 July 2026 to 31 July 2026 · money is counted in the month a stay CHECKS OUT; nights are split by actual date | O4: Days in month | P4: =IF(NOT(ISNUMBER($P$3)),"—",DAY($P$3)) -> 31
A6: Net (tracked costs only) | C6: Gross booking value | E6: Total tracked costs | G6: Occupancy | I6: Net per available night | K6: Cleanings still open
A7: =IF(NOT(ISNUMBER($L$23)),"—",$L$23) -> 2549.2 | C7: =IF(NOT(ISNUMBER($E$23)),"—",$E$23) -> 3890 | E7: =IF(NOT(ISNUMBER($K$23)),"—",$K$23) -> 1340.8 | G7: =IF(NOT(ISNUMBER($D$23)),"—",$D$23) -> 0.4 | I7: =IF(NOT(ISNUMBER($M$23)),"—",$M$23) -> 28.32 | K7: =IF(COUNTIFS(Cleaning!$D$5:$D$304,">="&$P$2,Cleaning!$D$5:$D$304,"<="&$P$3)=0,"—",IF(COUNTIFS(Cleaning!$D$5:$D$304,">="&$P$2,Cleaning!$D$5:$D$304,"<="&$P$3)-COUNTIFS(Cleaning!$D$5:$D$304,">="&$P$2,Cleaning!$D$5:$D$304,"<="&$P$3,Cleaning!$K$5:$K$304,"Done")=0,"All done ✓",COUNTIFS(Cleaning!$D$5:$D$304,">="&$P$2,Cleaning!$D$5:$D$304,"<="&$P$3)-COUNTIFS(Cleaning!$D$5:$D$304,">="&$P$2,Cleaning!$D$5:$D$304,"<="&$P$3,Cleaning!$K$5:$K$304,"Done"))) -> 1
A9: PER PROPERTY — selected month
A10: Property | B10: Nights booked | C10: Nights available | D10: Occupancy % | E10: Gross booking value | F10: Platform fees | G10: Cleaning & laundry | H10: Consumables | I10: Fixed monthly | J10: Other logged costs | K10: Total costs | L10: Net after tracked costs | M10: Net per available night
A11: =IF(Setup!$A25="","—",Setup!$A25) -> Riverside Loft | B11: =IF($A11="—","—",IF(SUMIFS(Bookings!$T$5:$T$304,Bookings!$B$5:$B$304,$A11)=0,"—",SUMIFS(Bookings!$T$5:$T$304,Bookings!$B$5:$B$304,$A11))) -> 16 | C11: =IF(OR($A11="—",NOT(ISNUMBER($P$4))),"—",$P$4-SUMIFS(Bookings!$U$5:$U$304,Bookings!$B$5:$B$304,$A11)) -> 31 | D11: =IFERROR(IF(OR($A11="—",NOT(ISNUMBER($C11)),$C11<=0),"—",IF(ISNUMBER($B11),$B11,0)/$C11),"—") -> 0.51612903 | E11: =IF($A11="—","—",IF(SUMIFS(Bookings!$W$5:$W$304,Bookings!$B$5:$B$304,$A11,Bookings!$G$5:$G$304,">="&$P$2,Bookings!$G$5:$G$304,"<="&$P$3)=0,"—",SUMIFS(Bookings!$W$5:$W$304,Bookings!$B$5:$B$304,$A11,Bookings!$G$5:$G$304,">="&$P$2,Bookings!$G$5:$G$304,"<="&$P$3))) -> 1935 | F11: =IF($A11="—","—",IF(SUMIFS(Bookings!$L$5:$L$304,Bookings!$B$5:$B$304,$A11,Bookings!$G$5:$G$304,">="&$P$2,Bookings!$G$5:$G$304,"<="&$P$3)=0,"—",SUMIFS(Bookings!$L$5:$L$304,Bookings!$B$5:$B$304,$A11,Bookings!$G$5:$G$304,">="&$P$2,Bookings!$G$5:$G$304,"<="&$P$3))) -> 66.65 | G11: =IF($A11="—","—",IF(SUMIFS(Bookings!$N$5:$N$304,Bookings!$B$5:$B$304,$A11,Bookings!$G$5:$G$304,">="&$P$2,Bookings!$G$5:$G$304,"<="&$P$3)+SUMIFS(Bookings!$O$5:$O$304,Bookings!$B$5:$B$304,$A11,Bookings!$G$5:$G$304,">="&$P$2,Bookings!$G$5:$G$304,"<="&$P$3)=0,"—",SUMIFS(Bookings!$N$5:$N$304,Bookings!$B$5:$B$304,$A11,Bookings!$G$5:$G$304,">="&$P$2,Bookings!$G$5:$G$304,"<="&$P$3)+SUMIFS(Bookings!$O$5:$O$304,Bookings!$B$5:$B$304,$A11,Bookings!$G$5:$G$304,">="&$P$2,Bookings!$G$5:$G$304,"<="&$P$3))) -> 228 | H11: =IF($A11="—","—",IF(SUMIFS(Bookings!$P$5:$P$304,Bookings!$B$5:$B$304,$A11,Bookings!$G$5:$G$304,">="&$P$2,Bookings!$G$5:$G$304,"<="&$P$3)=0,"—",SUMIFS(Bookings!$P$5:$P$304,Bookings!$B$5:$B$304,$A11,Bookings!$G$5:$G$304,">="&$P$2,Bookings!$G$5:$G$304,"<="&$P$3))) -> 49.5 | I11: =IF($A11="—","—",IFERROR(IF(INDEX(Setup!$J$25:$J$36,MATCH($A11,Setup!$A$25:$A$36,0))=0,"—",INDEX(Setup!$J$25:$J$36,MATCH($A11,Setup!$A$25:$A$36,0))),"—")) -> 62 | J11: =IF($A11="—","—",IF(SUMIFS(Costs!$F$5:$F$254,Costs!$C$5:$C$254,$A11,Costs!$B$5:$B$254,">="&$P$2,Costs!$B$5:$B$254,"<="&$P$3)=0,"—",SUMIFS(Costs!$F$5:$F$254,Costs!$C$5:$C$254,$A11,Costs!$B$5:$B$254,">="&$P$2,Costs!$B$5:$B$254,"<="&$P$3))) -> 148.5 | K11: =IF(OR($A11="—",COUNT($F11:$J11)=0),"—",ROUND(SUM($F11:$J11),2)) -> 554.65 | L11: =IF(OR($A11="—",COUNT($E11,$K11)=0),"—",ROUND(IF(ISNUMBER($E11),$E11,0)-IF(ISNUMBER($K11),$K11,0),2)) -> 1380.35 | M11: =IF(OR(NOT(ISNUMBER($L11)),NOT(ISNUMBER($C11)),$C11<=0),"—",ROUND($L11/$C11,2)) -> 44.53
A12: =IF(Setup!$A26="","—",Setup!$A26) -> Harbour Studio | B12: =IF($A12="—","—",IF(SUMIFS(Bookings!$T$5:$T$304,Bookings!$B$5:$B$304,$A12)=0,"—",SUMIFS(Bookings!$T$5:$T$304,Bookings!$B$5:$B$304,$A12))) -> 14 | C12: =IF(OR($A12="—",NOT(ISNUMBER($P$4))),"—",$P$4-SUMIFS(Bookings!$U$5:$U$304,Bookings!$B$5:$B$304,$A12)) -> 31 | D12: =IFERROR(IF(OR($A12="—",NOT(ISNUMBER($C12)),$C12<=0),"—",IF(ISNUMBER($B12),$B12,0)/$C12),"—") -> 0.4516129 | E12: =IF($A12="—","—",IF(SUMIFS(Bookings!$W$5:$W$304,Bookings!$B$5:$B$304,$A12,Bookings!$G$5:$G$304,">="&$P$2,Bookings!$G$5:$G$304,"<="&$P$3)=0,"—",SUMIFS(Bookings!$W$5:$W$304,Bookings!$B$5:$B$304,$A12,Bookings!$G$5:$G$304,">="&$P$2,Bookings!$G$5:$G$304,"<="&$P$3))) -> 1065 | F12: =IF($A12="—","—",IF(SUMIFS(Bookings!$L$5:$L$304,Bookings!$B$5:$B$304,$A12,Bookings!$G$5:$G$304,">="&$P$2,Bookings!$G$5:$G$304,"<="&$P$3)=0,"—",SUMIFS(Bookings!$L$5:$L$304,Bookings!$B$5:$B$304,$A12,Bookings!$G$5:$G$304,">="&$P$2,Bookings!$G$5:$G$304,"<="&$P$3))) -> 123.75 | G12: =IF($A12="—","—",IF(SUMIFS(Bookings!$N$5:$N$304,Bookings!$B$5:$B$304,$A12,Bookings!$G$5:$G$304,">="&$P$2,Bookings!$G$5:$G$304,"<="&$P$3)+SUMIFS(Bookings!$O$5:$O$304,Bookings!$B$5:$B$304,$A12,Bookings!$G$5:$G$304,">="&$P$2,Bookings!$G$5:$G$304,"<="&$P$3)=0,"—",SUMIFS(Bookings!$N$5:$N$304,Bookings!$B$5:$B$304,$A12,Bookings!$G$5:$G$304,">="&$P$2,Bookings!$G$5:$G$304,"<="&$P$3)+SUMIFS(Bookings!$O$5:$O$304,Bookings!$B$5:$B$304,$A12,Bookings!$G$5:$G$304,">="&$P$2,Bookings!$G$5:$G$304,"<="&$P$3))) -> 141 | H12: =IF($A12="—","—",IF(SUMIFS(Bookings!$P$5:$P$304,Bookings!$B$5:$B$304,$A12,Bookings!$G$5:$G$304,">="&$P$2,Bookings!$G$5:$G$304,"<="&$P$3)=0,"—",SUMIFS(Bookings!$P$5:$P$304,Bookings!$B$5:$B$304,$A12,Bookings!$G$5:$G$304,">="&$P$2,Bookings!$G$5:$G$304,"<="&$P$3))) -> 30.3 | I12: =IF($A12="—","—",IFERROR(IF(INDEX(Setup!$J$25:$J$36,MATCH($A12,Setup!$A$25:$A$36,0))=0,"—",INDEX(Setup!$J$25:$J$36,MATCH($A12,Setup!$A$25:$A$36,0))),"—")) -> 48 | J12: =IF($A12="—","—",IF(SUMIFS(Costs!$F$5:$F$254,Costs!$C$5:$C$254,$A12,Costs!$B$5:$B$254,">="&$P$2,Costs!$B$5:$B$254,"<="&$P$3)=0,"—",SUMIFS(Costs!$F$5:$F$254,Costs!$C$5:$C$254,$A12,Costs!$B$5:$B$254,">="&$P$2,Costs!$B$5:$B$254,"<="&$P$3))) -> 34.9 | K12: =IF(OR($A12="—",COUNT($F12:$J12)=0),"—",ROUND(SUM($F12:$J12),2)) -> 377.95 | L12: =IF(OR($A12="—",COUNT($E12,$K12)=0),"—",ROUND(IF(ISNUMBER($E12),$E12,0)-IF(ISNUMBER($K12),$K12,0),2)) -> 687.05 | M12: =IF(OR(NOT(ISNUMBER($L12)),NOT(ISNUMBER($C12)),$C12<=0),"—",ROUND($L12/$C12,2)) -> 22.16
A13: =IF(Setup!$A27="","—",Setup!$A27) -> Garden Cottage | B13: =IF($A13="—","—",IF(SUMIFS(Bookings!$T$5:$T$304,Bookings!$B$5:$B$304,$A13)=0,"—",SUMIFS(Bookings!$T$5:$T$304,Bookings!$B$5:$B$304,$A13))) -> 6 | C13: =IF(OR($A13="—",NOT(ISNUMBER($P$4))),"—",$P$4-SUMIFS(Bookings!$U$5:$U$304,Bookings!$B$5:$B$304,$A13)) -> 28 | D13: =IFERROR(IF(OR($A13="—",NOT(ISNUMBER($C13)),$C13<=0),"—",IF(ISNUMBER($B13),$B13,0)/$C13),"—") -> 0.21428571 | E13: =IF($A13="—","—",IF(SUMIFS(Bookings!$W$5:$W$304,Bookings!$B$5:$B$304,$A13,Bookings!$G$5:$G$304,">="&$P$2,Bookings!$G$5:$G$304,"<="&$P$3)=0,"—",SUMIFS(Bookings!$W$5:$W$304,Bookings!$B$5:$B$304,$A13,Bookings!$G$5:$G$304,">="&$P$2,Bookings!$G$5:$G$304,"<="&$P$3))) -> 890 | F13: =IF($A13="—","—",IF(SUMIFS(Bookings!$L$5:$L$304,Bookings!$B$5:$B$304,$A13,Bookings!$G$5:$G$304,">="&$P$2,Bookings!$G$5:$G$304,"<="&$P$3)=0,"—",SUMIFS(Bookings!$L$5:$L$304,Bookings!$B$5:$B$304,$A13,Bookings!$G$5:$G$304,">="&$P$2,Bookings!$G$5:$G$304,"<="&$P$3))) -> 71.2 | G13: =IF($A13="—","—",IF(SUMIFS(Bookings!$N$5:$N$304,Bookings!$B$5:$B$304,$A13,Bookings!$G$5:$G$304,">="&$P$2,Bookings!$G$5:$G$304,"<="&$P$3)+SUMIFS(Bookings!$O$5:$O$304,Bookings!$B$5:$B$304,$A13,Bookings!$G$5:$G$304,">="&$P$2,Bookings!$G$5:$G$304,"<="&$P$3)=0,"—",SUMIFS(Bookings!$N$5:$N$304,Bookings!$B$5:$B$304,$A13,Bookings!$G$5:$G$304,">="&$P$2,Bookings!$G$5:$G$304,"<="&$P$3)+SUMIFS(Bookings!$O$5:$O$304,Bookings!$B$5:$B$304,$A13,Bookings!$G$5:$G$304,">="&$P$2,Bookings!$G$5:$G$304,"<="&$P$3))) -> 156 | H13: =IF($A13="—","—",IF(SUMIFS(Bookings!$P$5:$P$304,Bookings!$B$5:$B$304,$A13,Bookings!$G$5:$G$304,">="&$P$2,Bookings!$G$5:$G$304,"<="&$P$3)=0,"—",SUMIFS(Bookings!$P$5:$P$304,Bookings!$B$5:$B$304,$A13,Bookings!$G$5:$G$304,">="&$P$2,Bookings!$G$5:$G$304,"<="&$P$3))) -> 20 | I13: =IF($A13="—","—",IFERROR(IF(INDEX(Setup!$J$25:$J$36,MATCH($A13,Setup!$A$25:$A$36,0))=0,"—",INDEX(Setup!$J$25:$J$36,MATCH($A13,Setup!$A$25:$A$36,0))),"—")) -> 74 | J13: =IF($A13="—","—",IF(SUMIFS(Costs!$F$5:$F$254,Costs!$C$5:$C$254,$A13,Costs!$B$5:$B$254,">="&$P$2,Costs!$B$5:$B$254,"<="&$P$3)=0,"—",SUMIFS(Costs!$F$5:$F$254,Costs!$C$5:$C$254,$A13,Costs!$B$5:$B$254,">="&$P$2,Costs!$B$5:$B$254,"<="&$P$3))) -> 87 | K13: =IF(OR($A13="—",COUNT($F13:$J13)=0),"—",ROUND(SUM($F13:$J13),2)) -> 408.2 | L13: =IF(OR($A13="—",COUNT($E13,$K13)=0),"—",ROUND(IF(ISNUMBER($E13),$E13,0)-IF(ISNUMBER($K13),$K13,0),2)) -> 481.8 | M13: =IF(OR(NOT(ISNUMBER($L13)),NOT(ISNUMBER($C13)),$C13<=0),"—",ROUND($L13/$C13,2)) -> 17.21
A14: =IF(Setup!$A28="","—",Setup!$A28) -> — | B14: =IF($A14="—","—",IF(SUMIFS(Bookings!$T$5:$T$304,Bookings!$B$5:$B$304,$A14)=0,"—",SUMIFS(Bookings!$T$5:$T$304,Bookings!$B$5:$B$304,$A14))) -> — | C14: =IF(OR($A14="—",NOT(ISNUMBER($P$4))),"—",$P$4-SUMIFS(Bookings!$U$5:$U$304,Bookings!$B$5:$B$304,$A14)) -> — | D14: =IFERROR(IF(OR($A14="—",NOT(ISNUMBER($C14)),$C14<=0),"—",IF(ISNUMBER($B14),$B14,0)/$C14),"—") -> — | E14: =IF($A14="—","—",IF(SUMIFS(Bookings!$W$5:$W$304,Bookings!$B$5:$B$304,$A14,Bookings!$G$5:$G$304,">="&$P$2,Bookings!$G$5:$G$304,"<="&$P$3)=0,"—",SUMIFS(Bookings!$W$5:$W$304,Bookings!$B$5:$B$304,$A14,Bookings!$G$5:$G$304,">="&$P$2,Bookings!$G$5:$G$304,"<="&$P$3))) -> — | F14: =IF($A14="—","—",IF(SUMIFS(Bookings!$L$5:$L$304,Bookings!$B$5:$B$304,$A14,Bookings!$G$5:$G$304,">="&$P$2,Bookings!$G$5:$G$304,"<="&$P$3)=0,"—",SUMIFS(Bookings!$L$5:$L$304,Bookings!$B$5:$B$304,$A14,Bookings!$G$5:$G$304,">="&$P$2,Bookings!$G$5:$G$304,"<="&$P$3))) -> — | G14: =IF($A14="—","—",IF(SUMIFS(Bookings!$N$5:$N$304,Bookings!$B$5:$B$304,$A14,Bookings!$G$5:$G$304,">="&$P$2,Bookings!$G$5:$G$304,"<="&$P$3)+SUMIFS(Bookings!$O$5:$O$304,Bookings!$B$5:$B$304,$A14,Bookings!$G$5:$G$304,">="&$P$2,Bookings!$G$5:$G$304,"<="&$P$3)=0,"—",SUMIFS(Bookings!$N$5:$N$304,Bookings!$B$5:$B$304,$A14,Bookings!$G$5:$G$304,">="&$P$2,Bookings!$G$5:$G$304,"<="&$P$3)+SUMIFS(Bookings!$O$5:$O$304,Bookings!$B$5:$B$304,$A14,Bookings!$G$5:$G$304,">="&$P$2,Bookings!$G$5:$G$304,"<="&$P$3))) -> — | H14: =IF($A14="—","—",IF(SUMIFS(Bookings!$P$5:$P$304,Bookings!$B$5:$B$304,$A14,Bookings!$G$5:$G$304,">="&$P$2,Bookings!$G$5:$G$304,"<="&$P$3)=0,"—",SUMIFS(Bookings!$P$5:$P$304,Bookings!$B$5:$B$304,$A14,Bookings!$G$5:$G$304,">="&$P$2,Bookings!$G$5:$G$304,"<="&$P$3))) -> — | I14: =IF($A14="—","—",IFERROR(IF(INDEX(Setup!$J$25:$J$36,MATCH($A14,Setup!$A$25:$A$36,0))=0,"—",INDEX(Setup!$J$25:$J$36,MATCH($A14,Setup!$A$25:$A$36,0))),"—")) -> — | J14: =IF($A14="—","—",IF(SUMIFS(Costs!$F$5:$F$254,Costs!$C$5:$C$254,$A14,Costs!$B$5:$B$254,">="&$P$2,Costs!$B$5:$B$254,"<="&$P$3)=0,"—",SUMIFS(Costs!$F$5:$F$254,Costs!$C$5:$C$254,$A14,Costs!$B$5:$B$254,">="&$P$2,Costs!$B$5:$B$254,"<="&$P$3))) -> — | K14: =IF(OR($A14="—",COUNT($F14:$J14)=0),"—",ROUND(SUM($F14:$J14),2)) -> — | L14: =IF(OR($A14="—",COUNT($E14,$K14)=0),"—",ROUND(IF(ISNUMBER($E14),$E14,0)-IF(ISNUMBER($K14),$K14,0),2)) -> — | M14: =IF(OR(NOT(ISNUMBER($L14)),NOT(ISNUMBER($C14)),$C14<=0),"—",ROUND($L14/$C14,2)) -> —
A15: =IF(Setup!$A29="","—",Setup!$A29) -> — | B15: =IF($A15="—","—",IF(SUMIFS(Bookings!$T$5:$T$304,Bookings!$B$5:$B$304,$A15)=0,"—",SUMIFS(Bookings!$T$5:$T$304,Bookings!$B$5:$B$304,$A15))) -> — | C15: =IF(OR($A15="—",NOT(ISNUMBER($P$4))),"—",$P$4-SUMIFS(Bookings!$U$5:$U$304,Bookings!$B$5:$B$304,$A15)) -> — | D15: =IFERROR(IF(OR($A15="—",NOT(ISNUMBER($C15)),$C15<=0),"—",IF(ISNUMBER($B15),$B15,0)/$C15),"—") -> — | E15: =IF($A15="—","—",IF(SUMIFS(Bookings!$W$5:$W$304,Bookings!$B$5:$B$304,$A15,Bookings!$G$5:$G$304,">="&$P$2,Bookings!$G$5:$G$304,"<="&$P$3)=0,"—",SUMIFS(Bookings!$W$5:$W$304,Bookings!$B$5:$B$304,$A15,Bookings!$G$5:$G$304,">="&$P$2,Bookings!$G$5:$G$304,"<="&$P$3))) -> — | F15: =IF($A15="—","—",IF(SUMIFS(Bookings!$L$5:$L$304,Bookings!$B$5:$B$304,$A15,Bookings!$G$5:$G$304,">="&$P$2,Bookings!$G$5:$G$304,"<="&$P$3)=0,"—",SUMIFS(Bookings!$L$5:$L$304,Bookings!$B$5:$B$304,$A15,Bookings!$G$5:$G$304,">="&$P$2,Bookings!$G$5:$G$304,"<="&$P$3))) -> — | G15: =IF($A15="—","—",IF(SUMIFS(Bookings!$N$5:$N$304,Bookings!$B$5:$B$304,$A15,Bookings!$G$5:$G$304,">="&$P$2,Bookings!$G$5:$G$304,"<="&$P$3)+SUMIFS(Bookings!$O$5:$O$304,Bookings!$B$5:$B$304,$A15,Bookings!$G$5:$G$304,">="&$P$2,Bookings!$G$5:$G$304,"<="&$P$3)=0,"—",SUMIFS(Bookings!$N$5:$N$304,Bookings!$B$5:$B$304,$A15,Bookings!$G$5:$G$304,">="&$P$2,Bookings!$G$5:$G$304,"<="&$P$3)+SUMIFS(Bookings!$O$5:$O$304,Bookings!$B$5:$B$304,$A15,Bookings!$G$5:$G$304,">="&$P$2,Bookings!$G$5:$G$304,"<="&$P$3))) -> — | H15: =IF($A15="—","—",IF(SUMIFS(Bookings!$P$5:$P$304,Bookings!$B$5:$B$304,$A15,Bookings!$G$5:$G$304,">="&$P$2,Bookings!$G$5:$G$304,"<="&$P$3)=0,"—",SUMIFS(Bookings!$P$5:$P$304,Bookings!$B$5:$B$304,$A15,Bookings!$G$5:$G$304,">="&$P$2,Bookings!$G$5:$G$304,"<="&$P$3))) -> — | I15: =IF($A15="—","—",IFERROR(IF(INDEX(Setup!$J$25:$J$36,MATCH($A15,Setup!$A$25:$A$36,0))=0,"—",INDEX(Setup!$J$25:$J$36,MATCH($A15,Setup!$A$25:$A$36,0))),"—")) -> — | J15: =IF($A15="—","—",IF(SUMIFS(Costs!$F$5:$F$254,Costs!$C$5:$C$254,$A15,Costs!$B$5:$B$254,">="&$P$2,Costs!$B$5:$B$254,"<="&$P$3)=0,"—",SUMIFS(Costs!$F$5:$F$254,Costs!$C$5:$C$254,$A15,Costs!$B$5:$B$254,">="&$P$2,Costs!$B$5:$B$254,"<="&$P$3))) -> — | K15: =IF(OR($A15="—",COUNT($F15:$J15)=0),"—",ROUND(SUM($F15:$J15),2)) -> — | L15: =IF(OR($A15="—",COUNT($E15,$K15)=0),"—",ROUND(IF(ISNUMBER($E15),$E15,0)-IF(ISNUMBER($K15),$K15,0),2)) -> — | M15: =IF(OR(NOT(ISNUMBER($L15)),NOT(ISNUMBER($C15)),$C15<=0),"—",ROUND($L15/$C15,2)) -> —
A16: =IF(Setup!$A30="","—",Setup!$A30) -> — | B16: =IF($A16="—","—",IF(SUMIFS(Bookings!$T$5:$T$304,Bookings!$B$5:$B$304,$A16)=0,"—",SUMIFS(Bookings!$T$5:$T$304,Bookings!$B$5:$B$304,$A16))) -> — | C16: =IF(OR($A16="—",NOT(ISNUMBER($P$4))),"—",$P$4-SUMIFS(Bookings!$U$5:$U$304,Bookings!$B$5:$B$304,$A16)) -> — | D16: =IFERROR(IF(OR($A16="—",NOT(ISNUMBER($C16)),$C16<=0),"—",IF(ISNUMBER($B16),$B16,0)/$C16),"—") -> — | E16: =IF($A16="—","—",IF(SUMIFS(Bookings!$W$5:$W$304,Bookings!$B$5:$B$304,$A16,Bookings!$G$5:$G$304,">="&$P$2,Bookings!$G$5:$G$304,"<="&$P$3)=0,"—",SUMIFS(Bookings!$W$5:$W$304,Bookings!$B$5:$B$304,$A16,Bookings!$G$5:$G$304,">="&$P$2,Bookings!$G$5:$G$304,"<="&$P$3))) -> — | F16: =IF($A16="—","—",IF(SUMIFS(Bookings!$L$5:$L$304,Bookings!$B$5:$B$304,$A16,Bookings!$G$5:$G$304,">="&$P$2,Bookings!$G$5:$G$304,"<="&$P$3)=0,"—",SUMIFS(Bookings!$L$5:$L$304,Bookings!$B$5:$B$304,$A16,Bookings!$G$5:$G$304,">="&$P$2,Bookings!$G$5:$G$304,"<="&$P$3))) -> — | G16: =IF($A16="—","—",IF(SUMIFS(Bookings!$N$5:$N$304,Bookings!$B$5:$B$304,$A16,Bookings!$G$5:$G$304,">="&$P$2,Bookings!$G$5:$G$304,"<="&$P$3)+SUMIFS(Bookings!$O$5:$O$304,Bookings!$B$5:$B$304,$A16,Bookings!$G$5:$G$304,">="&$P$2,Bookings!$G$5:$G$304,"<="&$P$3)=0,"—",SUMIFS(Bookings!$N$5:$N$304,Bookings!$B$5:$B$304,$A16,Bookings!$G$5:$G$304,">="&$P$2,Bookings!$G$5:$G$304,"<="&$P$3)+SUMIFS(Bookings!$O$5:$O$304,Bookings!$B$5:$B$304,$A16,Bookings!$G$5:$G$304,">="&$P$2,Bookings!$G$5:$G$304,"<="&$P$3))) -> — | H16: =IF($A16="—","—",IF(SUMIFS(Bookings!$P$5:$P$304,Bookings!$B$5:$B$304,$A16,Bookings!$G$5:$G$304,">="&$P$2,Bookings!$G$5:$G$304,"<="&$P$3)=0,"—",SUMIFS(Bookings!$P$5:$P$304,Bookings!$B$5:$B$304,$A16,Bookings!$G$5:$G$304,">="&$P$2,Bookings!$G$5:$G$304,"<="&$P$3))) -> — | I16: =IF($A16="—","—",IFERROR(IF(INDEX(Setup!$J$25:$J$36,MATCH($A16,Setup!$A$25:$A$36,0))=0,"—",INDEX(Setup!$J$25:$J$36,MATCH($A16,Setup!$A$25:$A$36,0))),"—")) -> — | J16: =IF($A16="—","—",IF(SUMIFS(Costs!$F$5:$F$254,Costs!$C$5:$C$254,$A16,Costs!$B$5:$B$254,">="&$P$2,Costs!$B$5:$B$254,"<="&$P$3)=0,"—",SUMIFS(Costs!$F$5:$F$254,Costs!$C$5:$C$254,$A16,Costs!$B$5:$B$254,">="&$P$2,Costs!$B$5:$B$254,"<="&$P$3))) -> — | K16: =IF(OR($A16="—",COUNT($F16:$J16)=0),"—",ROUND(SUM($F16:$J16),2)) -> — | L16: =IF(OR($A16="—",COUNT($E16,$K16)=0),"—",ROUND(IF(ISNUMBER($E16),$E16,0)-IF(ISNUMBER($K16),$K16,0),2)) -> — | M16: =IF(OR(NOT(ISNUMBER($L16)),NOT(ISNUMBER($C16)),$C16<=0),"—",ROUND($L16/$C16,2)) -> —
A17: =IF(Setup!$A31="","—",Setup!$A31) -> — | B17: =IF($A17="—","—",IF(SUMIFS(Bookings!$T$5:$T$304,Bookings!$B$5:$B$304,$A17)=0,"—",SUMIFS(Bookings!$T$5:$T$304,Bookings!$B$5:$B$304,$A17))) -> — | C17: =IF(OR($A17="—",NOT(ISNUMBER($P$4))),"—",$P$4-SUMIFS(Bookings!$U$5:$U$304,Bookings!$B$5:$B$304,$A17)) -> — | D17: =IFERROR(IF(OR($A17="—",NOT(ISNUMBER($C17)),$C17<=0),"—",IF(ISNUMBER($B17),$B17,0)/$C17),"—") -> — | E17: =IF($A17="—","—",IF(SUMIFS(Bookings!$W$5:$W$304,Bookings!$B$5:$B$304,$A17,Bookings!$G$5:$G$304,">="&$P$2,Bookings!$G$5:$G$304,"<="&$P$3)=0,"—",SUMIFS(Bookings!$W$5:$W$304,Bookings!$B$5:$B$304,$A17,Bookings!$G$5:$G$304,">="&$P$2,Bookings!$G$5:$G$304,"<="&$P$3))) -> — | F17: =IF($A17="—","—",IF(SUMIFS(Bookings!$L$5:$L$304,Bookings!$B$5:$B$304,$A17,Bookings!$G$5:$G$304,">="&$P$2,Bookings!$G$5:$G$304,"<="&$P$3)=0,"—",SUMIFS(Bookings!$L$5:$L$304,Bookings!$B$5:$B$304,$A17,Bookings!$G$5:$G$304,">="&$P$2,Bookings!$G$5:$G$304,"<="&$P$3))) -> — | G17: =IF($A17="—","—",IF(SUMIFS(Bookings!$N$5:$N$304,Bookings!$B$5:$B$304,$A17,Bookings!$G$5:$G$304,">="&$P$2,Bookings!$G$5:$G$304,"<="&$P$3)+SUMIFS(Bookings!$O$5:$O$304,Bookings!$B$5:$B$304,$A17,Bookings!$G$5:$G$304,">="&$P$2,Bookings!$G$5:$G$304,"<="&$P$3)=0,"—",SUMIFS(Bookings!$N$5:$N$304,Bookings!$B$5:$B$304,$A17,Bookings!$G$5:$G$304,">="&$P$2,Bookings!$G$5:$G$304,"<="&$P$3)+SUMIFS(Bookings!$O$5:$O$304,Bookings!$B$5:$B$304,$A17,Bookings!$G$5:$G$304,">="&$P$2,Bookings!$G$5:$G$304,"<="&$P$3))) -> — | H17: =IF($A17="—","—",IF(SUMIFS(Bookings!$P$5:$P$304,Bookings!$B$5:$B$304,$A17,Bookings!$G$5:$G$304,">="&$P$2,Bookings!$G$5:$G$304,"<="&$P$3)=0,"—",SUMIFS(Bookings!$P$5:$P$304,Bookings!$B$5:$B$304,$A17,Bookings!$G$5:$G$304,">="&$P$2,Bookings!$G$5:$G$304,"<="&$P$3))) -> — | I17: =IF($A17="—","—",IFERROR(IF(INDEX(Setup!$J$25:$J$36,MATCH($A17,Setup!$A$25:$A$36,0))=0,"—",INDEX(Setup!$J$25:$J$36,MATCH($A17,Setup!$A$25:$A$36,0))),"—")) -> — | J17: =IF($A17="—","—",IF(SUMIFS(Costs!$F$5:$F$254,Costs!$C$5:$C$254,$A17,Costs!$B$5:$B$254,">="&$P$2,Costs!$B$5:$B$254,"<="&$P$3)=0,"—",SUMIFS(Costs!$F$5:$F$254,Costs!$C$5:$C$254,$A17,Costs!$B$5:$B$254,">="&$P$2,Costs!$B$5:$B$254,"<="&$P$3))) -> — | K17: =IF(OR($A17="—",COUNT($F17:$J17)=0),"—",ROUND(SUM($F17:$J17),2)) -> — | L17: =IF(OR($A17="—",COUNT($E17,$K17)=0),"—",ROUND(IF(ISNUMBER($E17),$E17,0)-IF(ISNUMBER($K17),$K17,0),2)) -> — | M17: =IF(OR(NOT(ISNUMBER($L17)),NOT(ISNUMBER($C17)),$C17<=0),"—",ROUND($L17/$C17,2)) -> —
A18: =IF(Setup!$A32="","—",Setup!$A32) -> — | B18: =IF($A18="—","—",IF(SUMIFS(Bookings!$T$5:$T$304,Bookings!$B$5:$B$304,$A18)=0,"—",SUMIFS(Bookings!$T$5:$T$304,Bookings!$B$5:$B$304,$A18))) -> — | C18: =IF(OR($A18="—",NOT(ISNUMBER($P$4))),"—",$P$4-SUMIFS(Bookings!$U$5:$U$304,Bookings!$B$5:$B$304,$A18)) -> — | D18: =IFERROR(IF(OR($A18="—",NOT(ISNUMBER($C18)),$C18<=0),"—",IF(ISNUMBER($B18),$B18,0)/$C18),"—") -> — | E18: =IF($A18="—","—",IF(SUMIFS(Bookings!$W$5:$W$304,Bookings!$B$5:$B$304,$A18,Bookings!$G$5:$G$304,">="&$P$2,Bookings!$G$5:$G$304,"<="&$P$3)=0,"—",SUMIFS(Bookings!$W$5:$W$304,Bookings!$B$5:$B$304,$A18,Bookings!$G$5:$G$304,">="&$P$2,Bookings!$G$5:$G$304,"<="&$P$3))) -> — | F18: =IF($A18="—","—",IF(SUMIFS(Bookings!$L$5:$L$304,Bookings!$B$5:$B$304,$A18,Bookings!$G$5:$G$304,">="&$P$2,Bookings!$G$5:$G$304,"<="&$P$3)=0,"—",SUMIFS(Bookings!$L$5:$L$304,Bookings!$B$5:$B$304,$A18,Bookings!$G$5:$G$304,">="&$P$2,Bookings!$G$5:$G$304,"<="&$P$3))) -> — | G18: =IF($A18="—","—",IF(SUMIFS(Bookings!$N$5:$N$304,Bookings!$B$5:$B$304,$A18,Bookings!$G$5:$G$304,">="&$P$2,Bookings!$G$5:$G$304,"<="&$P$3)+SUMIFS(Bookings!$O$5:$O$304,Bookings!$B$5:$B$304,$A18,Bookings!$G$5:$G$304,">="&$P$2,Bookings!$G$5:$G$304,"<="&$P$3)=0,"—",SUMIFS(Bookings!$N$5:$N$304,Bookings!$B$5:$B$304,$A18,Bookings!$G$5:$G$304,">="&$P$2,Bookings!$G$5:$G$304,"<="&$P$3)+SUMIFS(Bookings!$O$5:$O$304,Bookings!$B$5:$B$304,$A18,Bookings!$G$5:$G$304,">="&$P$2,Bookings!$G$5:$G$304,"<="&$P$3))) -> — | H18: =IF($A18="—","—",IF(SUMIFS(Bookings!$P$5:$P$304,Bookings!$B$5:$B$304,$A18,Bookings!$G$5:$G$304,">="&$P$2,Bookings!$G$5:$G$304,"<="&$P$3)=0,"—",SUMIFS(Bookings!$P$5:$P$304,Bookings!$B$5:$B$304,$A18,Bookings!$G$5:$G$304,">="&$P$2,Bookings!$G$5:$G$304,"<="&$P$3))) -> — | I18: =IF($A18="—","—",IFERROR(IF(INDEX(Setup!$J$25:$J$36,MATCH($A18,Setup!$A$25:$A$36,0))=0,"—",INDEX(Setup!$J$25:$J$36,MATCH($A18,Setup!$A$25:$A$36,0))),"—")) -> — | J18: =IF($A18="—","—",IF(SUMIFS(Costs!$F$5:$F$254,Costs!$C$5:$C$254,$A18,Costs!$B$5:$B$254,">="&$P$2,Costs!$B$5:$B$254,"<="&$P$3)=0,"—",SUMIFS(Costs!$F$5:$F$254,Costs!$C$5:$C$254,$A18,Costs!$B$5:$B$254,">="&$P$2,Costs!$B$5:$B$254,"<="&$P$3))) -> — | K18: =IF(OR($A18="—",COUNT($F18:$J18)=0),"—",ROUND(SUM($F18:$J18),2)) -> — | L18: =IF(OR($A18="—",COUNT($E18,$K18)=0),"—",ROUND(IF(ISNUMBER($E18),$E18,0)-IF(ISNUMBER($K18),$K18,0),2)) -> — | M18: =IF(OR(NOT(ISNUMBER($L18)),NOT(ISNUMBER($C18)),$C18<=0),"—",ROUND($L18/$C18,2)) -> —
A19: =IF(Setup!$A33="","—",Setup!$A33) -> — | B19: =IF($A19="—","—",IF(SUMIFS(Bookings!$T$5:$T$304,Bookings!$B$5:$B$304,$A19)=0,"—",SUMIFS(Bookings!$T$5:$T$304,Bookings!$B$5:$B$304,$A19))) -> — | C19: =IF(OR($A19="—",NOT(ISNUMBER($P$4))),"—",$P$4-SUMIFS(Bookings!$U$5:$U$304,Bookings!$B$5:$B$304,$A19)) -> — | D19: =IFERROR(IF(OR($A19="—",NOT(ISNUMBER($C19)),$C19<=0),"—",IF(ISNUMBER($B19),$B19,0)/$C19),"—") -> — | E19: =IF($A19="—","—",IF(SUMIFS(Bookings!$W$5:$W$304,Bookings!$B$5:$B$304,$A19,Bookings!$G$5:$G$304,">="&$P$2,Bookings!$G$5:$G$304,"<="&$P$3)=0,"—",SUMIFS(Bookings!$W$5:$W$304,Bookings!$B$5:$B$304,$A19,Bookings!$G$5:$G$304,">="&$P$2,Bookings!$G$5:$G$304,"<="&$P$3))) -> — | F19: =IF($A19="—","—",IF(SUMIFS(Bookings!$L$5:$L$304,Bookings!$B$5:$B$304,$A19,Bookings!$G$5:$G$304,">="&$P$2,Bookings!$G$5:$G$304,"<="&$P$3)=0,"—",SUMIFS(Bookings!$L$5:$L$304,Bookings!$B$5:$B$304,$A19,Bookings!$G$5:$G$304,">="&$P$2,Bookings!$G$5:$G$304,"<="&$P$3))) -> — | G19: =IF($A19="—","—",IF(SUMIFS(Bookings!$N$5:$N$304,Bookings!$B$5:$B$304,$A19,Bookings!$G$5:$G$304,">="&$P$2,Bookings!$G$5:$G$304,"<="&$P$3)+SUMIFS(Bookings!$O$5:$O$304,Bookings!$B$5:$B$304,$A19,Bookings!$G$5:$G$304,">="&$P$2,Bookings!$G$5:$G$304,"<="&$P$3)=0,"—",SUMIFS(Bookings!$N$5:$N$304,Bookings!$B$5:$B$304,$A19,Bookings!$G$5:$G$304,">="&$P$2,Bookings!$G$5:$G$304,"<="&$P$3)+SUMIFS(Bookings!$O$5:$O$304,Bookings!$B$5:$B$304,$A19,Bookings!$G$5:$G$304,">="&$P$2,Bookings!$G$5:$G$304,"<="&$P$3))) -> — | H19: =IF($A19="—","—",IF(SUMIFS(Bookings!$P$5:$P$304,Bookings!$B$5:$B$304,$A19,Bookings!$G$5:$G$304,">="&$P$2,Bookings!$G$5:$G$304,"<="&$P$3)=0,"—",SUMIFS(Bookings!$P$5:$P$304,Bookings!$B$5:$B$304,$A19,Bookings!$G$5:$G$304,">="&$P$2,Bookings!$G$5:$G$304,"<="&$P$3))) -> — | I19: =IF($A19="—","—",IFERROR(IF(INDEX(Setup!$J$25:$J$36,MATCH($A19,Setup!$A$25:$A$36,0))=0,"—",INDEX(Setup!$J$25:$J$36,MATCH($A19,Setup!$A$25:$A$36,0))),"—")) -> — | J19: =IF($A19="—","—",IF(SUMIFS(Costs!$F$5:$F$254,Costs!$C$5:$C$254,$A19,Costs!$B$5:$B$254,">="&$P$2,Costs!$B$5:$B$254,"<="&$P$3)=0,"—",SUMIFS(Costs!$F$5:$F$254,Costs!$C$5:$C$254,$A19,Costs!$B$5:$B$254,">="&$P$2,Costs!$B$5:$B$254,"<="&$P$3))) -> — | K19: =IF(OR($A19="—",COUNT($F19:$J19)=0),"—",ROUND(SUM($F19:$J19),2)) -> — | L19: =IF(OR($A19="—",COUNT($E19,$K19)=0),"—",ROUND(IF(ISNUMBER($E19),$E19,0)-IF(ISNUMBER($K19),$K19,0),2)) -> — | M19: =IF(OR(NOT(ISNUMBER($L19)),NOT(ISNUMBER($C19)),$C19<=0),"—",ROUND($L19/$C19,2)) -> —
A20: =IF(Setup!$A34="","—",Setup!$A34) -> — | B20: =IF($A20="—","—",IF(SUMIFS(Bookings!$T$5:$T$304,Bookings!$B$5:$B$304,$A20)=0,"—",SUMIFS(Bookings!$T$5:$T$304,Bookings!$B$5:$B$304,$A20))) -> — | C20: =IF(OR($A20="—",NOT(ISNUMBER($P$4))),"—",$P$4-SUMIFS(Bookings!$U$5:$U$304,Bookings!$B$5:$B$304,$A20)) -> — | D20: =IFERROR(IF(OR($A20="—",NOT(ISNUMBER($C20)),$C20<=0),"—",IF(ISNUMBER($B20),$B20,0)/$C20),"—") -> — | E20: =IF($A20="—","—",IF(SUMIFS(Bookings!$W$5:$W$304,Bookings!$B$5:$B$304,$A20,Bookings!$G$5:$G$304,">="&$P$2,Bookings!$G$5:$G$304,"<="&$P$3)=0,"—",SUMIFS(Bookings!$W$5:$W$304,Bookings!$B$5:$B$304,$A20,Bookings!$G$5:$G$304,">="&$P$2,Bookings!$G$5:$G$304,"<="&$P$3))) -> — | F20: =IF($A20="—","—",IF(SUMIFS(Bookings!$L$5:$L$304,Bookings!$B$5:$B$304,$A20,Bookings!$G$5:$G$304,">="&$P$2,Bookings!$G$5:$G$304,"<="&$P$3)=0,"—",SUMIFS(Bookings!$L$5:$L$304,Bookings!$B$5:$B$304,$A20,Bookings!$G$5:$G$304,">="&$P$2,Bookings!$G$5:$G$304,"<="&$P$3))) -> — | G20: =IF($A20="—","—",IF(SUMIFS(Bookings!$N$5:$N$304,Bookings!$B$5:$B$304,$A20,Bookings!$G$5:$G$304,">="&$P$2,Bookings!$G$5:$G$304,"<="&$P$3)+SUMIFS(Bookings!$O$5:$O$304,Bookings!$B$5:$B$304,$A20,Bookings!$G$5:$G$304,">="&$P$2,Bookings!$G$5:$G$304,"<="&$P$3)=0,"—",SUMIFS(Bookings!$N$5:$N$304,Bookings!$B$5:$B$304,$A20,Bookings!$G$5:$G$304,">="&$P$2,Bookings!$G$5:$G$304,"<="&$P$3)+SUMIFS(Bookings!$O$5:$O$304,Bookings!$B$5:$B$304,$A20,Bookings!$G$5:$G$304,">="&$P$2,Bookings!$G$5:$G$304,"<="&$P$3))) -> — | H20: =IF($A20="—","—",IF(SUMIFS(Bookings!$P$5:$P$304,Bookings!$B$5:$B$304,$A20,Bookings!$G$5:$G$304,">="&$P$2,Bookings!$G$5:$G$304,"<="&$P$3)=0,"—",SUMIFS(Bookings!$P$5:$P$304,Bookings!$B$5:$B$304,$A20,Bookings!$G$5:$G$304,">="&$P$2,Bookings!$G$5:$G$304,"<="&$P$3))) -> — | I20: =IF($A20="—","—",IFERROR(IF(INDEX(Setup!$J$25:$J$36,MATCH($A20,Setup!$A$25:$A$36,0))=0,"—",INDEX(Setup!$J$25:$J$36,MATCH($A20,Setup!$A$25:$A$36,0))),"—")) -> — | J20: =IF($A20="—","—",IF(SUMIFS(Costs!$F$5:$F$254,Costs!$C$5:$C$254,$A20,Costs!$B$5:$B$254,">="&$P$2,Costs!$B$5:$B$254,"<="&$P$3)=0,"—",SUMIFS(Costs!$F$5:$F$254,Costs!$C$5:$C$254,$A20,Costs!$B$5:$B$254,">="&$P$2,Costs!$B$5:$B$254,"<="&$P$3))) -> — | K20: =IF(OR($A20="—",COUNT($F20:$J20)=0),"—",ROUND(SUM($F20:$J20),2)) -> — | L20: =IF(OR($A20="—",COUNT($E20,$K20)=0),"—",ROUND(IF(ISNUMBER($E20),$E20,0)-IF(ISNUMBER($K20),$K20,0),2)) -> — | M20: =IF(OR(NOT(ISNUMBER($L20)),NOT(ISNUMBER($C20)),$C20<=0),"—",ROUND($L20/$C20,2)) -> —
A21: =IF(Setup!$A35="","—",Setup!$A35) -> — | B21: =IF($A21="—","—",IF(SUMIFS(Bookings!$T$5:$T$304,Bookings!$B$5:$B$304,$A21)=0,"—",SUMIFS(Bookings!$T$5:$T$304,Bookings!$B$5:$B$304,$A21))) -> — | C21: =IF(OR($A21="—",NOT(ISNUMBER($P$4))),"—",$P$4-SUMIFS(Bookings!$U$5:$U$304,Bookings!$B$5:$B$304,$A21)) -> — | D21: =IFERROR(IF(OR($A21="—",NOT(ISNUMBER($C21)),$C21<=0),"—",IF(ISNUMBER($B21),$B21,0)/$C21),"—") -> — | E21: =IF($A21="—","—",IF(SUMIFS(Bookings!$W$5:$W$304,Bookings!$B$5:$B$304,$A21,Bookings!$G$5:$G$304,">="&$P$2,Bookings!$G$5:$G$304,"<="&$P$3)=0,"—",SUMIFS(Bookings!$W$5:$W$304,Bookings!$B$5:$B$304,$A21,Bookings!$G$5:$G$304,">="&$P$2,Bookings!$G$5:$G$304,"<="&$P$3))) -> — | F21: =IF($A21="—","—",IF(SUMIFS(Bookings!$L$5:$L$304,Bookings!$B$5:$B$304,$A21,Bookings!$G$5:$G$304,">="&$P$2,Bookings!$G$5:$G$304,"<="&$P$3)=0,"—",SUMIFS(Bookings!$L$5:$L$304,Bookings!$B$5:$B$304,$A21,Bookings!$G$5:$G$304,">="&$P$2,Bookings!$G$5:$G$304,"<="&$P$3))) -> — | G21: =IF($A21="—","—",IF(SUMIFS(Bookings!$N$5:$N$304,Bookings!$B$5:$B$304,$A21,Bookings!$G$5:$G$304,">="&$P$2,Bookings!$G$5:$G$304,"<="&$P$3)+SUMIFS(Bookings!$O$5:$O$304,Bookings!$B$5:$B$304,$A21,Bookings!$G$5:$G$304,">="&$P$2,Bookings!$G$5:$G$304,"<="&$P$3)=0,"—",SUMIFS(Bookings!$N$5:$N$304,Bookings!$B$5:$B$304,$A21,Bookings!$G$5:$G$304,">="&$P$2,Bookings!$G$5:$G$304,"<="&$P$3)+SUMIFS(Bookings!$O$5:$O$304,Bookings!$B$5:$B$304,$A21,Bookings!$G$5:$G$304,">="&$P$2,Bookings!$G$5:$G$304,"<="&$P$3))) -> — | H21: =IF($A21="—","—",IF(SUMIFS(Bookings!$P$5:$P$304,Bookings!$B$5:$B$304,$A21,Bookings!$G$5:$G$304,">="&$P$2,Bookings!$G$5:$G$304,"<="&$P$3)=0,"—",SUMIFS(Bookings!$P$5:$P$304,Bookings!$B$5:$B$304,$A21,Bookings!$G$5:$G$304,">="&$P$2,Bookings!$G$5:$G$304,"<="&$P$3))) -> — | I21: =IF($A21="—","—",IFERROR(IF(INDEX(Setup!$J$25:$J$36,MATCH($A21,Setup!$A$25:$A$36,0))=0,"—",INDEX(Setup!$J$25:$J$36,MATCH($A21,Setup!$A$25:$A$36,0))),"—")) -> — | J21: =IF($A21="—","—",IF(SUMIFS(Costs!$F$5:$F$254,Costs!$C$5:$C$254,$A21,Costs!$B$5:$B$254,">="&$P$2,Costs!$B$5:$B$254,"<="&$P$3)=0,"—",SUMIFS(Costs!$F$5:$F$254,Costs!$C$5:$C$254,$A21,Costs!$B$5:$B$254,">="&$P$2,Costs!$B$5:$B$254,"<="&$P$3))) -> — | K21: =IF(OR($A21="—",COUNT($F21:$J21)=0),"—",ROUND(SUM($F21:$J21),2)) -> — | L21: =IF(OR($A21="—",COUNT($E21,$K21)=0),"—",ROUND(IF(ISNUMBER($E21),$E21,0)-IF(ISNUMBER($K21),$K21,0),2)) -> — | M21: =IF(OR(NOT(ISNUMBER($L21)),NOT(ISNUMBER($C21)),$C21<=0),"—",ROUND($L21/$C21,2)) -> —
A22: =IF(Setup!$A36="","—",Setup!$A36) -> — | B22: =IF($A22="—","—",IF(SUMIFS(Bookings!$T$5:$T$304,Bookings!$B$5:$B$304,$A22)=0,"—",SUMIFS(Bookings!$T$5:$T$304,Bookings!$B$5:$B$304,$A22))) -> — | C22: =IF(OR($A22="—",NOT(ISNUMBER($P$4))),"—",$P$4-SUMIFS(Bookings!$U$5:$U$304,Bookings!$B$5:$B$304,$A22)) -> — | D22: =IFERROR(IF(OR($A22="—",NOT(ISNUMBER($C22)),$C22<=0),"—",IF(ISNUMBER($B22),$B22,0)/$C22),"—") -> — | E22: =IF($A22="—","—",IF(SUMIFS(Bookings!$W$5:$W$304,Bookings!$B$5:$B$304,$A22,Bookings!$G$5:$G$304,">="&$P$2,Bookings!$G$5:$G$304,"<="&$P$3)=0,"—",SUMIFS(Bookings!$W$5:$W$304,Bookings!$B$5:$B$304,$A22,Bookings!$G$5:$G$304,">="&$P$2,Bookings!$G$5:$G$304,"<="&$P$3))) -> — | F22: =IF($A22="—","—",IF(SUMIFS(Bookings!$L$5:$L$304,Bookings!$B$5:$B$304,$A22,Bookings!$G$5:$G$304,">="&$P$2,Bookings!$G$5:$G$304,"<="&$P$3)=0,"—",SUMIFS(Bookings!$L$5:$L$304,Bookings!$B$5:$B$304,$A22,Bookings!$G$5:$G$304,">="&$P$2,Bookings!$G$5:$G$304,"<="&$P$3))) -> — | G22: =IF($A22="—","—",IF(SUMIFS(Bookings!$N$5:$N$304,Bookings!$B$5:$B$304,$A22,Bookings!$G$5:$G$304,">="&$P$2,Bookings!$G$5:$G$304,"<="&$P$3)+SUMIFS(Bookings!$O$5:$O$304,Bookings!$B$5:$B$304,$A22,Bookings!$G$5:$G$304,">="&$P$2,Bookings!$G$5:$G$304,"<="&$P$3)=0,"—",SUMIFS(Bookings!$N$5:$N$304,Bookings!$B$5:$B$304,$A22,Bookings!$G$5:$G$304,">="&$P$2,Bookings!$G$5:$G$304,"<="&$P$3)+SUMIFS(Bookings!$O$5:$O$304,Bookings!$B$5:$B$304,$A22,Bookings!$G$5:$G$304,">="&$P$2,Bookings!$G$5:$G$304,"<="&$P$3))) -> — | H22: =IF($A22="—","—",IF(SUMIFS(Bookings!$P$5:$P$304,Bookings!$B$5:$B$304,$A22,Bookings!$G$5:$G$304,">="&$P$2,Bookings!$G$5:$G$304,"<="&$P$3)=0,"—",SUMIFS(Bookings!$P$5:$P$304,Bookings!$B$5:$B$304,$A22,Bookings!$G$5:$G$304,">="&$P$2,Bookings!$G$5:$G$304,"<="&$P$3))) -> — | I22: =IF($A22="—","—",IFERROR(IF(INDEX(Setup!$J$25:$J$36,MATCH($A22,Setup!$A$25:$A$36,0))=0,"—",INDEX(Setup!$J$25:$J$36,MATCH($A22,Setup!$A$25:$A$36,0))),"—")) -> — | J22: =IF($A22="—","—",IF(SUMIFS(Costs!$F$5:$F$254,Costs!$C$5:$C$254,$A22,Costs!$B$5:$B$254,">="&$P$2,Costs!$B$5:$B$254,"<="&$P$3)=0,"—",SUMIFS(Costs!$F$5:$F$254,Costs!$C$5:$C$254,$A22,Costs!$B$5:$B$254,">="&$P$2,Costs!$B$5:$B$254,"<="&$P$3))) -> — | K22: =IF(OR($A22="—",COUNT($F22:$J22)=0),"—",ROUND(SUM($F22:$J22),2)) -> — | L22: =IF(OR($A22="—",COUNT($E22,$K22)=0),"—",ROUND(IF(ISNUMBER($E22),$E22,0)-IF(ISNUMBER($K22),$K22,0),2)) -> — | M22: =IF(OR(NOT(ISNUMBER($L22)),NOT(ISNUMBER($C22)),$C22<=0),"—",ROUND($L22/$C22,2)) -> —
A23: PORTFOLIO TOTAL | B23: =IF(COUNT(B$11:B$22)=0,"—",ROUND(SUM(B$11:B$22),2)) -> 36 | C23: =IF(COUNT(C$11:C$22)=0,"—",ROUND(SUM(C$11:C$22),2)) -> 90 | D23: =IF(OR(NOT(ISNUMBER($C23)),$C23<=0),"—",IF(ISNUMBER($B23),$B23,0)/$C23) -> 0.4 | E23: =IF(COUNT(E$11:E$22)=0,"—",ROUND(SUM(E$11:E$22),2)) -> 3890 | F23: =IF(COUNT(F$11:F$22)=0,"—",ROUND(SUM(F$11:F$22),2)) -> 261.6 | G23: =IF(COUNT(G$11:G$22)=0,"—",ROUND(SUM(G$11:G$22),2)) -> 525 | H23: =IF(COUNT(H$11:H$22)=0,"—",ROUND(SUM(H$11:H$22),2)) -> 99.8 | I23: =IF(COUNT(I$11:I$22)=0,"—",ROUND(SUM(I$11:I$22),2)) -> 184 | J23: =IF(COUNT(J$11:J$22)=0,"—",ROUND(SUM(J$11:J$22),2)) -> 270.4 | K23: =IF(COUNT(K$11:K$22)=0,"—",ROUND(SUM(K$11:K$22),2)) -> 1340.8 | L23: =IF(COUNT(L$11:L$22)=0,"—",ROUND(SUM(L$11:L$22),2)) -> 2549.2 | M23: =IF(OR(NOT(ISNUMBER($L23)),NOT(ISNUMBER($C23)),$C23<=0),"—",ROUND($L23/$C23,2)) -> 28.32
A25: =IF(COUNTIF(Bookings!$V$5:$V$304,"⚠*")+COUNTIF(Costs!$I$5:$I$254,"⚠*")>0,"Data check: "&(COUNTIF(Bookings!$V$5:$V$304,"⚠*")+COUNTIF(Costs!$I$5:$I$254,"⚠*"))&" row(s) are NOT counted anywhere — see the Check column in Bookings and Costs.",IF(COUNTA(Bookings!$B$5:$B$304)+COUNTA(Costs!$C$5:$C$254)=0,"Data check: no rows entered yet — start in the Setup tab, then the Bookings tab.","Data check: every row is linked to a property in Setup.")) -> Data check: every row is linked to a property in Setup.
A27: HOW THE MATH WORKS
A28: 1 · Money (booking value, fees, cleaning, consumables) is counted in the month a stay CHECKS OUT. Nights and occupancy are split across months by the actual dates, so a stay spanning two months shows nights in both but money in one.
A29: 2 · Gross booking value = the total the guest paid, including any cleaning fee you charge. What you pay your cleaner is a cost in Setup.
A30: 3 · Fixed monthly costs come from Setup and run in every month you look at — never enter them again in the Costs tab. If you only owned a property part of the year, clear that field before checking earlier months.
A31: 4 · Colour thresholds are our convention, not a benchmark: occupancy green from 60%, amber from 40%; the cost tile turns amber when tracked costs pass 70% of gross. Change them in the conditional formatting menu whenever you like.
A32: 5 · 'Net after tracked costs' is gross minus exactly what you typed into this workbook. It is not a tax, accounting or bookkeeping figure, and no tax of any kind is calculated here.
A33: Never type on this sheet except the two month pickers. Excel: Review ▸ Unprotect Sheet (no password) if you want to restyle it. Google Sheets does not carry that protection over — just don't type here.

Sheet Bookings
A1: Bookings — one row per stay
A2: Type the white cells only: property, platform, status, guest, the two dates, guests and the gross booking value. Grey columns calculate themselves. Manual entry — no login, no API, no calendar sync.
A4: # | B4: Property | C4: Platform | D4: Status | E4: Guest / reference | F4: Check-in | G4: Check-out | H4: Nights | I4: Guests | J4: Gross booking value | K4: Platform fee % override | L4: Platform fee | M4: Estimated payout after platform fee | N4: Cleaning | O4: Laundry | P4: Consumables | Q4: Net after direct costs | R4: Net per night | S4: Notes | T4: Nights in selected month — guest (changes with the Dashboard month picker) | U4: Nights in selected month — owner block (changes with the Dashboard month picker) | V4: Check | W4: Gross counted in this file
A5: 1 | B5: Riverside Loft | C5: Airbnb | D5: Completed | E5: EXAMPLE — A. Pereira | F5: =IFERROR(DATE(YEAR(TODAY()),MONTH(TODAY()),1),"") -> 46204 | G5: =IFERROR(DATE(YEAR(TODAY()),MONTH(TODAY()),5),"") -> 46208 | H5: =IF(OR(NOT(ISNUMBER($F5)),NOT(ISNUMBER($G5))),"—",IF($G5<=$F5,"⚠ check dates",$G5-$F5)) -> 4 | I5: 2 | J5: 480 | L5: =IF(OR($B5="",NOT(ISNUMBER($J5)),$D5="Cancelled",$D5="Owner block"),"—",ROUND($J5*IF(ISNUMBER($K5),IF($K5>1,$K5/100,$K5),IF(IFERROR(INDEX(Setup!$D$25:$D$36,MATCH($B5,Setup!$A$25:$A$36,0)),0)>1,IFERROR(INDEX(Setup!$D$25:$D$36,MATCH($B5,Setup!$A$25:$A$36,0)),0)/100,IFERROR(INDEX(Setup!$D$25:$D$36,MATCH($B5,Setup!$A$25:$A$36,0)),0))),2)) -> 14.4 | M5: =IF(NOT(ISNUMBER($L5)),"—",ROUND($J5-$L5,2)) -> 465.6 | N5: =IF(OR($B5="",$G5="",$D5="Cancelled"),"—",IFERROR(IF(INDEX(Setup!$E$25:$E$36,MATCH($B5,Setup!$A$25:$A$36,0))=0,"—",INDEX(Setup!$E$25:$E$36,MATCH($B5,Setup!$A$25:$A$36,0))),"—")) -> 45 | O5: =IF(OR($B5="",$G5="",$D5="Cancelled"),"—",IFERROR(IF(INDEX(Setup!$F$25:$F$36,MATCH($B5,Setup!$A$25:$A$36,0))=0,"—",INDEX(Setup!$F$25:$F$36,MATCH($B5,Setup!$A$25:$A$36,0))),"—")) -> 12 | P5: =IF(OR($B5="",$G5="",$D5="Cancelled",$D5="Owner block"),"—",IF(IFERROR(INDEX(Setup!$G$25:$G$36,MATCH($B5,Setup!$A$25:$A$36,0)),0)+IFERROR(INDEX(Setup!$H$25:$H$36,MATCH($B5,Setup!$A$25:$A$36,0)),0)*IF(ISNUMBER($H5),$H5,0)=0,"—",ROUND(IFERROR(INDEX(Setup!$G$25:$G$36,MATCH($B5,Setup!$A$25:$A$36,0)),0)+IFERROR(INDEX(Setup!$H$25:$H$36,MATCH($B5,Setup!$A$25:$A$36,0)),0)*IF(ISNUMBER($H5),$H5,0),2))) -> 12 | Q5: =IF(OR($B5="",$D5="Cancelled"),"—",IF(AND(NOT(ISNUMBER($M5)),COUNT($N5:$P5)=0),"—",ROUND(IF(ISNUMBER($M5),$M5,0)-SUM($N5:$P5),2))) -> 396.6 | R5: =IF(OR(NOT(ISNUMBER($Q5)),NOT(ISNUMBER($H5)),$H5<=0),"—",ROUND($Q5/$H5,2)) -> 99.15 | T5: =IF(OR(NOT(ISNUMBER($F5)),NOT(ISNUMBER($G5)),NOT(ISNUMBER(Dashboard!$P$2)),NOT(ISNUMBER(Dashboard!$P$3)),$D5="Cancelled",$D5="Owner block"),"—",IF(MAX(0,MIN($G5,Dashboard!$P$3+1)-MAX($F5,Dashboard!$P$2))=0,"—",MAX(0,MIN($G5,Dashboard!$P$3+1)-MAX($F5,Dashboard!$P$2)))) -> 4 | U5: =IF(OR(NOT(ISNUMBER($F5)),NOT(ISNUMBER($G5)),NOT(ISNUMBER(Dashboard!$P$2)),NOT(ISNUMBER(Dashboard!$P$3)),$D5<>"Owner block"),"—",IF(MAX(0,MIN($G5,Dashboard!$P$3+1)-MAX($F5,Dashboard!$P$2))=0,"—",MAX(0,MIN($G5,Dashboard!$P$3+1)-MAX($F5,Dashboard!$P$2)))) -> — | V5: =IF($B5="",IF(COUNTA($C5:$G5,$I5:$K5,$S5)=0,"","⚠ no property — not counted"),IF(COUNTIF(Setup!$A$25:$A$36,$B5)=0,"⚠ property not in Setup",IF(AND($F5<>"",NOT(ISNUMBER($F5))),"⚠ check-in is not a real date",IF(AND($G5<>"",NOT(ISNUMBER($G5))),"⚠ check-out is not a real date",IF(AND($J5<>"",NOT(ISNUMBER($J5))),"⚠ booking value is not a number","OK"))))) -> OK | W5: =IF(OR($B5="",NOT(ISNUMBER($J5)),$D5="Cancelled",$D5="Owner block"),"—",$J5) -> 480
A6: 2 | B6: Riverside Loft | C6: Airbnb | D6: Completed | E6: EXAMPLE — J. Meyer | F6: =IFERROR(DATE(YEAR(TODAY()),MONTH(TODAY()),7),"") -> 46210 | G6: =IFERROR(DATE(YEAR(TODAY()),MONTH(TODAY()),11),"") -> 46214 | H6: =IF(OR(NOT(ISNUMBER($F6)),NOT(ISNUMBER($G6))),"—",IF($G6<=$F6,"⚠ check dates",$G6-$F6)) -> 4 | I6: 2 | J6: 505 | L6: =IF(OR($B6="",NOT(ISNUMBER($J6)),$D6="Cancelled",$D6="Owner block"),"—",ROUND($J6*IF(ISNUMBER($K6),IF($K6>1,$K6/100,$K6),IF(IFERROR(INDEX(Setup!$D$25:$D$36,MATCH($B6,Setup!$A$25:$A$36,0)),0)>1,IFERROR(INDEX(Setup!$D$25:$D$36,MATCH($B6,Setup!$A$25:$A$36,0)),0)/100,IFERROR(INDEX(Setup!$D$25:$D$36,MATCH($B6,Setup!$A$25:$A$36,0)),0))),2)) -> 15.15 | M6: =IF(NOT(ISNUMBER($L6)),"—",ROUND($J6-$L6,2)) -> 489.85 | N6: =IF(OR($B6="",$G6="",$D6="Cancelled"),"—",IFERROR(IF(INDEX(Setup!$E$25:$E$36,MATCH($B6,Setup!$A$25:$A$36,0))=0,"—",INDEX(Setup!$E$25:$E$36,MATCH($B6,Setup!$A$25:$A$36,0))),"—")) -> 45 | O6: =IF(OR($B6="",$G6="",$D6="Cancelled"),"—",IFERROR(IF(INDEX(Setup!$F$25:$F$36,MATCH($B6,Setup!$A$25:$A$36,0))=0,"—",INDEX(Setup!$F$25:$F$36,MATCH($B6,Setup!$A$25:$A$36,0))),"—")) -> 12 | P6: =IF(OR($B6="",$G6="",$D6="Cancelled",$D6="Owner block"),"—",IF(IFERROR(INDEX(Setup!$G$25:$G$36,MATCH($B6,Setup!$A$25:$A$36,0)),0)+IFERROR(INDEX(Setup!$H$25:$H$36,MATCH($B6,Setup!$A$25:$A$36,0)),0)*IF(ISNUMBER($H6),$H6,0)=0,"—",ROUND(IFERROR(INDEX(Setup!$G$25:$G$36,MATCH($B6,Setup!$A$25:$A$36,0)),0)+IFERROR(INDEX(Setup!$H$25:$H$36,MATCH($B6,Setup!$A$25:$A$36,0)),0)*IF(ISNUMBER($H6),$H6,0),2))) -> 12 | Q6: =IF(OR($B6="",$D6="Cancelled"),"—",IF(AND(NOT(ISNUMBER($M6)),COUNT($N6:$P6)=0),"—",ROUND(IF(ISNUMBER($M6),$M6,0)-SUM($N6:$P6),2))) -> 420.85 | R6: =IF(OR(NOT(ISNUMBER($Q6)),NOT(ISNUMBER($H6)),$H6<=0),"—",ROUND($Q6/$H6,2)) -> 105.21 | T6: =IF(OR(NOT(ISNUMBER($F6)),NOT(ISNUMBER($G6)),NOT(ISNUMBER(Dashboard!$P$2)),NOT(ISNUMBER(Dashboard!$P$3)),$D6="Cancelled",$D6="Owner block"),"—",IF(MAX(0,MIN($G6,Dashboard!$P$3+1)-MAX($F6,Dashboard!$P$2))=0,"—",MAX(0,MIN($G6,Dashboard!$P$3+1)-MAX($F6,Dashboard!$P$2)))) -> 4 | U6: =IF(OR(NOT(ISNUMBER($F6)),NOT(ISNUMBER($G6)),NOT(ISNUMBER(Dashboard!$P$2)),NOT(ISNUMBER(Dashboard!$P$3)),$D6<>"Owner block"),"—",IF(MAX(0,MIN($G6,Dashboard!$P$3+1)-MAX($F6,Dashboard!$P$2))=0,"—",MAX(0,MIN($G6,Dashboard!$P$3+1)-MAX($F6,Dashboard!$P$2)))) -> — | V6: =IF($B6="",IF(COUNTA($C6:$G6,$I6:$K6,$S6)=0,"","⚠ no property — not counted"),IF(COUNTIF(Setup!$A$25:$A$36,$B6)=0,"⚠ property not in Setup",IF(AND($F6<>"",NOT(ISNUMBER($F6))),"⚠ check-in is not a real date",IF(AND($G6<>"",NOT(ISNUMBER($G6))),"⚠ check-out is not a real date",IF(AND($J6<>"",NOT(ISNUMBER($J6))),"⚠ booking value is not a number","OK"))))) -> OK | W6: =IF(OR($B6="",NOT(ISNUMBER($J6)),$D6="Cancelled",$D6="Owner block"),"—",$J6) -> 505
A7: 3 | B7: Riverside Loft | C7: Vrbo | D7: Completed | E7: EXAMPLE — L. Rossi | F7: =IFERROR(DATE(YEAR(TODAY()),MONTH(TODAY()),12),"") -> 46215 | G7: =IFERROR(DATE(YEAR(TODAY()),MONTH(TODAY()),16),"") -> 46219 | H7: =IF(OR(NOT(ISNUMBER($F7)),NOT(ISNUMBER($G7))),"—",IF($G7<=$F7,"⚠ check dates",$G7-$F7)) -> 4 | I7: 3 | J7: 430 | K7: 0.05 | L7: =IF(OR($B7="",NOT(ISNUMBER($J7)),$D7="Cancelled",$D7="Owner block"),"—",ROUND($J7*IF(ISNUMBER($K7),IF($K7>1,$K7/100,$K7),IF(IFERROR(INDEX(Setup!$D$25:$D$36,MATCH($B7,Setup!$A$25:$A$36,0)),0)>1,IFERROR(INDEX(Setup!$D$25:$D$36,MATCH($B7,Setup!$A$25:$A$36,0)),0)/100,IFERROR(INDEX(Setup!$D$25:$D$36,MATCH($B7,Setup!$A$25:$A$36,0)),0))),2)) -> 21.5 | M7: =IF(NOT(ISNUMBER($L7)),"—",ROUND($J7-$L7,2)) -> 408.5 | N7: =IF(OR($B7="",$G7="",$D7="Cancelled"),"—",IFERROR(IF(INDEX(Setup!$E$25:$E$36,MATCH($B7,Setup!$A$25:$A$36,0))=0,"—",INDEX(Setup!$E$25:$E$36,MATCH($B7,Setup!$A$25:$A$36,0))),"—")) -> 45 | O7: =IF(OR($B7="",$G7="",$D7="Cancelled"),"—",IFERROR(IF(INDEX(Setup!$F$25:$F$36,MATCH($B7,Setup!$A$25:$A$36,0))=0,"—",INDEX(Setup!$F$25:$F$36,MATCH($B7,Setup!$A$25:$A$36,0))),"—")) -> 12 | P7: =IF(OR($B7="",$G7="",$D7="Cancelled",$D7="Owner block"),"—",IF(IFERROR(INDEX(Setup!$G$25:$G$36,MATCH($B7,Setup!$A$25:$A$36,0)),0)+IFERROR(INDEX(Setup!$H$25:$H$36,MATCH($B7,Setup!$A$25:$A$36,0)),0)*IF(ISNUMBER($H7),$H7,0)=0,"—",ROUND(IFERROR(INDEX(Setup!$G$25:$G$36,MATCH($B7,Setup!$A$25:$A$36,0)),0)+IFERROR(INDEX(Setup!$H$25:$H$36,MATCH($B7,Setup!$A$25:$A$36,0)),0)*IF(ISNUMBER($H7),$H7,0),2))) -> 12 | Q7: =IF(OR($B7="",$D7="Cancelled"),"—",IF(AND(NOT(ISNUMBER($M7)),COUNT($N7:$P7)=0),"—",ROUND(IF(ISNUMBER($M7),$M7,0)-SUM($N7:$P7),2))) -> 339.5 | R7: =IF(OR(NOT(ISNUMBER($Q7)),NOT(ISNUMBER($H7)),$H7<=0),"—",ROUND($Q7/$H7,2)) -> 84.88 | T7: =IF(OR(NOT(ISNUMBER($F7)),NOT(ISNUMBER($G7)),NOT(ISNUMBER(Dashboard!$P$2)),NOT(ISNUMBER(Dashboard!$P$3)),$D7="Cancelled",$D7="Owner block"),"—",IF(MAX(0,MIN($G7,Dashboard!$P$3+1)-MAX($F7,Dashboard!$P$2))=0,"—",MAX(0,MIN($G7,Dashboard!$P$3+1)-MAX($F7,Dashboard!$P$2)))) -> 4 | U7: =IF(OR(NOT(ISNUMBER($F7)),NOT(ISNUMBER($G7)),NOT(ISNUMBER(Dashboard!$P$2)),NOT(ISNUMBER(Dashboard!$P$3)),$D7<>"Owner block"),"—",IF(MAX(0,MIN($G7,Dashboard!$P$3+1)-MAX($F7,Dashboard!$P$2))=0,"—",MAX(0,MIN($G7,Dashboard!$P$3+1)-MAX($F7,Dashboard!$P$2)))) -> — | V7: =IF($B7="",IF(COUNTA($C7:$G7,$I7:$K7,$S7)=0,"","⚠ no property — not counted"),IF(COUNTIF(Setup!$A$25:$A$36,$B7)=0,"⚠ property not in Setup",IF(AND($F7<>"",NOT(ISNUMBER($F7))),"⚠ check-in is not a real date",IF(AND($G7<>"",NOT(ISNUMBER($G7))),"⚠ check-out is not a real date",IF(AND($J7<>"",NOT(ISNUMBER($J7))),"⚠ booking value is not a number","OK"))))) -> OK | W7: =IF(OR($B7="",NOT(ISNUMBER($J7)),$D7="Cancelled",$D7="Owner block"),"—",$J7) -> 430
A8: 4 | B8: Riverside Loft | C8: Airbnb | D8: Confirmed | E8: EXAMPLE — S. Novak | F8: =IFERROR(TODAY()+1,"") -> 46233 | G8: =IFERROR(TODAY()+3,"") -> 46235 | H8: =IF(OR(NOT(ISNUMBER($F8)),NOT(ISNUMBER($G8))),"—",IF($G8<=$F8,"⚠ check dates",$G8-$F8)) -> 2 | I8: 2 | J8: 560 | L8: =IF(OR($B8="",NOT(ISNUMBER($J8)),$D8="Cancelled",$D8="Owner block"),"—",ROUND($J8*IF(ISNUMBER($K8),IF($K8>1,$K8/100,$K8),IF(IFERROR(INDEX(Setup!$D$25:$D$36,MATCH($B8,Setup!$A$25:$A$36,0)),0)>1,IFERROR(INDEX(Setup!$D$25:$D$36,MATCH($B8,Setup!$A$25:$A$36,0)),0)/100,IFERROR(INDEX(Setup!$D$25:$D$36,MATCH($B8,Setup!$A$25:$A$36,0)),0))),2)) -> 16.8 | M8: =IF(NOT(ISNUMBER($L8)),"—",ROUND($J8-$L8,2)) -> 543.2 | N8: =IF(OR($B8="",$G8="",$D8="Cancelled"),"—",IFERROR(IF(INDEX(Setup!$E$25:$E$36,MATCH($B8,Setup!$A$25:$A$36,0))=0,"—",INDEX(Setup!$E$25:$E$36,MATCH($B8,Setup!$A$25:$A$36,0))),"—")) -> 45 | O8: =IF(OR($B8="",$G8="",$D8="Cancelled"),"—",IFERROR(IF(INDEX(Setup!$F$25:$F$36,MATCH($B8,Setup!$A$25:$A$36,0))=0,"—",INDEX(Setup!$F$25:$F$36,MATCH($B8,Setup!$A$25:$A$36,0))),"—")) -> 12 | P8: =IF(OR($B8="",$G8="",$D8="Cancelled",$D8="Owner block"),"—",IF(IFERROR(INDEX(Setup!$G$25:$G$36,MATCH($B8,Setup!$A$25:$A$36,0)),0)+IFERROR(INDEX(Setup!$H$25:$H$36,MATCH($B8,Setup!$A$25:$A$36,0)),0)*IF(ISNUMBER($H8),$H8,0)=0,"—",ROUND(IFERROR(INDEX(Setup!$G$25:$G$36,MATCH($B8,Setup!$A$25:$A$36,0)),0)+IFERROR(INDEX(Setup!$H$25:$H$36,MATCH($B8,Setup!$A$25:$A$36,0)),0)*IF(ISNUMBER($H8),$H8,0),2))) -> 9 | Q8: =IF(OR($B8="",$D8="Cancelled"),"—",IF(AND(NOT(ISNUMBER($M8)),COUNT($N8:$P8)=0),"—",ROUND(IF(ISNUMBER($M8),$M8,0)-SUM($N8:$P8),2))) -> 477.2 | R8: =IF(OR(NOT(ISNUMBER($Q8)),NOT(ISNUMBER($H8)),$H8<=0),"—",ROUND($Q8/$H8,2)) -> 238.6 | S8: Still ahead: the Cleaning tab counts the days down to this turnover. | T8: =IF(OR(NOT(ISNUMBER($F8)),NOT(ISNUMBER($G8)),NOT(ISNUMBER(Dashboard!$P$2)),NOT(ISNUMBER(Dashboard!$P$3)),$D8="Cancelled",$D8="Owner block"),"—",IF(MAX(0,MIN($G8,Dashboard!$P$3+1)-MAX($F8,Dashboard!$P$2))=0,"—",MAX(0,MIN($G8,Dashboard!$P$3+1)-MAX($F8,Dashboard!$P$2)))) -> 2 | U8: =IF(OR(NOT(ISNUMBER($F8)),NOT(ISNUMBER($G8)),NOT(ISNUMBER(Dashboard!$P$2)),NOT(ISNUMBER(Dashboard!$P$3)),$D8<>"Owner block"),"—",IF(MAX(0,MIN($G8,Dashboard!$P$3+1)-MAX($F8,Dashboard!$P$2))=0,"—",MAX(0,MIN($G8,Dashboard!$P$3+1)-MAX($F8,Dashboard!$P$2)))) -> — | V8: =IF($B8="",IF(COUNTA($C8:$G8,$I8:$K8,$S8)=0,"","⚠ no property — not counted"),IF(COUNTIF(Setup!$A$25:$A$36,$B8)=0,"⚠ property not in Setup",IF(AND($F8<>"",NOT(ISNUMBER($F8))),"⚠ check-in is not a real date",IF(AND($G8<>"",NOT(ISNUMBER($G8))),"⚠ check-out is not a real date",IF(AND($J8<>"",NOT(ISNUMBER($J8))),"⚠ booking value is not a number","OK"))))) -> OK | W8: =IF(OR($B8="",NOT(ISNUMBER($J8)),$D8="Cancelled",$D8="Owner block"),"—",$J8) -> 560
A9: 5 | B9: Harbour Studio | C9: Booking.com | D9: Completed | E9: EXAMPLE — T. Brandt | F9: =IFERROR(DATE(YEAR(TODAY()),MONTH(TODAY()),2),"") -> 46205 | G9: =IFERROR(DATE(YEAR(TODAY()),MONTH(TODAY()),6),"") -> 46209 | H9: =IF(OR(NOT(ISNUMBER($F9)),NOT(ISNUMBER($G9))),"—",IF($G9<=$F9,"⚠ check dates",$G9-$F9)) -> 4 | I9: 2 | J9: 310 | L9: =IF(OR($B9="",NOT(ISNUMBER($J9)),$D9="Cancelled",$D9="Owner block"),"—",ROUND($J9*IF(ISNUMBER($K9),IF($K9>1,$K9/100,$K9),IF(IFERROR(INDEX(Setup!$D$25:$D$36,MATCH($B9,Setup!$A$25:$A$36,0)),0)>1,IFERROR(INDEX(Setup!$D$25:$D$36,MATCH($B9,Setup!$A$25:$A$36,0)),0)/100,IFERROR(INDEX(Setup!$D$25:$D$36,MATCH($B9,Setup!$A$25:$A$36,0)),0))),2)) -> 46.5 | M9: =IF(NOT(ISNUMBER($L9)),"—",ROUND($J9-$L9,2)) -> 263.5 | N9: =IF(OR($B9="",$G9="",$D9="Cancelled"),"—",IFERROR(IF(INDEX(Setup!$E$25:$E$36,MATCH($B9,Setup!$A$25:$A$36,0))=0,"—",INDEX(Setup!$E$25:$E$36,MATCH($B9,Setup!$A$25:$A$36,0))),"—")) -> 38 | O9: =IF(OR($B9="",$G9="",$D9="Cancelled"),"—",IFERROR(IF(INDEX(Setup!$F$25:$F$36,MATCH($B9,Setup!$A$25:$A$36,0))=0,"—",INDEX(Setup!$F$25:$F$36,MATCH($B9,Setup!$A$25:$A$36,0))),"—")) -> 9 | P9: =IF(OR($B9="",$G9="",$D9="Cancelled",$D9="Owner block"),"—",IF(IFERROR(INDEX(Setup!$G$25:$G$36,MATCH($B9,Setup!$A$25:$A$36,0)),0)+IFERROR(INDEX(Setup!$H$25:$H$36,MATCH($B9,Setup!$A$25:$A$36,0)),0)*IF(ISNUMBER($H9),$H9,0)=0,"—",ROUND(IFERROR(INDEX(Setup!$G$25:$G$36,MATCH($B9,Setup!$A$25:$A$36,0)),0)+IFERROR(INDEX(Setup!$H$25:$H$36,MATCH($B9,Setup!$A$25:$A$36,0)),0)*IF(ISNUMBER($H9),$H9,0),2))) -> 9.3 | Q9: =IF(OR($B9="",$D9="Cancelled"),"—",IF(AND(NOT(ISNUMBER($M9)),COUNT($N9:$P9)=0),"—",ROUND(IF(ISNUMBER($M9),$M9,0)-SUM($N9:$P9),2))) -> 207.2 | R9: =IF(OR(NOT(ISNUMBER($Q9)),NOT(ISNUMBER($H9)),$H9<=0),"—",ROUND($Q9/$H9,2)) -> 51.8 | T9: =IF(OR(NOT(ISNUMBER($F9)),NOT(ISNUMBER($G9)),NOT(ISNUMBER(Dashboard!$P$2)),NOT(ISNUMBER(Dashboard!$P$3)),$D9="Cancelled",$D9="Owner block"),"—",IF(MAX(0,MIN($G9,Dashboard!$P$3+1)-MAX($F9,Dashboard!$P$2))=0,"—",MAX(0,MIN($G9,Dashboard!$P$3+1)-MAX($F9,Dashboard!$P$2)))) -> 4 | U9: =IF(OR(NOT(ISNUMBER($F9)),NOT(ISNUMBER($G9)),NOT(ISNUMBER(Dashboard!$P$2)),NOT(ISNUMBER(Dashboard!$P$3)),$D9<>"Owner block"),"—",IF(MAX(0,MIN($G9,Dashboard!$P$3+1)-MAX($F9,Dashboard!$P$2))=0,"—",MAX(0,MIN($G9,Dashboard!$P$3+1)-MAX($F9,Dashboard!$P$2)))) -> — | V9: =IF($B9="",IF(COUNTA($C9:$G9,$I9:$K9,$S9)=0,"","⚠ no property — not counted"),IF(COUNTIF(Setup!$A$25:$A$36,$B9)=0,"⚠ property not in Setup",IF(AND($F9<>"",NOT(ISNUMBER($F9))),"⚠ check-in is not a real date",IF(AND($G9<>"",NOT(ISNUMBER($G9))),"⚠ check-out is not a real date",IF(AND($J9<>"",NOT(ISNUMBER($J9))),"⚠ booking value is not a number","OK"))))) -> OK | W9: =IF(OR($B9="",NOT(ISNUMBER($J9)),$D9="Cancelled",$D9="Owner block"),"—",$J9) -> 310
A10: 6 | B10: Harbour Studio | C10: Booking.com | D10: Completed | E10: EXAMPLE — M. Silva | F10: =IFERROR(DATE(YEAR(TODAY()),MONTH(TODAY()),8),"") -> 46211 | G10: =IFERROR(DATE(YEAR(TODAY()),MONTH(TODAY()),14),"") -> 46217 | H10: =IF(OR(NOT(ISNUMBER($F10)),NOT(ISNUMBER($G10))),"—",IF($G10<=$F10,"⚠ check dates",$G10-$F10)) -> 6 | I10: 2 | J10: 455 | L10: =IF(OR($B10="",NOT(ISNUMBER($J10)),$D10="Cancelled",$D10="Owner block"),"—",ROUND($J10*IF(ISNUMBER($K10),IF($K10>1,$K10/100,$K10),IF(IFERROR(INDEX(Setup!$D$25:$D$36,MATCH($B10,Setup!$A$25:$A$36,0)),0)>1,IFERROR(INDEX(Setup!$D$25:$D$36,MATCH($B10,Setup!$A$25:$A$36,0)),0)/100,IFERROR(INDEX(Setup!$D$25:$D$36,MATCH($B10,Setup!$A$25:$A$36,0)),0))),2)) -> 68.25 | M10: =IF(NOT(ISNUMBER($L10)),"—",ROUND($J10-$L10,2)) -> 386.75 | N10: =IF(OR($B10="",$G10="",$D10="Cancelled"),"—",IFERROR(IF(INDEX(Setup!$E$25:$E$36,MATCH($B10,Setup!$A$25:$A$36,0))=0,"—",INDEX(Setup!$E$25:$E$36,MATCH($B10,Setup!$A$25:$A$36,0))),"—")) -> 38 | O10: =IF(OR($B10="",$G10="",$D10="Cancelled"),"—",IFERROR(IF(INDEX(Setup!$F$25:$F$36,MATCH($B10,Setup!$A$25:$A$36,0))=0,"—",INDEX(Setup!$F$25:$F$36,MATCH($B10,Setup!$A$25:$A$36,0))),"—")) -> 9 | P10: =IF(OR($B10="",$G10="",$D10="Cancelled",$D10="Owner block"),"—",IF(IFERROR(INDEX(Setup!$G$25:$G$36,MATCH($B10,Setup!$A$25:$A$36,0)),0)+IFERROR(INDEX(Setup!$H$25:$H$36,MATCH($B10,Setup!$A$25:$A$36,0)),0)*IF(ISNUMBER($H10),$H10,0)=0,"—",ROUND(IFERROR(INDEX(Setup!$G$25:$G$36,MATCH($B10,Setup!$A$25:$A$36,0)),0)+IFERROR(INDEX(Setup!$H$25:$H$36,MATCH($B10,Setup!$A$25:$A$36,0)),0)*IF(ISNUMBER($H10),$H10,0),2))) -> 11.7 | Q10: =IF(OR($B10="",$D10="Cancelled"),"—",IF(AND(NOT(ISNUMBER($M10)),COUNT($N10:$P10)=0),"—",ROUND(IF(ISNUMBER($M10),$M10,0)-SUM($N10:$P10),2))) -> 328.05 | R10: =IF(OR(NOT(ISNUMBER($Q10)),NOT(ISNUMBER($H10)),$H10<=0),"—",ROUND($Q10/$H10,2)) -> 54.68 | S10: The next row checks in the day this guest leaves — the Cleaning tab flags a SAME-DAY TURN. | T10: =IF(OR(NOT(ISNUMBER($F10)),NOT(ISNUMBER($G10)),NOT(ISNUMBER(Dashboard!$P$2)),NOT(ISNUMBER(Dashboard!$P$3)),$D10="Cancelled",$D10="Owner block"),"—",IF(MAX(0,MIN($G10,Dashboard!$P$3+1)-MAX($F10,Dashboard!$P$2))=0,"—",MAX(0,MIN($G10,Dashboard!$P$3+1)-MAX($F10,Dashboard!$P$2)))) -> 6 | U10: =IF(OR(NOT(ISNUMBER($F10)),NOT(ISNUMBER($G10)),NOT(ISNUMBER(Dashboard!$P$2)),NOT(ISNUMBER(Dashboard!$P$3)),$D10<>"Owner block"),"—",IF(MAX(0,MIN($G10,Dashboard!$P$3+1)-MAX($F10,Dashboard!$P$2))=0,"—",MAX(0,MIN($G10,Dashboard!$P$3+1)-MAX($F10,Dashboard!$P$2)))) -> — | V10: =IF($B10="",IF(COUNTA($C10:$G10,$I10:$K10,$S10)=0,"","⚠ no property — not counted"),IF(COUNTIF(Setup!$A$25:$A$36,$B10)=0,"⚠ property not in Setup",IF(AND($F10<>"",NOT(ISNUMBER($F10))),"⚠ check-in is not a real date",IF(AND($G10<>"",NOT(ISNUMBER($G10))),"⚠ check-out is not a real date",IF(AND($J10<>"",NOT(ISNUMBER($J10))),"⚠ booking value is not a number","OK"))))) -> OK | W10: =IF(OR($B10="",NOT(ISNUMBER($J10)),$D10="Cancelled",$D10="Owner block"),"—",$J10) -> 455
