Workbook

Sheet Start Here
B1: Freelance Invoice Tracker
B2: Write a print-ready invoice from your line items, get your next free invoice number suggested and duplicates flagged, and see who is late — every time you open it.
B3: SET UP ONCE — fill the yellow boxes. Everything else follows from them.
B4: Your business name | C4: Your business name
B5: Your name / contact person | C5: Your name
B6: Address line 1 | C6: Street 1
B7: Address line 2 — ZIP + city | C7: 12345 Your city
B8: Country | C8: Your country
B9: Email | C9: you@yourdomain.com
B10: Phone / website | C10: yourdomain.com
B11: Tax or registration number — free text, whatever your country calls it (shipped empty on purpose)
B12: Currency symbol or code — pick one or simply type your own (AED, HUF, anything) | C12: €
B13: Invoice number prefix | C13: 2026-
B14: Next free invoice number — calculates itself, never type here | C14: =IF(COUNT(Invoices!$X$8:$X$257)=0,$C$13&"001",$C$13&TEXT(MAX(Invoices!$X$8:$X$257)+1,"000")) -> 2026-009
B15: Default payment terms in days | C15: 14
B16: First reminder after … days overdue | C16: 7
B17: Second reminder after … days overdue | C17: 21
B18: Last friendly reminder after … days overdue | C18: 45
B19: Payment details, line 1 (printed on every invoice) | C19: Bank: Your Bank · IBAN 00 0000 0000 0000 0000
B20: Payment details, line 2 (printed on every invoice) | C20: PayPal: you@yourdomain.com
B21: Footer note printed on every invoice — your own tax / legal wording goes here | C21: Thank you for your business. Please pay by the due date shown above.
B22: Default rate to add, as a plain number (e.g. 10 = 10 %). Leave 0 if you do not add one. | C22: 0
B23: =IF(OR($C$16>=$C$17,$C$17>=$C$18),"Check your reminder days: the first reminder must come before the second, and the second before the last one.","")
B24: HOW TO USE THIS WORKBOOK
B25: 1 · Invoices — one row per invoice: number, date, client, project. The grey columns (due date, totals, status, days overdue, what to do next) fill themselves.
B26: 2 · Line Items — one row per item, tagged with its invoice number from the dropdown. The net amount lands back on the Invoices sheet by itself.
B27: 3 · Invoice (print) — pick a number in cell C1 and the whole document fills in. Ctrl/Cmd+P → Save as PDF; row 1 with the picker stays off the printout. Google Sheets: select A2:G45 → File → Print → Selected cells → Fit to width.
B28: 4 · Dashboard — open it any morning: what is outstanding, what is overdue, who to chase today. It recalculates every time you open the file.
B29: 5 · Below the printable invoice sits a ready-to-copy reminder email with the number, the amount, the due date and the days overdue.
B30: 6 · Lists — the four dropdown lists (stage, unit, currency, payment terms). Each dropdown reads rows 1–20 of its column, so you can add your own values in the empty cells below the last one. Nothing on that sheet is calculated.
B32: CLEAN UP THE DEMO — the file ships with eight example invoices so you can see it working. Select Invoices rows 8–15 and Line Items rows 8–27 → right-click → Delete rows. Never use 'Clear contents' on a whole row: that would take the grey formulas with it. You lose 8 of 250 template rows, nothing else.
B34: This workbook contains no tax rules, no rates and no country logic, and gives no tax, legal or accounting advice. It multiplies the percentage you type in and adds it up. Leave it at 0 if that is right for you.
B35: Whatever your country requires on an invoice — a tax line, a registration number, a small-business note — goes into C11 and C21 above. C11 ships empty on purpose; C21 holds a neutral thank-you line that you can overwrite with your own wording.
B36: Invoice numbers: this sheet suggests the next free number and flags duplicates on the spot — it cannot stop you from typing one twice. If you already have invoices from before, type your highest existing number into row 8 once; the suggestion counts up from the highest number in the sheet.
B37: Do not use * or ? inside an invoice number — both are wildcard characters and would quietly make the totals wrong. Column V on the Invoices sheet warns you if one slips in.
... B46: Questions or a broken formula? Message us on Etsy — we reply within 48 h.

Sheet Dashboard
A1: Dashboard
A2: Everything here calculates itself — there is nothing to type on this sheet.
B4: Today | C4: =TODAY() -> 46232
B6: =IF('Start Here'!$C$12="","Outstanding","Outstanding ("&'Start Here'!$C$12&")") -> Outstanding (€) | E6: =IF('Start Here'!$C$12="","Overdue now","Overdue now ("&'Start Here'!$C$12&")") -> Overdue now (€) | H6: Oldest overdue
B7: =IFERROR(SUMIF(Invoices!$Q$8:$Q$257,"Open",Invoices!$O$8:$O$257)+SUMIF(Invoices!$Q$8:$Q$257,"Overdue",Invoices!$O$8:$O$257)+SUMIF(Invoices!$Q$8:$Q$257,"Part-paid",Invoices!$O$8:$O$257),0) -> 7821 | E7: =IFERROR(SUMIF(Invoices!$Q$8:$Q$257,"Overdue",Invoices!$O$8:$O$257),0) -> 5901 | H7: =IFERROR(ROUNDDOWN(MAX(Invoices!$Z$8:$Z$257),0),0) -> 68
B8: open + overdue + part-paid, nothing else | E8: =IF(COUNTIF(Invoices!$Q$8:$Q$257,"Overdue")=0,"nothing overdue",COUNTIF(Invoices!$Q$8:$Q$257,"Overdue")&" invoice(s)") -> 3 invoice(s) | H8: the longest anyone has kept you waiting
B10: =IF('Start Here'!$C$12="","Paid — last 30 days","Paid — last 30 days ("&'Start Here'!$C$12&")") -> Paid — last 30 days (€) | E10: Average days to pay | H10: =IF('Start Here'!$C$12="","Invoiced this month","Invoiced this month ("&'Start Here'!$C$12&")") -> Invoiced this month (€)
B11: =IFERROR(SUMIFS(Invoices!$M$8:$M$257,Invoices!$N$8:$N$257,">="&(TODAY()-30),Invoices!$N$8:$N$257,"<="&TODAY(),Invoices!$Q$8:$Q$257,"<>Cancelled"),0) -> 3718.5 | E11: =IFERROR(ROUND(AVERAGE(Invoices!$AA$8:$AA$257),0),0) -> 27 | H11: =IFERROR(SUMIFS(Invoices!$L$8:$L$257,Invoices!$B$8:$B$257,">="&DATE(YEAR(TODAY()),MONTH(TODAY()),1),Invoices!$B$8:$B$257,"<="&EOMONTH(TODAY(),0),Invoices!$Q$8:$Q$257,"<>Cancelled",Invoices!$Q$8:$Q$257,"<>Draft"),0) -> 4060
B13: Next free invoice number | C13: =IF(COUNT(Invoices!$X$8:$X$257)=0,'Start Here'!$C$13&"001",'Start Here'!$C$13&TEXT(MAX(Invoices!$X$8:$X$257)+1,"000")) -> 2026-009
B14: Numbering check | C14: =IF(COUNTIF(Invoices!$V$8:$V$257,"*Duplicate*")=0,"Numbering clean",COUNTIF(Invoices!$V$8:$V$257,"*Duplicate*")&" duplicate invoice number(s) — see column V on the Invoices sheet") -> Numbering clean
B15: WHERE THE OPEN MONEY SITS
B16: Not due | C16: 1-14 days | D16: 15-30 days | E16: 31-60 days | F16: 61+ days
B17: =IFERROR(SUMIF(Invoices!$AB$8:$AB$257,"Not due",Invoices!$O$8:$O$257),0) -> 1920 | C17: =IFERROR(SUMIF(Invoices!$AB$8:$AB$257,"1-14",Invoices!$O$8:$O$257),0) -> 1240 | D17: =IFERROR(SUMIF(Invoices!$AB$8:$AB$257,"15-30",Invoices!$O$8:$O$257),0) -> 3209 | E17: =IFERROR(SUMIF(Invoices!$AB$8:$AB$257,"31-60",Invoices!$O$8:$O$257),0) -> 0 | F17: =IFERROR(SUMIF(Invoices!$AB$8:$AB$257,"61+",Invoices!$O$8:$O$257),0) -> 1452
B18: =IF(COUNTIF(Invoices!$AB$8:$AB$257,"Not due")=0,"—",COUNTIF(Invoices!$AB$8:$AB$257,"Not due")&" invoice(s)") -> 2 invoice(s) | C18: =IF(COUNTIF(Invoices!$AB$8:$AB$257,"1-14")=0,"—",COUNTIF(Invoices!$AB$8:$AB$257,"1-14")&" invoice(s)") -> 1 invoice(s) | D18: =IF(COUNTIF(Invoices!$AB$8:$AB$257,"15-30")=0,"—",COUNTIF(Invoices!$AB$8:$AB$257,"15-30")&" invoice(s)") -> 1 invoice(s) | E18: =IF(COUNTIF(Invoices!$AB$8:$AB$257,"31-60")=0,"—",COUNTIF(Invoices!$AB$8:$AB$257,"31-60")&" invoice(s)") -> — | F18: =IF(COUNTIF(Invoices!$AB$8:$AB$257,"61+")=0,"—",COUNTIF(Invoices!$AB$8:$AB$257,"61+")&" invoice(s)") -> 1 invoice(s)
B19: =IF(COUNTA(Invoices!$A$8:$A$257)=0,"No invoices yet — add your first one on the Invoices sheet. This page fills itself.","")
B20: WHO TO CHASE TODAY — the five longest-overdue invoices
B21: Invoice no. | C21: Client | D21: Open amount | E21: Days overdue | F21: Action | G21: Client email
B22: =IFERROR(IF(INDEX(Invoices!$A$8:$A$257,MATCH(LARGE(Invoices!$Z$8:$Z$257,1),Invoices!$Z$8:$Z$257,0))&""="","—",INDEX(Invoices!$A$8:$A$257,MATCH(LARGE(Invoices!$Z$8:$Z$257,1),Invoices!$Z$8:$Z$257,0))&""),"—") -> 2026-005 | C22: =IFERROR(IF(INDEX(Invoices!$E$8:$E$257,MATCH(LARGE(Invoices!$Z$8:$Z$257,1),Invoices!$Z$8:$Z$257,0))&""="","—",INDEX(Invoices!$E$8:$E$257,MATCH(LARGE(Invoices!$Z$8:$Z$257,1),Invoices!$Z$8:$Z$257,0))&""),"—") -> Bramble Coffee Co. | D22: =IFERROR(IF(INDEX(Invoices!$O$8:$O$257,MATCH(LARGE(Invoices!$Z$8:$Z$257,1),Invoices!$Z$8:$Z$257,0))="","—",INDEX(Invoices!$O$8:$O$257,MATCH(LARGE(Invoices!$Z$8:$Z$257,1),Invoices!$Z$8:$Z$257,0))),"—") -> 1452 | E22: =IFERROR(ROUNDDOWN(LARGE(Invoices!$Z$8:$Z$257,1),0),"—") -> 68 | F22: =IFERROR(IF(INDEX(Invoices!$S$8:$S$257,MATCH(LARGE(Invoices!$Z$8:$Z$257,1),Invoices!$Z$8:$Z$257,0))&""="","—",INDEX(Invoices!$S$8:$S$257,MATCH(LARGE(Invoices!$Z$8:$Z$257,1),Invoices!$Z$8:$Z$257,0))&""),"—") -> Last friendly reminder | G22: =IFERROR(IF(INDEX(Invoices!$F$8:$F$257,MATCH(LARGE(Invoices!$Z$8:$Z$257,1),Invoices!$Z$8:$Z$257,0))&""="","—",INDEX(Invoices!$F$8:$F$257,MATCH(LARGE(Invoices!$Z$8:$Z$257,1),Invoices!$Z$8:$Z$257,0))&""),"—") -> hello@bramble.example
B23: =IFERROR(IF(INDEX(Invoices!$A$8:$A$257,MATCH(LARGE(Invoices!$Z$8:$Z$257,2),Invoices!$Z$8:$Z$257,0))&""="","—",INDEX(Invoices!$A$8:$A$257,MATCH(LARGE(Invoices!$Z$8:$Z$257,2),Invoices!$Z$8:$Z$257,0))&""),"—") -> 2026-004 | C23: =IFERROR(IF(INDEX(Invoices!$E$8:$E$257,MATCH(LARGE(Invoices!$Z$8:$Z$257,2),Invoices!$Z$8:$Z$257,0))&""="","—",INDEX(Invoices!$E$8:$E$257,MATCH(LARGE(Invoices!$Z$8:$Z$257,2),Invoices!$Z$8:$Z$257,0))&""),"—") -> Northwind Studio | D23: =IFERROR(IF(INDEX(Invoices!$O$8:$O$257,MATCH(LARGE(Invoices!$Z$8:$Z$257,2),Invoices!$Z$8:$Z$257,0))="","—",INDEX(Invoices!$O$8:$O$257,MATCH(LARGE(Invoices!$Z$8:$Z$257,2),Invoices!$Z$8:$Z$257,0))),"—") -> 3209 | E23: =IFERROR(ROUNDDOWN(LARGE(Invoices!$Z$8:$Z$257,2),0),"—") -> 22 | F23: =IFERROR(IF(INDEX(Invoices!$S$8:$S$257,MATCH(LARGE(Invoices!$Z$8:$Z$257,2),Invoices!$Z$8:$Z$257,0))&""="","—",INDEX(Invoices!$S$8:$S$257,MATCH(LARGE(Invoices!$Z$8:$Z$257,2),Invoices!$Z$8:$Z$257,0))&""),"—") -> Second reminder | G23: =IFERROR(IF(INDEX(Invoices!$F$8:$F$257,MATCH(LARGE(Invoices!$Z$8:$Z$257,2),Invoices!$Z$8:$Z$257,0))&""="","—",INDEX(Invoices!$F$8:$F$257,MATCH(LARGE(Invoices!$Z$8:$Z$257,2),Invoices!$Z$8:$Z$257,0))&""),"—") -> ana@northwind.example
B24: =IFERROR(IF(INDEX(Invoices!$A$8:$A$257,MATCH(LARGE(Invoices!$Z$8:$Z$257,3),Invoices!$Z$8:$Z$257,0))&""="","—",INDEX(Invoices!$A$8:$A$257,MATCH(LARGE(Invoices!$Z$8:$Z$257,3),Invoices!$Z$8:$Z$257,0))&""),"—") -> 2026-003 | C24: =IFERROR(IF(INDEX(Invoices!$E$8:$E$257,MATCH(LARGE(Invoices!$Z$8:$Z$257,3),Invoices!$Z$8:$Z$257,0))&""="","—",INDEX(Invoices!$E$8:$E$257,MATCH(LARGE(Invoices!$Z$8:$Z$257,3),Invoices!$Z$8:$Z$257,0))&""),"—") -> Marisol Ferrer | D24: =IFERROR(IF(INDEX(Invoices!$O$8:$O$257,MATCH(LARGE(Invoices!$Z$8:$Z$257,3),Invoices!$Z$8:$Z$257,0))="","—",INDEX(Invoices!$O$8:$O$257,MATCH(LARGE(Invoices!$Z$8:$Z$257,3),Invoices!$Z$8:$Z$257,0))),"—") -> 1240 | E24: =IFERROR(ROUNDDOWN(LARGE(Invoices!$Z$8:$Z$257,3),0),"—") -> 12 | F24: =IFERROR(IF(INDEX(Invoices!$S$8:$S$257,MATCH(LARGE(Invoices!$Z$8:$Z$257,3),Invoices!$Z$8:$Z$257,0))&""="","—",INDEX(Invoices!$S$8:$S$257,MATCH(LARGE(Invoices!$Z$8:$Z$257,3),Invoices!$Z$8:$Z$257,0))&""),"—") -> First reminder | G24: =IFERROR(IF(INDEX(Invoices!$F$8:$F$257,MATCH(LARGE(Invoices!$Z$8:$Z$257,3),Invoices!$Z$8:$Z$257,0))&""="","—",INDEX(Invoices!$F$8:$F$257,MATCH(LARGE(Invoices!$Z$8:$Z$257,3),Invoices!$Z$8:$Z$257,0))&""),"—") -> marisol@ferrer.example
B25: =IFERROR(IF(INDEX(Invoices!$A$8:$A$257,MATCH(LARGE(Invoices!$Z$8:$Z$257,4),Invoices!$Z$8:$Z$257,0))&""="","—",INDEX(Invoices!$A$8:$A$257,MATCH(LARGE(Invoices!$Z$8:$Z$257,4),Invoices!$Z$8:$Z$257,0))&""),"—") -> — | C25: =IFERROR(IF(INDEX(Invoices!$E$8:$E$257,MATCH(LARGE(Invoices!$Z$8:$Z$257,4),Invoices!$Z$8:$Z$257,0))&""="","—",INDEX(Invoices!$E$8:$E$257,MATCH(LARGE(Invoices!$Z$8:$Z$257,4),Invoices!$Z$8:$Z$257,0))&""),"—") -> — | D25: =IFERROR(IF(INDEX(Invoices!$O$8:$O$257,MATCH(LARGE(Invoices!$Z$8:$Z$257,4),Invoices!$Z$8:$Z$257,0))="","—",INDEX(Invoices!$O$8:$O$257,MATCH(LARGE(Invoices!$Z$8:$Z$257,4),Invoices!$Z$8:$Z$257,0))),"—") -> — | E25: =IFERROR(ROUNDDOWN(LARGE(Invoices!$Z$8:$Z$257,4),0),"—") -> — | F25: =IFERROR(IF(INDEX(Invoices!$S$8:$S$257,MATCH(LARGE(Invoices!$Z$8:$Z$257,4),Invoices!$Z$8:$Z$257,0))&""="","—",INDEX(Invoices!$S$8:$S$257,MATCH(LARGE(Invoices!$Z$8:$Z$257,4),Invoices!$Z$8:$Z$257,0))&""),"—") -> — | G25: =IFERROR(IF(INDEX(Invoices!$F$8:$F$257,MATCH(LARGE(Invoices!$Z$8:$Z$257,4),Invoices!$Z$8:$Z$257,0))&""="","—",INDEX(Invoices!$F$8:$F$257,MATCH(LARGE(Invoices!$Z$8:$Z$257,4),Invoices!$Z$8:$Z$257,0))&""),"—") -> —
B26: =IFERROR(IF(INDEX(Invoices!$A$8:$A$257,MATCH(LARGE(Invoices!$Z$8:$Z$257,5),Invoices!$Z$8:$Z$257,0))&""="","—",INDEX(Invoices!$A$8:$A$257,MATCH(LARGE(Invoices!$Z$8:$Z$257,5),Invoices!$Z$8:$Z$257,0))&""),"—") -> — | C26: =IFERROR(IF(INDEX(Invoices!$E$8:$E$257,MATCH(LARGE(Invoices!$Z$8:$Z$257,5),Invoices!$Z$8:$Z$257,0))&""="","—",INDEX(Invoices!$E$8:$E$257,MATCH(LARGE(Invoices!$Z$8:$Z$257,5),Invoices!$Z$8:$Z$257,0))&""),"—") -> — | D26: =IFERROR(IF(INDEX(Invoices!$O$8:$O$257,MATCH(LARGE(Invoices!$Z$8:$Z$257,5),Invoices!$Z$8:$Z$257,0))="","—",INDEX(Invoices!$O$8:$O$257,MATCH(LARGE(Invoices!$Z$8:$Z$257,5),Invoices!$Z$8:$Z$257,0))),"—") -> — | E26: =IFERROR(ROUNDDOWN(LARGE(Invoices!$Z$8:$Z$257,5),0),"—") -> — | F26: =IFERROR(IF(INDEX(Invoices!$S$8:$S$257,MATCH(LARGE(Invoices!$Z$8:$Z$257,5),Invoices!$Z$8:$Z$257,0))&""="","—",INDEX(Invoices!$S$8:$S$257,MATCH(LARGE(Invoices!$Z$8:$Z$257,5),Invoices!$Z$8:$Z$257,0))&""),"—") -> — | G26: =IFERROR(IF(INDEX(Invoices!$F$8:$F$257,MATCH(LARGE(Invoices!$Z$8:$Z$257,5),Invoices!$Z$8:$Z$257,0))&""="","—",INDEX(Invoices!$F$8:$F$257,MATCH(LARGE(Invoices!$Z$8:$Z$257,5),Invoices!$Z$8:$Z$257,0))&""),"—") -> —
B27: =IF(COUNTIF(Invoices!$Q$8:$Q$257,"Overdue")>5,"+"&COUNTIF(Invoices!$Q$8:$Q$257,"Overdue")-5&" more overdue — see the Invoices sheet","")

Sheet Invoices
A1: Invoices
A2: One row per invoice. Type in the yellow columns — the grey ones work out the due date, the totals, the status and what to do next.
A4: Yellow = you type. Grey = calculates itself — never type in a grey cell. | J4: This workbook contains no tax rules, no rates and no country logic, and gives no tax, legal or accounting advice. It multiplies the percentage you type in and adds it up.
A5: Demo: rows 8–15 hold eight example invoices and use live formulas (=TODAY()-n) so the file never looks stale. To start clean: select rows 8–15 → right-click → Delete rows. You lose 8 of 250 template rows, nothing else. Do NOT use 'Clear contents' on a whole row — that removes the grey formulas too.
A7: Invoice no. | B7: Invoice date | C7: Terms (days) | D7: Due date | E7: Client | F7: Client email | G7: Client address (Alt+Enter = new line) | H7: Project / reference | I7: =IF('Start Here'!$C$12="","Net amount","Net amount ("&'Start Here'!$C$12&")") -> Net amount (€) | J7: Tax rate % | K7: =IF('Start Here'!$C$12="","Tax amount","Tax amount ("&'Start Here'!$C$12&")") -> Tax amount (€) | L7: =IF('Start Here'!$C$12="","Total","Total ("&'Start Here'!$C$12&")") -> Total (€) | M7: =IF('Start Here'!$C$12="","Paid amount","Paid amount ("&'Start Here'!$C$12&")") -> Paid amount (€) | N7: Paid date | O7: =IF('Start Here'!$C$12="","Open amount","Open amount ("&'Start Here'!$C$12&")") -> Open amount (€) | P7: Stage | Q7: Status | R7: Days overdue | S7: Action | T7: Follow-up sent on | U7: Notes | V7: Check — blank means all good | X7: NumTail (helper) | Y7: ClientAddrKey (helper) | Z7: OverdueSortKey (helper) | AA7: DaysToPay (helper) | AB7: AgeingBucket (helper)
A8: 2026-001 | B8: =TODAY()-54 -> 46178 | C8: 14 | D8: =IF($B8="","",$B8+IF($C8="",IF('Start Here'!$C$15="",14,'Start Here'!$C$15),$C8)) -> 46192 | E8: Northwind Studio | F8: ana@northwind.example | G8: Northwind Studio Harbour Road 12 2000 Antwerp Belgium | H8: Brand website copy | I8: =IF($A8="","",ROUND(SUMIF('Line Items'!$A$8:$A$507,$A8,'Line Items'!$H$8:$H$507),2)) -> 1195 | J8: 0 | K8: =IF($A8="","",ROUND($I8*IFERROR(IF($J8="",IF('Start Here'!$C$22="",0,'Start Here'!$C$22),$J8),0)/100,2)) -> 0 | L8: =IF($A8="","",ROUND($I8+$K8,2)) -> 1195 | M8: 1195 | N8: =TODAY()-42 -> 46190 | O8: =IF($A8="","",ROUND($L8-IF($M8="",0,$M8),2)) -> 0 | Q8: =IF($A8="","",IF($P8="Cancelled","Cancelled",IF($P8="Draft","Draft",IF($L8=0,"No lines yet",IF($O8<=0,"Paid",IF($D8="","No date",IF($D8<TODAY(),"Overdue",IF(IF($M8="",0,$M8)>0,"Part-paid","Open")))))))) -> Paid | R8: =IF($A8="","",IF($Q8<>"Overdue","—",TODAY()-$D8)) -> — | S8: =IF($A8="","",IF(OR($Q8="Paid",$Q8="Cancelled",$Q8="Draft"),"—",IF($Q8="No lines yet","Add line items",IF($Q8="No date","Add invoice date",IF($D8-TODAY()>7,"—",IF($D8-TODAY()>=1,"Due soon",IF($D8=TODAY(),"Due today",IF(TODAY()-$D8<IF('Start Here'!$C$16="",7,'Start Here'!$C$16),"Just overdue",IF(TODAY()-$D8<IF('Start Here'!$C$17="",21,'Start Here'!$C$17),"First reminder",IF(TODAY()-$D8<IF('Start Here'!$C$18="",45,'Start Here'!$C$18),"Second reminder","Last friendly reminder")))))))))) -> — | U8: Paid 12 days after the invoice date. | V8: =IF($A8="","",TRIM(IF(COUNTIF($A$8:$A$257,$A8)>1,"Duplicate no. ","")&IF(ISNUMBER(FIND("*",$A8))+ISNUMBER(FIND("?",$A8))>0,"Avoid * and ? in invoice numbers ","")&IF($E8="","No client ","")&IF($L8=0,"No amount ","")&IF(AND($Q8="Overdue",$F8=""),"No client email ",""))) | X8: =IF($A8="","",IFERROR(VALUE(IF('Start Here'!$C$13="",$A8,SUBSTITUTE($A8,'Start Here'!$C$13,""))),"")) -> 1 | Y8: =IF(AND($E8<>"",$G8<>""),$E8,"") -> Northwind Studio | Z8: =IF($A8="","",IF($Q8<>"Overdue","",(TODAY()-$D8)+ROW()/100000)) | AA8: =IF($A8="","",IF(AND($Q8="Paid",ISNUMBER($N8),ISNUMBER($B8)),$N8-$B8,"")) -> 12 | AB8: =IF($A8="","",IF(OR($Q8="Paid",$Q8="Draft",$Q8="Cancelled",$Q8="No lines yet",$Q8="No date"),"",IF($Q8<>"Overdue","Not due",IF(TODAY()-$D8<=14,"1-14",IF(TODAY()-$D8<=30,"15-30",IF(TODAY()-$D8<=60,"31-60","61+"))))))
A9: 2026-002 | B9: =TODAY()-70 -> 46162 | C9: 30 | D9: =IF($B9="","",$B9+IF($C9="",IF('Start Here'!$C$15="",14,'Start Here'!$C$15),$C9)) -> 46192 | E9: Halden & Voss | F9: billing@haldenvoss.example | G9: Halden & Voss Rathausplatz 4 8000 Zurich Switzerland | H9: Q2 analytics dashboard | I9: =IF($A9="","",ROUND(SUMIF('Line Items'!$A$8:$A$507,$A9,'Line Items'!$H$8:$H$507),2)) -> 2818.5 | J9: 0 | K9: =IF($A9="","",ROUND($I9*IFERROR(IF($J9="",IF('Start Here'!$C$22="",0,'Start Here'!$C$22),$J9),0)/100,2)) -> 0 | L9: =IF($A9="","",ROUND($I9+$K9,2)) -> 2818.5 | M9: 2818.5 | N9: =TODAY()-28 -> 46204 | O9: =IF($A9="","",ROUND($L9-IF($M9="",0,$M9),2)) -> 0 | Q9: =IF($A9="","",IF($P9="Cancelled","Cancelled",IF($P9="Draft","Draft",IF($L9=0,"No lines yet",IF($O9<=0,"Paid",IF($D9="","No date",IF($D9<TODAY(),"Overdue",IF(IF($M9="",0,$M9)>0,"Part-paid","Open")))))))) -> Paid | R9: =IF($A9="","",IF($Q9<>"Overdue","—",TODAY()-$D9)) -> — | S9: =IF($A9="","",IF(OR($Q9="Paid",$Q9="Cancelled",$Q9="Draft"),"—",IF($Q9="No lines yet","Add line items",IF($Q9="No date","Add invoice date",IF($D9-TODAY()>7,"—",IF($D9-TODAY()>=1,"Due soon",IF($D9=TODAY(),"Due today",IF(TODAY()-$D9<IF('Start Here'!$C$16="",7,'Start Here'!$C$16),"Just overdue",IF(TODAY()-$D9<IF('Start Here'!$C$17="",21,'Start Here'!$C$17),"First reminder",IF(TODAY()-$D9<IF('Start Here'!$C$18="",45,'Start Here'!$C$18),"Second reminder","Last friendly reminder")))))))))) -> — | U9: Slow payer: 42 days. Consider a deposit next time. | V9: =IF($A9="","",TRIM(IF(COUNTIF($A$8:$A$257,$A9)>1,"Duplicate no. ","")&IF(ISNUMBER(FIND("*",$A9))+ISNUMBER(FIND("?",$A9))>0,"Avoid * and ? in invoice numbers ","")&IF($E9="","No client ","")&IF($L9=0,"No amount ","")&IF(AND($Q9="Overdue",$F9=""),"No client email ",""))) | X9: =IF($A9="","",IFERROR(VALUE(IF('Start Here'!$C$13="",$A9,SUBSTITUTE($A9,'Start Here'!$C$13,""))),"")) -> 2 | Y9: =IF(AND($E9<>"",$G9<>""),$E9,"") -> Halden & Voss | Z9: =IF($A9="","",IF($Q9<>"Overdue","",(TODAY()-$D9)+ROW()/100000)) | AA9: =IF($A9="","",IF(AND($Q9="Paid",ISNUMBER($N9),ISNUMBER($B9)),$N9-$B9,"")) -> 42 | AB9: =IF($A9="","",IF(OR($Q9="Paid",$Q9="Draft",$Q9="Cancelled",$Q9="No lines yet",$Q9="No date"),"",IF($Q9<>"Overdue","Not due",IF(TODAY()-$D9<=14,"1-14",IF(TODAY()-$D9<=30,"15-30",IF(TODAY()-$D9<=60,"31-60","61+"))))))
A10: 2026-003 | B10: =TODAY()-26 -> 46206 | C10: 14 | D10: =IF($B10="","",$B10+IF($C10="",IF('Start Here'!$C$15="",14,'Start Here'!$C$15),$C10)) -> 46220 | E10: Marisol Ferrer | F10: marisol@ferrer.example | G10: Marisol Ferrer Calle Mayor 8 28013 Madrid Spain | H10: Podcast editing, April | I10: =IF($A10="","",ROUND(SUMIF('Line Items'!$A$8:$A$507,$A10,'Line Items'!$H$8:$H$507),2)) -> 1240 | J10: 0 | K10: =IF($A10="","",ROUND($I10*IFERROR(IF($J10="",IF('Start Here'!$C$22="",0,'Start Here'!$C$22),$J10),0)/100,2)) -> 0 | L10: =IF($A10="","",ROUND($I10+$K10,2)) -> 1240 | O10: =IF($A10="","",ROUND($L10-IF($M10="",0,$M10),2)) -> 1240 | P10: Sent | Q10: =IF($A10="","",IF($P10="Cancelled","Cancelled",IF($P10="Draft","Draft",IF($L10=0,"No lines yet",IF($O10<=0,"Paid",IF($D10="","No date",IF($D10<TODAY(),"Overdue",IF(IF($M10="",0,$M10)>0,"Part-paid","Open")))))))) -> Overdue | R10: =IF($A10="","",IF($Q10<>"Overdue","—",TODAY()-$D10)) -> 12 | S10: =IF($A10="","",IF(OR($Q10="Paid",$Q10="Cancelled",$Q10="Draft"),"—",IF($Q10="No lines yet","Add line items",IF($Q10="No date","Add invoice date",IF($D10-TODAY()>7,"—",IF($D10-TODAY()>=1,"Due soon",IF($D10=TODAY(),"Due today",IF(TODAY()-$D10<IF('Start Here'!$C$16="",7,'Start Here'!$C$16),"Just overdue",IF(TODAY()-$D10<IF('Start Here'!$C$17="",21,'Start Here'!$C$17),"First reminder",IF(TODAY()-$D10<IF('Start Here'!$C$18="",45,'Start Here'!$C$18),"Second reminder","Last friendly reminder")))))))))) -> First reminder | T10: =TODAY()-5 -> 46227 | U10: First reminder sent. | V10: =IF($A10="","",TRIM(IF(COUNTIF($A$8:$A$257,$A10)>1,"Duplicate no. ","")&IF(ISNUMBER(FIND("*",$A10))+ISNUMBER(FIND("?",$A10))>0,"Avoid * and ? in invoice numbers ","")&IF($E10="","No client ","")&IF($L10=0,"No amount ","")&IF(AND($Q10="Overdue",$F10=""),"No client email ",""))) | X10: =IF($A10="","",IFERROR(VALUE(IF('Start Here'!$C$13="",$A10,SUBSTITUTE($A10,'Start Here'!$C$13,""))),"")) -> 3 | Y10: =IF(AND($E10<>"",$G10<>""),$E10,"") -> Marisol Ferrer | Z10: =IF($A10="","",IF($Q10<>"Overdue","",(TODAY()-$D10)+ROW()/100000)) -> 12.0001 | AA10: =IF($A10="","",IF(AND($Q10="Paid",ISNUMBER($N10),ISNUMBER($B10)),$N10-$B10,"")) | AB10: =IF($A10="","",IF(OR($Q10="Paid",$Q10="Draft",$Q10="Cancelled",$Q10="No lines yet",$Q10="No date"),"",IF($Q10<>"Overdue","Not due",IF(TODAY()-$D10<=14,"1-14",IF(TODAY()-$D10<=30,"15-30",IF(TODAY()-$D10<=60,"31-60","61+")))))) -> 1-14
A11: 2026-004 | B11: =TODAY()-52 -> 46180 | C11: 30 | D11: =IF($B11="","",$B11+IF($C11="",IF('Start Here'!$C$15="",14,'Start Here'!$C$15),$C11)) -> 46210 | E11: Northwind Studio | F11: ana@northwind.example | H11: Website relaunch, phase 2 | I11: =IF($A11="","",ROUND(SUMIF('Line Items'!$A$8:$A$507,$A11,'Line Items'!$H$8:$H$507),2)) -> 3209 | J11: 0 | K11: =IF($A11="","",ROUND($I11*IFERROR(IF($J11="",IF('Start Here'!$C$22="",0,'Start Here'!$C$22),$J11),0)/100,2)) -> 0 | L11: =IF($A11="","",ROUND($I11+$K11,2)) -> 3209 | O11: =IF($A11="","",ROUND($L11-IF($M11="",0,$M11),2)) -> 3209 | P11: Sent | Q11: =IF($A11="","",IF($P11="Cancelled","Cancelled",IF($P11="Draft","Draft",IF($L11=0,"No lines yet",IF($O11<=0,"Paid",IF($D11="","No date",IF($D11<TODAY(),"Overdue",IF(IF($M11="",0,$M11)>0,"Part-paid","Open")))))))) -> Overdue | R11: =IF($A11="","",IF($Q11<>"Overdue","—",TODAY()-$D11)) -> 22 | S11: =IF($A11="","",IF(OR($Q11="Paid",$Q11="Cancelled",$Q11="Draft"),"—",IF($Q11="No lines yet","Add line items",IF($Q11="No date","Add invoice date",IF($D11-TODAY()>7,"—",IF($D11-TODAY()>=1,"Due soon",IF($D11=TODAY(),"Due today",IF(TODAY()-$D11<IF('Start Here'!$C$16="",7,'Start Here'!$C$16),"Just overdue",IF(TODAY()-$D11<IF('Start Here'!$C$17="",21,'Start Here'!$C$17),"First reminder",IF(TODAY()-$D11<IF('Start Here'!$C$18="",45,'Start Here'!$C$18),"Second reminder","Last friendly reminder")))))))))) -> Second reminder | T11: =TODAY()-8 -> 46224 | U11: Address fills itself from invoice 2026-001. | V11: =IF($A11="","",TRIM(IF(COUNTIF($A$8:$A$257,$A11)>1,"Duplicate no. ","")&IF(ISNUMBER(FIND("*",$A11))+ISNUMBER(FIND("?",$A11))>0,"Avoid * and ? in invoice numbers ","")&IF($E11="","No client ","")&IF($L11=0,"No amount ","")&IF(AND($Q11="Overdue",$F11=""),"No client email ",""))) | X11: =IF($A11="","",IFERROR(VALUE(IF('Start Here'!$C$13="",$A11,SUBSTITUTE($A11,'Start Here'!$C$13,""))),"")) -> 4 | Y11: =IF(AND($E11<>"",$G11<>""),$E11,"") | Z11: =IF($A11="","",IF($Q11<>"Overdue","",(TODAY()-$D11)+ROW()/100000)) -> 22.00011 | AA11: =IF($A11="","",IF(AND($Q11="Paid",ISNUMBER($N11),ISNUMBER($B11)),$N11-$B11,"")) | AB11: =IF($A11="","",IF(OR($Q11="Paid",$Q11="Draft",$Q11="Cancelled",$Q11="No lines yet",$Q11="No date"),"",IF($Q11<>"Overdue","Not due",IF(TODAY()-$D11<=14,"1-14",IF(TODAY()-$D11<=30,"15-30",IF(TODAY()-$D11<=60,"31-60","61+")))))) -> 15-30
A12: 2026-005 | B12: =TODAY()-82 -> 46150 | C12: 14 | D12: =IF($B12="","",$B12+IF($C12="",IF('Start Here'!$C$15="",14,'Start Here'!$C$15),$C12)) -> 46164 | E12: Bramble Coffee Co. | F12: hello@bramble.example | G12: Bramble Coffee Co. Mill Lane 3 Bristol BS1 4QD United Kingdom | H12: Menu and packaging artwork | I12: =IF($A12="","",ROUND(SUMIF('Line Items'!$A$8:$A$507,$A12,'Line Items'!$H$8:$H$507),2)) -> 1320 | J12: 10 | K12: =IF($A12="","",ROUND($I12*IFERROR(IF($J12="",IF('Start Here'!$C$22="",0,'Start Here'!$C$22),$J12),0)/100,2)) -> 132 | L12: =IF($A12="","",ROUND($I12+$K12,2)) -> 1452 | O12: =IF($A12="","",ROUND($L12-IF($M12="",0,$M12),2)) -> 1452 | P12: Sent | Q12: =IF($A12="","",IF($P12="Cancelled","Cancelled",IF($P12="Draft","Draft",IF($L12=0,"No lines yet",IF($O12<=0,"Paid",IF($D12="","No date",IF($D12<TODAY(),"Overdue",IF(IF($M12="",0,$M12)>0,"Part-paid","Open")))))))) -> Overdue | R12: =IF($A12="","",IF($Q12<>"Overdue","—",TODAY()-$D12)) -> 68 | S12: =IF($A12="","",IF(OR($Q12="Paid",$Q12="Cancelled",$Q12="Draft"),"—",IF($Q12="No lines yet","Add line items",IF($Q12="No date","Add invoice date",IF($D12-TODAY()>7,"—",IF($D12-TODAY()>=1,"Due soon",IF($D12=TODAY(),"Due today",IF(TODAY()-$D12<IF('Start Here'!$C$16="",7,'Start Here'!$C$16),"Just overdue",IF(TODAY()-$D12<IF('Start Here'!$C$17="",21,'Start Here'!$C$17),"First reminder",IF(TODAY()-$D12<IF('Start Here'!$C$18="",45,'Start Here'!$C$18),"Second reminder","Last friendly reminder")))))))))) -> Last friendly reminder | T12: =TODAY()-20 -> 46212 | U12: Shows the rate column: 10 typed in, 10 % added. Nothing preset. | V12: =IF($A12="","",TRIM(IF(COUNTIF($A$8:$A$257,$A12)>1,"Duplicate no. ","")&IF(ISNUMBER(FIND("*",$A12))+ISNUMBER(FIND("?",$A12))>0,"Avoid * and ? in invoice numbers ","")&IF($E12="","No client ","")&IF($L12=0,"No amount ","")&IF(AND($Q12="Overdue",$F12=""),"No client email ",""))) | X12: =IF($A12="","",IFERROR(VALUE(IF('Start Here'!$C$13="",$A12,SUBSTITUTE($A12,'Start Here'!$C$13,""))),"")) -> 5 | Y12: =IF(AND($E12<>"",$G12<>""),$E12,"") -> Bramble Coffee Co. | Z12: =IF($A12="","",IF($Q12<>"Overdue","",(TODAY()-$D12)+ROW()/100000)) -> 68.00012 | AA12: =IF($A12="","",IF(AND($Q12="Paid",ISNUMBER($N12),ISNUMBER($B12)),$N12-$B12,"")) | AB12: =IF($A12="","",IF(OR($Q12="Paid",$Q12="Draft",$Q12="Cancelled",$Q12="No lines yet",$Q12="No date"),"",IF($Q12<>"Overdue","Not due",IF(TODAY()-$D12<=14,"1-14",IF(TODAY()-$D12<=30,"15-30",IF(TODAY()-$D12<=60,"31-60","61+")))))) -> 61+
A13: 2026-006 | B13: =TODAY()-3 -> 46229 | C13: 14 | D13: =IF($B13="","",$B13+IF($C13="",IF('Start Here'!$C$15="",14,'Start Here'!$C$15),$C13)) -> 46243 | E13: Larkfield Books | F13: accounts@larkfield.example | G13: Larkfield Books 17 Cedar Street Dublin D02 Ireland | H13: Editorial retainer | I13: =IF($A13="","",ROUND(SUMIF('Line Items'!$A$8:$A$507,$A13,'Line Items'!$H$8:$H$507),2)) -> 1800 | J13: 0 | K13: =IF($A13="","",ROUND($I13*IFERROR(IF($J13="",IF('Start Here'!$C$22="",0,'Start Here'!$C$22),$J13),0)/100,2)) -> 0 | L13: =IF($A13="","",ROUND($I13+$K13,2)) -> 1800 | M13: 900 | N13: =TODAY()-2 -> 46230 | O13: =IF($A13="","",ROUND($L13-IF($M13="",0,$M13),2)) -> 900 | Q13: =IF($A13="","",IF($P13="Cancelled","Cancelled",IF($P13="Draft","Draft",IF($L13=0,"No lines yet",IF($O13<=0,"Paid",IF($D13="","No date",IF($D13<TODAY(),"Overdue",IF(IF($M13="",0,$M13)>0,"Part-paid","Open")))))))) -> Part-paid | R13: =IF($A13="","",IF($Q13<>"Overdue","—",TODAY()-$D13)) -> — | S13: =IF($A13="","",IF(OR($Q13="Paid",$Q13="Cancelled",$Q13="Draft"),"—",IF($Q13="No lines yet","Add line items",IF($Q13="No date","Add invoice date",IF($D13-TODAY()>7,"—",IF($D13-TODAY()>=1,"Due soon",IF($D13=TODAY(),"Due today",IF(TODAY()-$D13<IF('Start Here'!$C$16="",7,'Start Here'!$C$16),"Just overdue",IF(TODAY()-$D13<IF('Start Here'!$C$17="",21,'Start Here'!$C$17),"First reminder",IF(TODAY()-$D13<IF('Start Here'!$C$18="",45,'Start Here'!$C$18),"Second reminder","Last friendly reminder")))))))))) -> — | U13: 50 % deposit received, rest due with the invoice. | V13: =IF($A13="","",TRIM(IF(COUNTIF($A$8:$A$257,$A13)>1,"Duplicate no. ","")&IF(ISNUMBER(FIND("*",$A13))+ISNUMBER(FIND("?",$A13))>0,"Avoid * and ? in invoice numbers ","")&IF($E13="","No client ","")&IF($L13=0,"No amount ","")&IF(AND($Q13="Overdue",$F13=""),"No client email ",""))) | X13: =IF($A13="","",IFERROR(VALUE(IF('Start Here'!$C$13="",$A13,SUBSTITUTE($A13,'Start Here'!$C$13,""))),"")) -> 6 | Y13: =IF(AND($E13<>"",$G13<>""),$E13,"") -> Larkfield Books | Z13: =IF($A13="","",IF($Q13<>"Overdue","",(TODAY()-$D13)+ROW()/100000)) | AA13: =IF($A13="","",IF(AND($Q13="Paid",ISNUMBER($N13),ISNUMBER($B13)),$N13-$B13,"")) | AB13: =IF($A13="","",IF(OR($Q13="Paid",$Q13="Draft",$Q13="Cancelled",$Q13="No lines yet",$Q13="No date"),"",IF($Q13<>"Overdue","Not due",IF(TODAY()-$D13<=14,"1-14",IF(TODAY()-$D13<=30,"15-30",IF(TODAY()-$D13<=60,"31-60","61+")))))) -> Not due
A14: 2026-007 | B14: =TODAY() -> 46232 | C14: 14 | D14: =IF($B14="","",$B14+IF($C14="",IF('Start Here'!$C$15="",14,'Start Here'!$C$15),$C14)) -> 46246 | E14: Marisol Ferrer | F14: marisol@ferrer.example | H14: Podcast editing, May | I14: =IF($A14="","",ROUND(SUMIF('Line Items'!$A$8:$A$507,$A14,'Line Items'!$H$8:$H$507),2)) -> 1020 | J14: 0 | K14: =IF($A14="","",ROUND($I14*IFERROR(IF($J14="",IF('Start Here'!$C$22="",0,'Start Here'!$C$22),$J14),0)/100,2)) -> 0 | L14: =IF($A14="","",ROUND($I14+$K14,2)) -> 1020 | O14: =IF($A14="","",ROUND($L14-IF($M14="",0,$M14),2)) -> 1020 | Q14: =IF($A14="","",IF($P14="Cancelled","Cancelled",IF($P14="Draft","Draft",IF($L14=0,"No lines yet",IF($O14<=0,"Paid",IF($D14="","No date",IF($D14<TODAY(),"Overdue",IF(IF($M14="",0,$M14)>0,"Part-paid","Open")))))))) -> Open | R14: =IF($A14="","",IF($Q14<>"Overdue","—",TODAY()-$D14)) -> — | S14: =IF($A14="","",IF(OR($Q14="Paid",$Q14="Cancelled",$Q14="Draft"),"—",IF($Q14="No lines yet","Add line items",IF($Q14="No date","Add invoice date",IF($D14-TODAY()>7,"—",IF($D14-TODAY()>=1,"Due soon",IF($D14=TODAY(),"Due today",IF(TODAY()-$D14<IF('Start Here'!$C$16="",7,'Start Here'!$C$16),"Just overdue",IF(TODAY()-$D14<IF('Start Here'!$C$17="",21,'Start Here'!$C$17),"First reminder",IF(TODAY()-$D14<IF('Start Here'!$C$18="",45,'Start Here'!$C$18),"Second reminder","Last friendly reminder")))))))))) -> — | U14: Issued today — nothing to chase yet. | V14: =IF($A14="","",TRIM(IF(COUNTIF($A$8:$A$257,$A14)>1,"Duplicate no. ","")&IF(ISNUMBER(FIND("*",$A14))+ISNUMBER(FIND("?",$A14))>0,"Avoid * and ? in invoice numbers ","")&IF($E14="","No client ","")&IF($L14=0,"No amount ","")&IF(AND($Q14="Overdue",$F14=""),"No client email ",""))) | X14: =IF($A14="","",IFERROR(VALUE(IF('Start Here'!$C$13="",$A14,SUBSTITUTE($A14,'Start Here'!$C$13,""))),"")) -> 7 | Y14: =IF(AND($E14<>"",$G14<>""),$E14,"") | Z14: =IF($A14="","",IF($Q14<>"Overdue","",(TODAY()-$D14)+ROW()/100000)) | AA14: =IF($A14="","",IF(AND($Q14="Paid",ISNUMBER($N14),ISNUMBER($B14)),$N14-$B14,"")) | AB14: =IF($A14="","",IF(OR($Q14="Paid",$Q14="Draft",$Q14="Cancelled",$Q14="No lines yet",$Q14="No date"),"",IF($Q14<>"Overdue","Not due",IF(TODAY()-$D14<=14,"1-14",IF(TODAY()-$D14<=30,"15-30",IF(TODAY()-$D14<=60,"31-60","61+")))))) -> Not due
A15: 2026-008 | B15: =TODAY()-1 -> 46231 | C15: 14 | D15: =IF($B15="","",$B15+IF($C15="",IF('Start Here'!$C$15="",14,'Start Here'!$C$15),$C15)) -> 46245 | E15: Kestrel Fitness | F15: sam@kestrel.example | G15: Kestrel Fitness Schoolhouse Yard 2 10119 Berlin Germany | H15: Coaching site refresh | I15: =IF($A15="","",ROUND(SUMIF('Line Items'!$A$8:$A$507,$A15,'Line Items'!$H$8:$H$507),2)) -> 535 | J15: 0 | K15: =IF($A15="","",ROUND($I15*IFERROR(IF($J15="",IF('Start Here'!$C$22="",0,'Start Here'!$C$22),$J15),0)/100,2)) -> 0 | L15: =IF($A15="","",ROUND($I15+$K15,2)) -> 535 | O15: =IF($A15="","",ROUND($L15-IF($M15="",0,$M15),2)) -> 535 | P15: Draft | Q15: =IF($A15="","",IF($P15="Cancelled","Cancelled",IF($P15="Draft","Draft",IF($L15=0,"No lines yet",IF($O15<=0,"Paid",IF($D15="","No date",IF($D15<TODAY(),"Overdue",IF(IF($M15="",0,$M15)>0,"Part-paid","Open")))))))) -> Draft | R15: =IF($A15="","",IF($Q15<>"Overdue","—",TODAY()-$D15)) -> — | S15: =IF($A15="","",IF(OR($Q15="Paid",$Q15="Cancelled",$Q15="Draft"),"—",IF($Q15="No lines yet","Add line items",IF($Q15="No date","Add invoice date",IF($D15-TODAY()>7,"—",IF($D15-TODAY()>=1,"Due soon",IF($D15=TODAY(),"Due today",IF(TODAY()-$D15<IF('Start Here'!$C$16="",7,'Start Here'!$C$16),"Just overdue",IF(TODAY()-$D15<IF('Start Here'!$C$17="",21,'Start Here'!$C$17),"First reminder",IF(TODAY()-$D15<IF('Start Here'!$C$18="",45,'Start Here'!$C$18),"Second reminder","Last friendly reminder")))))))))) -> — | U15: Draft: counts nowhere until you change the stage. | V15: =IF($A15="","",TRIM(IF(COUNTIF($A$8:$A$257,$A15)>1,"Duplicate no. ","")&IF(ISNUMBER(FIND("*",$A15))+ISNUMBER(FIND("?",$A15))>0,"Avoid * and ? in invoice numbers ","")&IF($E15="","No client ","")&IF($L15=0,"No amount ","")&IF(AND($Q15="Overdue",$F15=""),"No client email ",""))) | X15: =IF($A15="","",IFERROR(VALUE(IF('Start Here'!$C$13="",$A15,SUBSTITUTE($A15,'Start Here'!$C$13,""))),"")) -> 8 | Y15: =IF(AND($E15<>"",$G15<>""),$E15,"") -> Kestrel Fitness | Z15: =IF($A15="","",IF($Q15<>"Overdue","",(TODAY()-$D15)+ROW()/100000)) | AA15: =IF($A15="","",IF(AND($Q15="Paid",ISNUMBER($N15),ISNUMBER($B15)),$N15-$B15,"")) | AB15: =IF($A15="","",IF(OR($Q15="Paid",$Q15="Draft",$Q15="Cancelled",$Q15="No lines yet",$Q15="No date"),"",IF($Q15<>"Overdue","Not due",IF(TODAY()-$D15<=14,"1-14",IF(TODAY()-$D15<=30,"15-30",IF(TODAY()-$D15<=60,"31-60","61+"))))))
D16: =IF($B16="","",$B16+IF($C16="",IF('Start Here'!$C$15="",14,'Start Here'!$C$15),$C16)) | I16: =IF($A16="","",ROUND(SUMIF('Line Items'!$A$8:$A$507,$A16,'Line Items'!$H$8:$H$507),2)) | K16: =IF($A16="","",ROUND($I16*IFERROR(IF($J16="",IF('Start Here'!$C$22="",0,'Start Here'!$C$22),$J16),0)/100,2)) | L16: =IF($A16="","",ROUND($I16+$K16,2)) | O16: =IF($A16="","",ROUND($L16-IF($M16="",0,$M16),2)) | Q16: =IF($A16="","",IF($P16="Cancelled","Cancelled",IF($P16="Draft","Draft",IF($L16=0,"No lines yet",IF($O16<=0,"Paid",IF($D16="","No date",IF($D16<TODAY(),"Overdue",IF(IF($M16="",0,$M16)>0,"Part-paid","Open")))))))) | R16: =IF($A16="","",IF($Q16<>"Overdue","—",TODAY()-$D16)) | S16: =IF($A16="","",IF(OR($Q16="Paid",$Q16="Cancelled",$Q16="Draft"),"—",IF($Q16="No lines yet","Add line items",IF($Q16="No date","Add invoice date",IF($D16-TODAY()>7,"—",IF($D16-TODAY()>=1,"Due soon",IF($D16=TODAY(),"Due today",IF(TODAY()-$D16<IF('Start Here'!$C$16="",7,'Start Here'!$C$16),"Just overdue",IF(TODAY()-$D16<IF('Start Here'!$C$17="",21,'Start Here'!$C$17),"First reminder",IF(TODAY()-$D16<IF('Start Here'!$C$18="",45,'Start Here'!$C$18),"Second reminder","Last friendly reminder")))))))))) | V16: =IF($A16="","",TRIM(IF(COUNTIF($A$8:$A$257,$A16)>1,"Duplicate no. ","")&IF(ISNUMBER(FIND("*",$A16))+ISNUMBER(FIND("?",$A16))>0,"Avoid * and ? in invoice numbers ","")&IF($E16="","No client ","")&IF($L16=0,"No amount ","")&IF(AND($Q16="Overdue",$F16=""),"No client email ",""))) | X16: =IF($A16="","",IFERROR(VALUE(IF('Start Here'!$C$13="",$A16,SUBSTITUTE($A16,'Start Here'!$C$13,""))),"")) | Y16: =IF(AND($E16<>"",$G16<>""),$E16,"") | Z16: =IF($A16="","",IF($Q16<>"Overdue","",(TODAY()-$D16)+ROW()/100000)) | AA16: =IF($A16="","",IF(AND($Q16="Paid",ISNUMBER($N16),ISNUMBER($B16)),$N16-$B16,"")) | AB16: =IF($A16="","",IF(OR($Q16="Paid",$Q16="Draft",$Q16="Cancelled",$Q16="No lines yet",$Q16="No date"),"",IF($Q16<>"Overdue","Not due",IF(TODAY()-$D16<=14,"1-14",IF(TODAY()-$D16<=30,"15-30",IF(TODAY()-$D16<=60,"31-60","61+"))))))
D17: =IF($B17="","",$B17+IF($C17="",IF('Start Here'!$C$15="",14,'Start Here'!$C$15),$C17)) | I17: =IF($A17="","",ROUND(SUMIF('Line Items'!$A$8:$A$507,$A17,'Line Items'!$H$8:$H$507),2)) | K17: =IF($A17="","",ROUND($I17*IFERROR(IF($J17="",IF('Start Here'!$C$22="",0,'Start Here'!$C$22),$J17),0)/100,2)) | L17: =IF($A17="","",ROUND($I17+$K17,2)) | O17: =IF($A17="","",ROUND($L17-IF($M17="",0,$M17),2)) | Q17: =IF($A17="","",IF($P17="Cancelled","Cancelled",IF($P17="Draft","Draft",IF($L17=0,"No lines yet",IF($O17<=0,"Paid",IF($D17="","No date",IF($D17<TODAY(),"Overdue",IF(IF($M17="",0,$M17)>0,"Part-paid","Open")))))))) | R17: =IF($A17="","",IF($Q17<>"Overdue","—",TODAY()-$D17)) | S17: =IF($A17="","",IF(OR($Q17="Paid",$Q17="Cancelled",$Q17="Draft"),"—",IF($Q17="No lines yet","Add line items",IF($Q17="No date","Add invoice date",IF($D17-TODAY()>7,"—",IF($D17-TODAY()>=1,"Due soon",IF($D17=TODAY(),"Due today",IF(TODAY()-$D17<IF('Start Here'!$C$16="",7,'Start Here'!$C$16),"Just overdue",IF(TODAY()-$D17<IF('Start Here'!$C$17="",21,'Start Here'!$C$17),"First reminder",IF(TODAY()-$D17<IF('Start Here'!$C$18="",45,'Start Here'!$C$18),"Second reminder","Last friendly reminder")))))))))) | V17: =IF($A17="","",TRIM(IF(COUNTIF($A$8:$A$257,$A17)>1,"Duplicate no. ","")&IF(ISNUMBER(FIND("*",$A17))+ISNUMBER(FIND("?",$A17))>0,"Avoid * and ? in invoice numbers ","")&IF($E17="","No client ","")&IF($L17=0,"No amount ","")&IF(AND($Q17="Overdue",$F17=""),"No client email ",""))) | X17: =IF($A17="","",IFERROR(VALUE(IF('Start Here'!$C$13="",$A17,SUBSTITUTE($A17,'Start Here'!$C$13,""))),"")) | Y17: =IF(AND($E17<>"",$G17<>""),$E17,"") | Z17: =IF($A17="","",IF($Q17<>"Overdue","",(TODAY()-$D17)+ROW()/100000)) | AA17: =IF($A17="","",IF(AND($Q17="Paid",ISNUMBER($N17),ISNUMBER($B17)),$N17-$B17,"")) | AB17: =IF($A17="","",IF(OR($Q17="Paid",$Q17="Draft",$Q17="Cancelled",$Q17="No lines yet",$Q17="No date"),"",IF($Q17<>"Overdue","Not due",IF(TODAY()-$D17<=14,"1-14",IF(TODAY()-$D17<=30,"15-30",IF(TODAY()-$D17<=60,"31-60","61+"))))))
D18: =IF($B18="","",$B18+IF($C18="",IF('Start Here'!$C$15="",14,'Start Here'!$C$15),$C18)) | I18: =IF($A18="","",ROUND(SUMIF('Line Items'!$A$8:$A$507,$A18,'Line Items'!$H$8:$H$507),2)) | K18: =IF($A18="","",ROUND($I18*IFERROR(IF($J18="",IF('Start Here'!$C$22="",0,'Start Here'!$C$22),$J18),0)/100,2)) | L18: =IF($A18="","",ROUND($I18+$K18,2)) | O18: =IF($A18="","",ROUND($L18-IF($M18="",0,$M18),2)) | Q18: =IF($A18="","",IF($P18="Cancelled","Cancelled",IF($P18="Draft","Draft",IF($L18=0,"No lines yet",IF($O18<=0,"Paid",IF($D18="","No date",IF($D18<TODAY(),"Overdue",IF(IF($M18="",0,$M18)>0,"Part-paid","Open")))))))) | R18: =IF($A18="","",IF($Q18<>"Overdue","—",TODAY()-$D18)) | S18: =IF($A18="","",IF(OR($Q18="Paid",$Q18="Cancelled",$Q18="Draft"),"—",IF($Q18="No lines yet","Add line items",IF($Q18="No date","Add invoice date",IF($D18-TODAY()>7,"—",IF($D18-TODAY()>=1,"Due soon",IF($D18=TODAY(),"Due today",IF(TODAY()-$D18<IF('Start Here'!$C$16="",7,'Start Here'!$C$16),"Just overdue",IF(TODAY()-$D18<IF('Start Here'!$C$17="",21,'Start Here'!$C$17),"First reminder",IF(TODAY()-$D18<IF('Start Here'!$C$18="",45,'Start Here'!$C$18),"Second reminder","Last friendly reminder")))))))))) | V18: =IF($A18="","",TRIM(IF(COUNTIF($A$8:$A$257,$A18)>1,"Duplicate no. ","")&IF(ISNUMBER(FIND("*",$A18))+ISNUMBER(FIND("?",$A18))>0,"Avoid * and ? in invoice numbers ","")&IF($E18="","No client ","")&IF($L18=0,"No amount ","")&IF(AND($Q18="Overdue",$F18=""),"No client email ",""))) | X18: =IF($A18="","",IFERROR(VALUE(IF('Start Here'!$C$13="",$A18,SUBSTITUTE($A18,'Start Here'!$C$13,""))),"")) | Y18: =IF(AND($E18<>"",$G18<>""),$E18,"") | Z18: =IF($A18="","",IF($Q18<>"Overdue","",(TODAY()-$D18)+ROW()/100000)) | AA18: =IF($A18="","",IF(AND($Q18="Paid",ISNUMBER($N18),ISNUMBER($B18)),$N18-$B18,"")) | AB18: =IF($A18="","",IF(OR($Q18="Paid",$Q18="Draft",$Q18="Cancelled",$Q18="No lines yet",$Q18="No date"),"",IF($Q18<>"Overdue","Not due",IF(TODAY()-$D18<=14,"1-14",IF(TODAY()-$D18<=30,"15-30",IF(TODAY()-$D18<=60,"31-60","61+"))))))
D19: =IF($B19="","",$B19+IF($C19="",IF('Start Here'!$C$15="",14,'Start Here'!$C$15),$C19)) | I19: =IF($A19="","",ROUND(SUMIF('Line Items'!$A$8:$A$507,$A19,'Line Items'!$H$8:$H$507),2)) | K19: =IF($A19="","",ROUND($I19*IFERROR(IF($J19="",IF('Start Here'!$C$22="",0,'Start Here'!$C$22),$J19),0)/100,2)) | L19: =IF($A19="","",ROUND($I19+$K19,2)) | O19: =IF($A19="","",ROUND($L19-IF($M19="",0,$M19),2)) | Q19: =IF($A19="","",IF($P19="Cancelled","Cancelled",IF($P19="Draft","Draft",IF($L19=0,"No lines yet",IF($O19<=0,"Paid",IF($D19="","No date",IF($D19<TODAY(),"Overdue",IF(IF($M19="",0,$M19)>0,"Part-paid","Open")))))))) | R19: =IF($A19="","",IF($Q19<>"Overdue","—",TODAY()-$D19)) | S19: =IF($A19="","",IF(OR($Q19="Paid",$Q19="Cancelled",$Q19="Draft"),"—",IF($Q19="No lines yet","Add line items",IF($Q19="No date","Add invoice date",IF($D19-TODAY()>7,"—",IF($D19-TODAY()>=1,"Due soon",IF($D19=TODAY(),"Due today",IF(TODAY()-$D19<IF('Start Here'!$C$16="",7,'Start Here'!$C$16),"Just overdue",IF(TODAY()-$D19<IF('Start Here'!$C$17="",21,'Start Here'!$C$17),"First reminder",IF(TODAY()-$D19<IF('Start Here'!$C$18="",45,'Start Here'!$C$18),"Second reminder","Last friendly reminder")))))))))) | V19: =IF($A19="","",TRIM(IF(COUNTIF($A$8:$A$257,$A19)>1,"Duplicate no. ","")&IF(ISNUMBER(FIND("*",$A19))+ISNUMBER(FIND("?",$A19))>0,"Avoid * and ? in invoice numbers ","")&IF($E19="","No client ","")&IF($L19=0,"No amount ","")&IF(AND($Q19="Overdue",$F19=""),"No client email ",""))) | X19: =IF($A19="","",IFERROR(VALUE(IF('Start Here'!$C$13="",$A19,SUBSTITUTE($A19,'Start Here'!$C$13,""))),"")) | Y19: =IF(AND($E19<>"",$G19<>""),$E19,"") | Z19: =IF($A19="","",IF($Q19<>"Overdue","",(TODAY()-$D19)+ROW()/100000)) | AA19: =IF($A19="","",IF(AND($Q19="Paid",ISNUMBER($N19),ISNUMBER($B19)),$N19-$B19,"")) | AB19: =IF($A19="","",IF(OR($Q19="Paid",$Q19="Draft",$Q19="Cancelled",$Q19="No lines yet",$Q19="No date"),"",IF($Q19<>"Overdue","Not due",IF(TODAY()-$D19<=14,"1-14",IF(TODAY()-$D19<=30,"15-30",IF(TODAY()-$D19<=60,"31-60","61+"))))))
D20: =IF($B20="","",$B20+IF($C20="",IF('Start Here'!$C$15="",14,'Start Here'!$C$15),$C20)) | I20: =IF($A20="","",ROUND(SUMIF('Line Items'!$A$8:$A$507,$A20,'Line Items'!$H$8:$H$507),2)) | K20: =IF($A20="","",ROUND($I20*IFERROR(IF($J20="",IF('Start Here'!$C$22="",0,'Start Here'!$C$22),$J20),0)/100,2)) | L20: =IF($A20="","",ROUND($I20+$K20,2)) | O20: =IF($A20="","",ROUND($L20-IF($M20="",0,$M20),2)) | Q20: =IF($A20="","",IF($P20="Cancelled","Cancelled",IF($P20="Draft","Draft",IF($L20=0,"No lines yet",IF($O20<=0,"Paid",IF($D20="","No date",IF($D20<TODAY(),"Overdue",IF(IF($M20="",0,$M20)>0,"Part-paid","Open")))))))) | R20: =IF($A20="","",IF($Q20<>"Overdue","—",TODAY()-$D20)) | S20: =IF($A20="","",IF(OR($Q20="Paid",$Q20="Cancelled",$Q20="Draft"),"—",IF($Q20="No lines yet","Add line items",IF($Q20="No date","Add invoice date",IF($D20-TODAY()>7,"—",IF($D20-TODAY()>=1,"Due soon",IF($D20=TODAY(),"Due today",IF(TODAY()-$D20<IF('Start Here'!$C$16="",7,'Start Here'!$C$16),"Just overdue",IF(TODAY()-$D20<IF('Start Here'!$C$17="",21,'Start Here'!$C$17),"First reminder",IF(TODAY()-$D20<IF('Start Here'!$C$18="",45,'Start Here'!$C$18),"Second reminder","Last friendly reminder")))))))))) | V20: =IF($A20="","",TRIM(IF(COUNTIF($A$8:$A$257,$A20)>1,"Duplicate no. ","")&IF(ISNUMBER(FIND("*",$A20))+ISNUMBER(FIND("?",$A20))>0,"Avoid * and ? in invoice numbers ","")&IF($E20="","No client ","")&IF($L20=0,"No amount ","")&IF(AND($Q20="Overdue",$F20=""),"No client email ",""))) | X20: =IF($A20="","",IFERROR(VALUE(IF('Start Here'!$C$13="",$A20,SUBSTITUTE($A20,'Start Here'!$C$13,""))),"")) | Y20: =IF(AND($E20<>"",$G20<>""),$E20,"") | Z20: =IF($A20="","",IF($Q20<>"Overdue","",(TODAY()-$D20)+ROW()/100000)) | AA20: =IF($A20="","",IF(AND($Q20="Paid",ISNUMBER($N20),ISNUMBER($B20)),$N20-$B20,"")) | AB20: =IF($A20="","",IF(OR($Q20="Paid",$Q20="Draft",$Q20="Cancelled",$Q20="No lines yet",$Q20="No date"),"",IF($Q20<>"Overdue","Not due",IF(TODAY()-$D20<=14,"1-14",IF(TODAY()-$D20<=30,"15-30",IF(TODAY()-$D20<=60,"31-60","61+"))))))
D21: =IF($B21="","",$B21+IF($C21="",IF('Start Here'!$C$15="",14,'Start Here'!$C$15),$C21)) | I21: =IF($A21="","",ROUND(SUMIF('Line Items'!$A$8:$A$507,$A21,'Line Items'!$H$8:$H$507),2)) | K21: =IF($A21="","",ROUND($I21*IFERROR(IF($J21="",IF('Start Here'!$C$22="",0,'Start Here'!$C$22),$J21),0)/100,2)) | L21: =IF($A21="","",ROUND($I21+$K21,2)) | O21: =IF($A21="","",ROUND($L21-IF($M21="",0,$M21),2)) | Q21: =IF($A21="","",IF($P21="Cancelled","Cancelled",IF($P21="Draft","Draft",IF($L21=0,"No lines yet",IF($O21<=0,"Paid",IF($D21="","No date",IF($D21<TODAY(),"Overdue",IF(IF($M21="",0,$M21)>0,"Part-paid","Open")))))))) | R21: =IF($A21="","",IF($Q21<>"Overdue","—",TODAY()-$D21)) | S21: =IF($A21="","",IF(OR($Q21="Paid",$Q21="Cancelled",$Q21="Draft"),"—",IF($Q21="No lines yet","Add line items",IF($Q21="No date","Add invoice date",IF($D21-TODAY()>7,"—",IF($D21-TODAY()>=1,"Due soon",IF($D21=TODAY(),"Due today",IF(TODAY()-$D21<IF('Start Here'!$C$16="",7,'Start Here'!$C$16),"Just overdue",IF(TODAY()-$D21<IF('Start Here'!$C$17="",21,'Start Here'!$C$17),"First reminder",IF(TODAY()-$D21<IF('Start Here'!$C$18="",45,'Start Here'!$C$18),"Second reminder","Last friendly reminder")))))))))) | V21: =IF($A21="","",TRIM(IF(COUNTIF($A$8:$A$257,$A21)>1,"Duplicate no. ","")&IF(ISNUMBER(FIND("*",$A21))+ISNUMBER(FIND("?",$A21))>0,"Avoid * and ? in invoice numbers ","")&IF($E21="","No client ","")&IF($L21=0,"No amount ","")&IF(AND($Q21="Overdue",$F21=""),"No client email ",""))) | X21: =IF($A21="","",IFERROR(VALUE(IF('Start Here'!$C$13="",$A21,SUBSTITUTE($A21,'Start Here'!$C$13,""))),"")) | Y21: =IF(AND($E21<>"",$G21<>""),$E21,"") | Z21: =IF($A21="","",IF($Q21<>"Overdue","",(TODAY()-$D21)+ROW()/100000)) | AA21: =IF($A21="","",IF(AND($Q21="Paid",ISNUMBER($N21),ISNUMBER($B21)),$N21-$B21,"")) | AB21: =IF($A21="","",IF(OR($Q21="Paid",$Q21="Draft",$Q21="Cancelled",$Q21="No lines yet",$Q21="No date"),"",IF($Q21<>"Overdue","Not due",IF(TODAY()-$D21<=14,"1-14",IF(TODAY()-$D21<=30,"15-30",IF(TODAY()-$D21<=60,"31-60","61+"))))))
D22: =IF($B22="","",$B22+IF($C22="",IF('Start Here'!$C$15="",14,'Start Here'!$C$15),$C22)) | I22: =IF($A22="","",ROUND(SUMIF('Line Items'!$A$8:$A$507,$A22,'Line Items'!$H$8:$H$507),2)) | K22: =IF($A22="","",ROUND($I22*IFERROR(IF($J22="",IF('Start Here'!$C$22="",0,'Start Here'!$C$22),$J22),0)/100,2)) | L22: =IF($A22="","",ROUND($I22+$K22,2)) | O22: =IF($A22="","",ROUND($L22-IF($M22="",0,$M22),2)) | Q22: =IF($A22="","",IF($P22="Cancelled","Cancelled",IF($P22="Draft","Draft",IF($L22=0,"No lines yet",IF($O22<=0,"Paid",IF($D22="","No date",IF($D22<TODAY(),"Overdue",IF(IF($M22="",0,$M22)>0,"Part-paid","Open")))))))) | R22: =IF($A22="","",IF($Q22<>"Overdue","—",TODAY()-$D22)) | S22: =IF($A22="","",IF(OR($Q22="Paid",$Q22="Cancelled",$Q22="Draft"),"—",IF($Q22="No lines yet","Add line items",IF($Q22="No date","Add invoice date",IF($D22-TODAY()>7,"—",IF($D22-TODAY()>=1,"Due soon",IF($D22=TODAY(),"Due today",IF(TODAY()-$D22<IF('Start Here'!$C$16="",7,'Start Here'!$C$16),"Just overdue",IF(TODAY()-$D22<IF('Start Here'!$C$17="",21,'Start Here'!$C$17),"First reminder",IF(TODAY()-$D22<IF('Start Here'!$C$18="",45,'Start Here'!$C$18),"Second reminder","Last friendly reminder")))))))))) | V22: =IF($A22="","",TRIM(IF(COUNTIF($A$8:$A$257,$A22)>1,"Duplicate no. ","")&IF(ISNUMBER(FIND("*",$A22))+ISNUMBER(FIND("?",$A22))>0,"Avoid * and ? in invoice numbers ","")&IF($E22="","No client ","")&IF($L22=0,"No amount ","")&IF(AND($Q22="Overdue",$F22=""),"No client email ",""))) | X22: =IF($A22="","",IFERROR(VALUE(IF('Start Here'!$C$13="",$A22,SUBSTITUTE($A22,'Start Here'!$C$13,""))),"")) | Y22: =IF(AND($E22<>"",$G22<>""),$E22,"") | Z22: =IF($A22="","",IF($Q22<>"Overdue","",(TODAY()-$D22)+ROW()/100000)) | AA22: =IF($A22="","",IF(AND($Q22="Paid",ISNUMBER($N22),ISNUMBER($B22)),$N22-$B22,"")) | AB22: =IF($A22="","",IF(OR($Q22="Paid",$Q22="Draft",$Q22="Cancelled",$Q22="No lines yet",$Q22="No date"),"",IF($Q22<>"Overdue","Not due",IF(TODAY()-$D22<=14,"1-14",IF(TODAY()-$D22<=30,"15-30",IF(TODAY()-$D22<=60,"31-60","61+"))))))
D23: =IF($B23="","",$B23+IF($C23="",IF('Start Here'!$C$15="",14,'Start Here'!$C$15),$C23)) | I23: =IF($A23="","",ROUND(SUMIF('Line Items'!$A$8:$A$507,$A23,'Line Items'!$H$8:$H$507),2)) | K23: =IF($A23="","",ROUND($I23*IFERROR(IF($J23="",IF('Start Here'!$C$22="",0,'Start Here'!$C$22),$J23),0)/100,2)) | L23: =IF($A23="","",ROUND($I23+$K23,2)) | O23: =IF($A23="","",ROUND($L23-IF($M23="",0,$M23),2)) | Q23: =IF($A23="","",IF($P23="Cancelled","Cancelled",IF($P23="Draft","Draft",IF($L23=0,"No lines yet",IF($O23<=0,"Paid",IF($D23="","No date",IF($D23<TODAY(),"Overdue",IF(IF($M23="",0,$M23)>0,"Part-paid","Open")))))))) | R23: =IF($A23="","",IF($Q23<>"Overdue","—",TODAY()-$D23)) | S23: =IF($A23="","",IF(OR($Q23="Paid",$Q23="Cancelled",$Q23="Draft"),"—",IF($Q23="No lines yet","Add line items",IF($Q23="No date","Add invoice date",IF($D23-TODAY()>7,"—",IF($D23-TODAY()>=1,"Due soon",IF($D23=TODAY(),"Due today",IF(TODAY()-$D23<IF('Start Here'!$C$16="",7,'Start Here'!$C$16),"Just overdue",IF(TODAY()-$D23<IF('Start Here'!$C$17="",21,'Start Here'!$C$17),"First reminder",IF(TODAY()-$D23<IF('Start Here'!$C$18="",45,'Start Here'!$C$18),"Second reminder","Last friendly reminder")))))))))) | V23: =IF($A23="","",TRIM(IF(COUNTIF($A$8:$A$257,$A23)>1,"Duplicate no. ","")&IF(ISNUMBER(FIND("*",$A23))+ISNUMBER(FIND("?",$A23))>0,"Avoid * and ? in invoice numbers ","")&IF($E23="","No client ","")&IF($L23=0,"No amount ","")&IF(AND($Q23="Overdue",$F23=""),"No client email ",""))) | X23: =IF($A23="","",IFERROR(VALUE(IF('Start Here'!$C$13="",$A23,SUBSTITUTE($A23,'Start Here'!$C$13,""))),"")) | Y23: =IF(AND($E23<>"",$G23<>""),$E23,"") | Z23: =IF($A23="","",IF($Q23<>"Overdue","",(TODAY()-$D23)+ROW()/100000)) | AA23: =IF($A23="","",IF(AND($Q23="Paid",ISNUMBER($N23),ISNUMBER($B23)),$N23-$B23,"")) | AB23: =IF($A23="","",IF(OR($Q23="Paid",$Q23="Draft",$Q23="Cancelled",$Q23="No lines yet",$Q23="No date"),"",IF($Q23<>"Overdue","Not due",IF(TODAY()-$D23<=14,"1-14",IF(TODAY()-$D23<=30,"15-30",IF(TODAY()-$D23<=60,"31-60","61+"))))))
D24: =IF($B24="","",$B24+IF($C24="",IF('Start Here'!$C$15="",14,'Start Here'!$C$15),$C24)) | I24: =IF($A24="","",ROUND(SUMIF('Line Items'!$A$8:$A$507,$A24,'Line Items'!$H$8:$H$507),2)) | K24: =IF($A24="","",ROUND($I24*IFERROR(IF($J24="",IF('Start Here'!$C$22="",0,'Start Here'!$C$22),$J24),0)/100,2)) | L24: =IF($A24="","",ROUND($I24+$K24,2)) | O24: =IF($A24="","",ROUND($L24-IF($M24="",0,$M24),2)) | Q24: =IF($A24="","",IF($P24="Cancelled","Cancelled",IF($P24="Draft","Draft",IF($L24=0,"No lines yet",IF($O24<=0,"Paid",IF($D24="","No date",IF($D24<TODAY(),"Overdue",IF(IF($M24="",0,$M24)>0,"Part-paid","Open")))))))) | R24: =IF($A24="","",IF($Q24<>"Overdue","—",TODAY()-$D24)) | S24: =IF($A24="","",IF(OR($Q24="Paid",$Q24="Cancelled",$Q24="Draft"),"—",IF($Q24="No lines yet","Add line items",IF($Q24="No date","Add invoice date",IF($D24-TODAY()>7,"—",IF($D24-TODAY()>=1,"Due soon",IF($D24=TODAY(),"Due today",IF(TODAY()-$D24<IF('Start Here'!$C$16="",7,'Start Here'!$C$16),"Just overdue",IF(TODAY()-$D24<IF('Start Here'!$C$17="",21,'Start Here'!$C$17),"First reminder",IF(TODAY()-$D24<IF('Start Here'!$C$18="",45,'Start Here'!$C$18),"Second reminder","Last friendly reminder")))))))))) | V24: =IF($A24="","",TRIM(IF(COUNTIF($A$8:$A$257,$A24)>1,"Duplicate no. ","")&IF(ISNUMBER(FIND("*",$A24))+ISNUMBER(FIND("?",$A24))>0,"Avoid * and ? in invoice numbers ","")&IF($E24="","No client ","")&IF($L24=0,"No amount ","")&IF(AND($Q24="Overdue",$F24=""),"No client email ",""))) | X24: =IF($A24="","",IFERROR(VALUE(IF('Start Here'!$C$13="",$A24,SUBSTITUTE($A24,'Start Here'!$C$13,""))),"")) | Y24: =IF(AND($E24<>"",$G24<>""),$E24,"") | Z24: =IF($A24="","",IF($Q24<>"Overdue","",(TODAY()-$D24)+ROW()/100000)) | AA24: =IF($A24="","",IF(AND($Q24="Paid",ISNUMBER($N24),ISNUMBER($B24)),$N24-$B24,"")) | AB24: =IF($A24="","",IF(OR($Q24="Paid",$Q24="Draft",$Q24="Cancelled",$Q24="No lines yet",$Q24="No date"),"",IF($Q24<>"Overdue","Not due",IF(TODAY()-$D24<=14,"1-14",IF(TODAY()-$D24<=30,"15-30",IF(TODAY()-$D24<=60,"31-60","61+"))))))
D25: =IF($B25="","",$B25+IF($C25="",IF('Start Here'!$C$15="",14,'Start Here'!$C$15),$C25)) | I25: =IF($A25="","",ROUND(SUMIF('Line Items'!$A$8:$A$507,$A25,'Line Items'!$H$8:$H$507),2)) | K25: =IF($A25="","",ROUND($I25*IFERROR(IF($J25="",IF('Start Here'!$C$22="",0,'Start Here'!$C$22),$J25),0)/100,2)) | L25: =IF($A25="","",ROUND($I25+$K25,2)) | O25: =IF($A25="","",ROUND($L25-IF($M25="",0,$M25),2)) | Q25: =IF($A25="","",IF($P25="Cancelled","Cancelled",IF($P25="Draft","Draft",IF($L25=0,"No lines yet",IF($O25<=0,"Paid",IF($D25="","No date",IF($D25<TODAY(),"Overdue",IF(IF($M25="",0,$M25)>0,"Part-paid","Open")))))))) | R25: =IF($A25="","",IF($Q25<>"Overdue","—",TODAY()-$D25)) | S25: =IF($A25="","",IF(OR($Q25="Paid",$Q25="Cancelled",$Q25="Draft"),"—",IF($Q25="No lines yet","Add line items",IF($Q25="No date","Add invoice date",IF($D25-TODAY()>7,"—",IF($D25-TODAY()>=1,"Due soon",IF($D25=TODAY(),"Due today",IF(TODAY()-$D25<IF('Start Here'!$C$16="",7,'Start Here'!$C$16),"Just overdue",IF(TODAY()-$D25<IF('Start Here'!$C$17="",21,'Start Here'!$C$17),"First reminder",IF(TODAY()-$D25<IF('Start Here'!$C$18="",45,'Start Here'!$C$18),"Second reminder","Last friendly reminder")))))))))) | V25: =IF($A25="","",TRIM(IF(COUNTIF($A$8:$A$257,$A25)>1,"Duplicate no. ","")&IF(ISNUMBER(FIND("*",$A25))+ISNUMBER(FIND("?",$A25))>0,"Avoid * and ? in invoice numbers ","")&IF($E25="","No client ","")&IF($L25=0,"No amount ","")&IF(AND($Q25="Overdue",$F25=""),"No client email ",""))) | X25: =IF($A25="","",IFERROR(VALUE(IF('Start Here'!$C$13="",$A25,SUBSTITUTE($A25,'Start Here'!$C$13,""))),"")) | Y25: =IF(AND($E25<>"",$G25<>""),$E25,"") | Z25: =IF($A25="","",IF($Q25<>"Overdue","",(TODAY()-$D25)+ROW()/100000)) | AA25: =IF($A25="","",IF(AND($Q25="Paid",ISNUMBER($N25),ISNUMBER($B25)),$N25-$B25,"")) | AB25: =IF($A25="","",IF(OR($Q25="Paid",$Q25="Draft",$Q25="Cancelled",$Q25="No lines yet",$Q25="No date"),"",IF($Q25<>"Overdue","Not due",IF(TODAY()-$D25<=14,"1-14",IF(TODAY()-$D25<=30,"15-30",IF(TODAY()-$D25<=60,"31-60","61+"))))))
D26: =IF($B26="","",$B26+IF($C26="",IF('Start Here'!$C$15="",14,'Start Here'!$C$15),$C26)) | I26: =IF($A26="","",ROUND(SUMIF('Line Items'!$A$8:$A$507,$A26,'Line Items'!$H$8:$H$507),2)) | K26: =IF($A26="","",ROUND($I26*IFERROR(IF($J26="",IF('Start Here'!$C$22="",0,'Start Here'!$C$22),$J26),0)/100,2)) | L26: =IF($A26="","",ROUND($I26+$K26,2)) | O26: =IF($A26="","",ROUND($L26-IF($M26="",0,$M26),2)) | Q26: =IF($A26="","",IF($P26="Cancelled","Cancelled",IF($P26="Draft","Draft",IF($L26=0,"No lines yet",IF($O26<=0,"Paid",IF($D26="","No date",IF($D26<TODAY(),"Overdue",IF(IF($M26="",0,$M26)>0,"Part-paid","Open")))))))) | R26: =IF($A26="","",IF($Q26<>"Overdue","—",TODAY()-$D26)) | S26: =IF($A26="","",IF(OR($Q26="Paid",$Q26="Cancelled",$Q26="Draft"),"—",IF($Q26="No lines yet","Add line items",IF($Q26="No date","Add invoice date",IF($D26-TODAY()>7,"—",IF($D26-TODAY()>=1,"Due soon",IF($D26=TODAY(),"Due today",IF(TODAY()-$D26<IF('Start Here'!$C$16="",7,'Start Here'!$C$16),"Just overdue",IF(TODAY()-$D26<IF('Start Here'!$C$17="",21,'Start Here'!$C$17),"First reminder",IF(TODAY()-$D26<IF('Start Here'!$C$18="",45,'Start Here'!$C$18),"Second reminder","Last friendly reminder")))))))))) | V26: =IF($A26="","",TRIM(IF(COUNTIF($A$8:$A$257,$A26)>1,"Duplicate no. ","")&IF(ISNUMBER(FIND("*",$A26))+ISNUMBER(FIND("?",$A26))>0,"Avoid * and ? in invoice numbers ","")&IF($E26="","No client ","")&IF($L26=0,"No amount ","")&IF(AND($Q26="Overdue",$F26=""),"No client email ",""))) | X26: =IF($A26="","",IFERROR(VALUE(IF('Start Here'!$C$13="",$A26,SUBSTITUTE($A26,'Start Here'!$C$13,""))),"")) | Y26: =IF(AND($E26<>"",$G26<>""),$E26,"") | Z26: =IF($A26="","",IF($Q26<>"Overdue","",(TODAY()-$D26)+ROW()/100000)) | AA26: =IF($A26="","",IF(AND($Q26="Paid",ISNUMBER($N26),ISNUMBER($B26)),$N26-$B26,"")) | AB26: =IF($A26="","",IF(OR($Q26="Paid",$Q26="Draft",$Q26="Cancelled",$Q26="No lines yet",$Q26="No date"),"",IF($Q26<>"Overdue","Not due",IF(TODAY()-$D26<=14,"1-14",IF(TODAY()-$D26<=30,"15-30",IF(TODAY()-$D26<=60,"31-60","61+"))))))
D27: =IF($B27="","",$B27+IF($C27="",IF('Start Here'!$C$15="",14,'Start Here'!$C$15),$C27)) | I27: =IF($A27="","",ROUND(SUMIF('Line Items'!$A$8:$A$507,$A27,'Line Items'!$H$8:$H$507),2)) | K27: =IF($A27="","",ROUND($I27*IFERROR(IF($J27="",IF('Start Here'!$C$22="",0,'Start Here'!$C$22),$J27),0)/100,2)) | L27: =IF($A27="","",ROUND($I27+$K27,2)) | O27: =IF($A27="","",ROUND($L27-IF($M27="",0,$M27),2)) | Q27: =IF($A27="","",IF($P27="Cancelled","Cancelled",IF($P27="Draft","Draft",IF($L27=0,"No lines yet",IF($O27<=0,"Paid",IF($D27="","No date",IF($D27<TODAY(),"Overdue",IF(IF($M27="",0,$M27)>0,"Part-paid","Open")))))))) | R27: =IF($A27="","",IF($Q27<>"Overdue","—",TODAY()-$D27)) | S27: =IF($A27="","",IF(OR($Q27="Paid",$Q27="Cancelled",$Q27="Draft"),"—",IF($Q27="No lines yet","Add line items",IF($Q27="No date","Add invoice date",IF($D27-TODAY()>7,"—",IF($D27-TODAY()>=1,"Due soon",IF($D27=TODAY(),"Due today",IF(TODAY()-$D27<IF('Start Here'!$C$16="",7,'Start Here'!$C$16),"Just overdue",IF(TODAY()-$D27<IF('Start Here'!$C$17="",21,'Start Here'!$C$17),"First reminder",IF(TODAY()-$D27<IF('Start Here'!$C$18="",45,'Start Here'!$C$18),"Second reminder","Last friendly reminder")))))))))) | V27: =IF($A27="","",TRIM(IF(COUNTIF($A$8:$A$257,$A27)>1,"Duplicate no. ","")&IF(ISNUMBER(FIND("*",$A27))+ISNUMBER(FIND("?",$A27))>0,"Avoid * and ? in invoice numbers ","")&IF($E27="","No client ","")&IF($L27=0,"No amount ","")&IF(AND($Q27="Overdue",$F27=""),"No client email ",""))) | X27: =IF($A27="","",IFERROR(VALUE(IF('Start Here'!$C$13="",$A27,SUBSTITUTE($A27,'Start Here'!$C$13,""))),"")) | Y27: =IF(AND($E27<>"",$G27<>""),$E27,"") | Z27: =IF($A27="","",IF($Q27<>"Overdue","",(TODAY()-$D27)+ROW()/100000)) | AA27: =IF($A27="","",IF(AND($Q27="Paid",ISNUMBER($N27),ISNUMBER($B27)),$N27-$B27,"")) | AB27: =IF($A27="","",IF(OR($Q27="Paid",$Q27="Draft",$Q27="Cancelled",$Q27="No lines yet",$Q27="No date"),"",IF($Q27<>"Overdue","Not due",IF(TODAY()-$D27<=14,"1-14",IF(TODAY()-$D27<=30,"15-30",IF(TODAY()-$D27<=60,"31-60","61+"))))))
