Workbook

Sheet Setup
A1: Shared Expense Splitter — start here
A2: Enter each shared expense once — the workbook shows every person's fair share (equal, by weight such as room size, by nights present, by your own custom units, or exact amounts), each person's balance, and a payback plan of at most 9 transfers for 10 people. Up to 10 people and 300 expenses, in Excel and Google Sheets without macros. One currency per workbook — the currency label is a text label, there is no exchange-rate conversion.
B4: HOW TO USE — 5 STEPS
B5: STEP 1 · Name your group (C15), pick a currency label (C16) and a default split method (C17).
B6: STEP 2 · Type your people into B21:B30 — up to 10. Weight = room m2 / headcount / any number. Nights = nights or days present.
B7: STEP 3 · Expenses sheet: one row per expense — date, what it was, who paid, how much, category, how it is split.
B8: STEP 4 · Fine-tune a single row in the person columns H–Q: blank = normal share · 0 = not part of this expense · a number = custom units (or the exact amount in 'Exact amounts' mode). In 'Custom units' and 'Exact amounts' rows a blank cell counts as 0 — only the numbers you type share the row.
B9: STEP 5 · 'Who Owes What' shows every balance, 'Settle Up' shows the transfers that clear them. Tick each one off in 'Done?'.
B10: GOOGLE SHEETS: File → Import → Upload this file. Formulas, dropdowns, colours, frozen rows, tab colours and hidden columns survive the trip. Print setup (Letter / fit-to-width) does not — pick 'Fit to width' once in the Google Sheets print dialog.
B11: LIMITS — up to 10 people · up to 300 expenses · ONE currency per workbook: the currency label is a text label, there is no exchange-rate conversion · grey and hidden columns calculate themselves, never type in them.
B12: LICENSE — Personal use. One buyer, unlimited own projects & devices. Please don't resell or redistribute. · Questions or a broken formula? Message us on Etsy — we reply within 2 business days.
B13: For personal and household use. This is a calculation sheet, not accounting software: no VAT or tax calculation, no currency conversion, no legal or financial advice.
B15: Group name | C15: Flat share + Lisbon trip | F15: =IF($C$16="","Tip: type your currency symbol in C16 — it appears in every money heading.","")
B16: Currency label | C16: € | F16: Text label only. One currency per workbook — there is no exchange-rate conversion.
B17: Default split method | C17: Equal | F17: Used for every Expenses row that has no 'Split by' of its own.
A20: # | B20: Member | C20: Active? | D20: Weight (room m2, headcount, any number) | E20: Nights / days | F20: Note | G20: Check | H20: Categories (edit freely) | J20: Split methods (fixed) | L20: Yes/No | N20: Currency examples
A21: 1 | B21: Anna | C21: Yes | D21: 18 | E21: 7 | F21: Big room · flat + trip | G21: =IF($B21="","",IF(SUMPRODUCT(($B$21:$B$30=$B21)*1)>1,"⚠ duplicate name — every member needs a unique name","")) | H21: Groceries | J21: Equal | L21: Yes | N21: €
A22: 2 | B22: Ben | C22: Yes | D22: 16 | E22: 7 | F22: Flat + trip | G22: =IF($B22="","",IF(SUMPRODUCT(($B$21:$B$30=$B22)*1)>1,"⚠ duplicate name — every member needs a unique name","")) | H22: Rent | J22: Weights | L22: No | N22: $
A23: 3 | B23: Chris | C23: Yes | D23: 14 | E23: 3 | F23: Joined the trip on day 5 | G23: =IF($B23="","",IF(SUMPRODUCT(($B$21:$B$30=$B23)*1)>1,"⚠ duplicate name — every member needs a unique name","")) | H23: Utilities & internet | J23: Nights | N23: £
A24: 4 | B24: Dana | C24: Yes | D24: 12 | E24: 4 | F24: Flat + trip | G24: =IF($B24="","",IF(SUMPRODUCT(($B$21:$B$30=$B24)*1)>1,"⚠ duplicate name — every member needs a unique name","")) | H24: Household & repairs | J24: Custom units | N24: CHF
A25: 5 | B25: Eli | C25: Yes | E25: 7 | F25: Trip only — no room in the flat | G25: =IF($B25="","",IF(SUMPRODUCT(($B$21:$B$30=$B25)*1)>1,"⚠ duplicate name — every member needs a unique name","")) | H25: Eating out | J25: Exact amounts | N25: kr
A26: 6 | C26: No | G26: =IF($B26="","",IF(SUMPRODUCT(($B$21:$B$30=$B26)*1)>1,"⚠ duplicate name — every member needs a unique name","")) | H26: Drinks & nightlife | N26: zł
A27: 7 | C27: No | G27: =IF($B27="","",IF(SUMPRODUCT(($B$21:$B$30=$B27)*1)>1,"⚠ duplicate name — every member needs a unique name","")) | H27: Travel & transport | N27: C$
A28: 8 | C28: No | G28: =IF($B28="","",IF(SUMPRODUCT(($B$21:$B$30=$B28)*1)>1,"⚠ duplicate name — every member needs a unique name","")) | H28: Accommodation | N28: A$
A29: 9 | C29: No | G29: =IF($B29="","",IF(SUMPRODUCT(($B$21:$B$30=$B29)*1)>1,"⚠ duplicate name — every member needs a unique name","")) | H29: Activities & tickets | N29: ₹
A30: 10 | C30: No | G30: =IF($B30="","",IF(SUMPRODUCT(($B$21:$B$30=$B30)*1)>1,"⚠ duplicate name — every member needs a unique name","")) | H30: Gifts & celebration | N30: R$
H31: Payback / cash to a person
H32: Other
B33: REMEMBER · In Equal / Weights / Nights rows: blank = normal share, 0 = not part of that expense, any number = custom share. In 'Custom units' and 'Exact amounts' rows only the numbers you type count — blank means 0. Set Active = No only for people who never joined.
B34: CASH PAYBACK · Ben hands Anna 50 in cash? Add a normal row: Paid by = Ben, Amount = 50, Split by = 'Exact amounts', type 50 in Anna's column, leave everyone else blank. The category 'Payback / cash to a person' is only a label — the split mode does the maths.
B35: SPLIT MODES · Equal = same share for everyone active · Weights = by the Weight column · Nights = by the Nights column · Custom units = ONLY the people you type a number for share that row, a blank cell counts as 0 · Exact amounts = you type each person's exact amount (they must add up to the total). Type numbers for everyone who should share a 'Custom units' row — if you leave the whole row blank, the Check column says so instead of splitting it silently.
B36: MAKE IT YOURS · The example (flat share + Lisbon trip) is here so you can see every split mode working. To start your own: on the Expenses sheet select B8:Q31 and press Delete, then overwrite the names in B21:B30 above. Never delete whole rows — column A, the Check column R, the 'Share of' column S and the hidden columns T:AG hold the formulas.

Sheet Expenses
A1: Expenses — one row per expense
A2: Grey and hidden columns calculate themselves. Blank in a person's column = normal share · 0 = not part of this expense · a number = custom units (or the exact amount in 'Exact amounts' mode). In 'Custom units' and 'Exact amounts' rows a blank cell counts as 0 — only the numbers you type share the row.
B4: Show each person's share for: | C4: Anna | E4: ← pick a name; column S then shows that person's share of every row.
R6: The engine columns T:AG are hidden. Unhide them if you want to see the maths — never type in them. | T6: ▼ calculates itself — never type here
A7: # | B7: Date | C7: What was it? | D7: Paid by | E7: =IF(Setup!$C$16="","Amount","Amount ("&Setup!$C$16&")") -> Amount (€) | F7: Category | G7: Split by | H7: =IF(Setup!$B$21="","(person 1)",Setup!$B$21) -> Anna | I7: =IF(Setup!$B$22="","(person 2)",Setup!$B$22) -> Ben | J7: =IF(Setup!$B$23="","(person 3)",Setup!$B$23) -> Chris | K7: =IF(Setup!$B$24="","(person 4)",Setup!$B$24) -> Dana | L7: =IF(Setup!$B$25="","(person 5)",Setup!$B$25) -> Eli | M7: =IF(Setup!$B$26="","(person 6)",Setup!$B$26) -> (person 6) | N7: =IF(Setup!$B$27="","(person 7)",Setup!$B$27) -> (person 7) | O7: =IF(Setup!$B$28="","(person 8)",Setup!$B$28) -> (person 8) | P7: =IF(Setup!$B$29="","(person 9)",Setup!$B$29) -> (person 9) | Q7: =IF(Setup!$B$30="","(person 10)",Setup!$B$30) -> (person 10) | R7: Check | S7: =IF($C$4="","Share of … (pick a name in C4)","Share of "&$C$4) -> Share of Anna | T7: Split used | U7: =IF(Setup!$B$21="","units — person 1","units — "&Setup!$B$21) -> units — Anna | V7: =IF(Setup!$B$22="","units — person 2","units — "&Setup!$B$22) -> units — Ben | W7: =IF(Setup!$B$23="","units — person 3","units — "&Setup!$B$23) -> units — Chris | X7: =IF(Setup!$B$24="","units — person 4","units — "&Setup!$B$24) -> units — Dana | Y7: =IF(Setup!$B$25="","units — person 5","units — "&Setup!$B$25) -> units — Eli | Z7: =IF(Setup!$B$26="","units — person 6","units — "&Setup!$B$26) -> units — person 6 | AA7: =IF(Setup!$B$27="","units — person 7","units — "&Setup!$B$27) -> units — person 7 | AB7: =IF(Setup!$B$28="","units — person 8","units — "&Setup!$B$28) -> units — person 8 | AC7: =IF(Setup!$B$29="","units — person 9","units — "&Setup!$B$29) -> units — person 9 | AD7: =IF(Setup!$B$30="","units — person 10","units — "&Setup!$B$30) -> units — person 10 | AE7: Total units | AF7: Divisor (never 0) | AG7: Amount (number)
A8: =IF($T8="","—",ROW()-7) -> 1 | B8: =TODAY()-45 -> 46187 | C8: Rent — this month | D8: Anna | E8: 1450 | F8: Rent | G8: Weights | R8: =IF($T8="","",IF($D8="","Who paid?",IF(SUMPRODUCT((Setup!$B$21:$B$30=$D8)*1)=0,"Payer is not in the member list on Setup",IF($E8="","Amount missing — type the number in column E",IF(NOT(ISNUMBER($E8)),"Amount must be a plain number — no currency symbol, no text",IF(AND($T8="Custom units",$AE8<=0),"Custom units: nobody has units on this row — type a number for at least one person",IF($AE8<=0,"Nobody shares this row — check the person columns H–Q, and the Weight / Nights columns on Setup",IF(AND($T8="Exact amounts",ABS($AE8-$AG8)>0.01),"Exact amounts do not add up to the amount","OK")))))))) -> OK | S8: =IFERROR(IF(OR($T8="",$C$4=""),"—",ROUND($AG8*INDEX($U8:$AD8,1,MATCH($C$4,Setup!$B$21:$B$30,0))/$AF8,2)),"—") -> 435 | T8: =IF(AND($C8="",$D8="",NOT(ISNUMBER($E8))),"",IF($G8="",IF(Setup!$C$17="","Equal",Setup!$C$17),$G8)) -> Weights | U8: =IF($T8="",0,IF(OR(Setup!$B$21="",Setup!$C$21="No"),0,IF(ISNUMBER(H8),H8,IF($T8="Weights",IF(ISNUMBER(Setup!$D$21),Setup!$D$21,0),IF($T8="Nights",IF(ISNUMBER(Setup!$E$21),Setup!$E$21,0),IF(OR($T8="Exact amounts",$T8="Custom units"),0,1)))))) -> 18 | V8: =IF($T8="",0,IF(OR(Setup!$B$22="",Setup!$C$22="No"),0,IF(ISNUMBER(I8),I8,IF($T8="Weights",IF(ISNUMBER(Setup!$D$22),Setup!$D$22,0),IF($T8="Nights",IF(ISNUMBER(Setup!$E$22),Setup!$E$22,0),IF(OR($T8="Exact amounts",$T8="Custom units"),0,1)))))) -> 16 | W8: =IF($T8="",0,IF(OR(Setup!$B$23="",Setup!$C$23="No"),0,IF(ISNUMBER(J8),J8,IF($T8="Weights",IF(ISNUMBER(Setup!$D$23),Setup!$D$23,0),IF($T8="Nights",IF(ISNUMBER(Setup!$E$23),Setup!$E$23,0),IF(OR($T8="Exact amounts",$T8="Custom units"),0,1)))))) -> 14 | X8: =IF($T8="",0,IF(OR(Setup!$B$24="",Setup!$C$24="No"),0,IF(ISNUMBER(K8),K8,IF($T8="Weights",IF(ISNUMBER(Setup!$D$24),Setup!$D$24,0),IF($T8="Nights",IF(ISNUMBER(Setup!$E$24),Setup!$E$24,0),IF(OR($T8="Exact amounts",$T8="Custom units"),0,1)))))) -> 12 | Y8: =IF($T8="",0,IF(OR(Setup!$B$25="",Setup!$C$25="No"),0,IF(ISNUMBER(L8),L8,IF($T8="Weights",IF(ISNUMBER(Setup!$D$25),Setup!$D$25,0),IF($T8="Nights",IF(ISNUMBER(Setup!$E$25),Setup!$E$25,0),IF(OR($T8="Exact amounts",$T8="Custom units"),0,1)))))) -> 0 | Z8: =IF($T8="",0,IF(OR(Setup!$B$26="",Setup!$C$26="No"),0,IF(ISNUMBER(M8),M8,IF($T8="Weights",IF(ISNUMBER(Setup!$D$26),Setup!$D$26,0),IF($T8="Nights",IF(ISNUMBER(Setup!$E$26),Setup!$E$26,0),IF(OR($T8="Exact amounts",$T8="Custom units"),0,1)))))) -> 0 | AA8: =IF($T8="",0,IF(OR(Setup!$B$27="",Setup!$C$27="No"),0,IF(ISNUMBER(N8),N8,IF($T8="Weights",IF(ISNUMBER(Setup!$D$27),Setup!$D$27,0),IF($T8="Nights",IF(ISNUMBER(Setup!$E$27),Setup!$E$27,0),IF(OR($T8="Exact amounts",$T8="Custom units"),0,1)))))) -> 0 | AB8: =IF($T8="",0,IF(OR(Setup!$B$28="",Setup!$C$28="No"),0,IF(ISNUMBER(O8),O8,IF($T8="Weights",IF(ISNUMBER(Setup!$D$28),Setup!$D$28,0),IF($T8="Nights",IF(ISNUMBER(Setup!$E$28),Setup!$E$28,0),IF(OR($T8="Exact amounts",$T8="Custom units"),0,1)))))) -> 0 | AC8: =IF($T8="",0,IF(OR(Setup!$B$29="",Setup!$C$29="No"),0,IF(ISNUMBER(P8),P8,IF($T8="Weights",IF(ISNUMBER(Setup!$D$29),Setup!$D$29,0),IF($T8="Nights",IF(ISNUMBER(Setup!$E$29),Setup!$E$29,0),IF(OR($T8="Exact amounts",$T8="Custom units"),0,1)))))) -> 0 | AD8: =IF($T8="",0,IF(OR(Setup!$B$30="",Setup!$C$30="No"),0,IF(ISNUMBER(Q8),Q8,IF($T8="Weights",IF(ISNUMBER(Setup!$D$30),Setup!$D$30,0),IF($T8="Nights",IF(ISNUMBER(Setup!$E$30),Setup!$E$30,0),IF(OR($T8="Exact amounts",$T8="Custom units"),0,1)))))) -> 0 | AE8: =IF($T8="",0,SUM($U8:$AD8)) -> 60 | AF8: =IF($AE8<=0,1,$AE8) -> 60 | AG8: =IF(ISNUMBER($E8),$E8,0) -> 1450
A9: =IF($T9="","—",ROW()-7) -> 2 | B9: =TODAY()-44 -> 46188 | C9: Electricity & internet | D9: Ben | E9: 186.4 | F9: Utilities & internet | G9: Equal | L9: 0 | R9: =IF($T9="","",IF($D9="","Who paid?",IF(SUMPRODUCT((Setup!$B$21:$B$30=$D9)*1)=0,"Payer is not in the member list on Setup",IF($E9="","Amount missing — type the number in column E",IF(NOT(ISNUMBER($E9)),"Amount must be a plain number — no currency symbol, no text",IF(AND($T9="Custom units",$AE9<=0),"Custom units: nobody has units on this row — type a number for at least one person",IF($AE9<=0,"Nobody shares this row — check the person columns H–Q, and the Weight / Nights columns on Setup",IF(AND($T9="Exact amounts",ABS($AE9-$AG9)>0.01),"Exact amounts do not add up to the amount","OK")))))))) -> OK | S9: =IFERROR(IF(OR($T9="",$C$4=""),"—",ROUND($AG9*INDEX($U9:$AD9,1,MATCH($C$4,Setup!$B$21:$B$30,0))/$AF9,2)),"—") -> 46.6 | T9: =IF(AND($C9="",$D9="",NOT(ISNUMBER($E9))),"",IF($G9="",IF(Setup!$C$17="","Equal",Setup!$C$17),$G9)) -> Equal | U9: =IF($T9="",0,IF(OR(Setup!$B$21="",Setup!$C$21="No"),0,IF(ISNUMBER(H9),H9,IF($T9="Weights",IF(ISNUMBER(Setup!$D$21),Setup!$D$21,0),IF($T9="Nights",IF(ISNUMBER(Setup!$E$21),Setup!$E$21,0),IF(OR($T9="Exact amounts",$T9="Custom units"),0,1)))))) -> 1 | V9: =IF($T9="",0,IF(OR(Setup!$B$22="",Setup!$C$22="No"),0,IF(ISNUMBER(I9),I9,IF($T9="Weights",IF(ISNUMBER(Setup!$D$22),Setup!$D$22,0),IF($T9="Nights",IF(ISNUMBER(Setup!$E$22),Setup!$E$22,0),IF(OR($T9="Exact amounts",$T9="Custom units"),0,1)))))) -> 1 | W9: =IF($T9="",0,IF(OR(Setup!$B$23="",Setup!$C$23="No"),0,IF(ISNUMBER(J9),J9,IF($T9="Weights",IF(ISNUMBER(Setup!$D$23),Setup!$D$23,0),IF($T9="Nights",IF(ISNUMBER(Setup!$E$23),Setup!$E$23,0),IF(OR($T9="Exact amounts",$T9="Custom units"),0,1)))))) -> 1 | X9: =IF($T9="",0,IF(OR(Setup!$B$24="",Setup!$C$24="No"),0,IF(ISNUMBER(K9),K9,IF($T9="Weights",IF(ISNUMBER(Setup!$D$24),Setup!$D$24,0),IF($T9="Nights",IF(ISNUMBER(Setup!$E$24),Setup!$E$24,0),IF(OR($T9="Exact amounts",$T9="Custom units"),0,1)))))) -> 1 | Y9: =IF($T9="",0,IF(OR(Setup!$B$25="",Setup!$C$25="No"),0,IF(ISNUMBER(L9),L9,IF($T9="Weights",IF(ISNUMBER(Setup!$D$25),Setup!$D$25,0),IF($T9="Nights",IF(ISNUMBER(Setup!$E$25),Setup!$E$25,0),IF(OR($T9="Exact amounts",$T9="Custom units"),0,1)))))) -> 0 | Z9: =IF($T9="",0,IF(OR(Setup!$B$26="",Setup!$C$26="No"),0,IF(ISNUMBER(M9),M9,IF($T9="Weights",IF(ISNUMBER(Setup!$D$26),Setup!$D$26,0),IF($T9="Nights",IF(ISNUMBER(Setup!$E$26),Setup!$E$26,0),IF(OR($T9="Exact amounts",$T9="Custom units"),0,1)))))) -> 0 | AA9: =IF($T9="",0,IF(OR(Setup!$B$27="",Setup!$C$27="No"),0,IF(ISNUMBER(N9),N9,IF($T9="Weights",IF(ISNUMBER(Setup!$D$27),Setup!$D$27,0),IF($T9="Nights",IF(ISNUMBER(Setup!$E$27),Setup!$E$27,0),IF(OR($T9="Exact amounts",$T9="Custom units"),0,1)))))) -> 0 | AB9: =IF($T9="",0,IF(OR(Setup!$B$28="",Setup!$C$28="No"),0,IF(ISNUMBER(O9),O9,IF($T9="Weights",IF(ISNUMBER(Setup!$D$28),Setup!$D$28,0),IF($T9="Nights",IF(ISNUMBER(Setup!$E$28),Setup!$E$28,0),IF(OR($T9="Exact amounts",$T9="Custom units"),0,1)))))) -> 0 | AC9: =IF($T9="",0,IF(OR(Setup!$B$29="",Setup!$C$29="No"),0,IF(ISNUMBER(P9),P9,IF($T9="Weights",IF(ISNUMBER(Setup!$D$29),Setup!$D$29,0),IF($T9="Nights",IF(ISNUMBER(Setup!$E$29),Setup!$E$29,0),IF(OR($T9="Exact amounts",$T9="Custom units"),0,1)))))) -> 0 | AD9: =IF($T9="",0,IF(OR(Setup!$B$30="",Setup!$C$30="No"),0,IF(ISNUMBER(Q9),Q9,IF($T9="Weights",IF(ISNUMBER(Setup!$D$30),Setup!$D$30,0),IF($T9="Nights",IF(ISNUMBER(Setup!$E$30),Setup!$E$30,0),IF(OR($T9="Exact amounts",$T9="Custom units"),0,1)))))) -> 0 | AE9: =IF($T9="",0,SUM($U9:$AD9)) -> 4 | AF9: =IF($AE9<=0,1,$AE9) -> 4 | AG9: =IF(ISNUMBER($E9),$E9,0) -> 186.4
A10: =IF($T10="","—",ROW()-7) -> 3 | B10: =TODAY()-42 -> 46190 | C10: Weekly groceries | D10: Chris | E10: 94.2 | F10: Groceries | G10: Equal | L10: 0 | R10: =IF($T10="","",IF($D10="","Who paid?",IF(SUMPRODUCT((Setup!$B$21:$B$30=$D10)*1)=0,"Payer is not in the member list on Setup",IF($E10="","Amount missing — type the number in column E",IF(NOT(ISNUMBER($E10)),"Amount must be a plain number — no currency symbol, no text",IF(AND($T10="Custom units",$AE10<=0),"Custom units: nobody has units on this row — type a number for at least one person",IF($AE10<=0,"Nobody shares this row — check the person columns H–Q, and the Weight / Nights columns on Setup",IF(AND($T10="Exact amounts",ABS($AE10-$AG10)>0.01),"Exact amounts do not add up to the amount","OK")))))))) -> OK | S10: =IFERROR(IF(OR($T10="",$C$4=""),"—",ROUND($AG10*INDEX($U10:$AD10,1,MATCH($C$4,Setup!$B$21:$B$30,0))/$AF10,2)),"—") -> 23.55 | T10: =IF(AND($C10="",$D10="",NOT(ISNUMBER($E10))),"",IF($G10="",IF(Setup!$C$17="","Equal",Setup!$C$17),$G10)) -> Equal | U10: =IF($T10="",0,IF(OR(Setup!$B$21="",Setup!$C$21="No"),0,IF(ISNUMBER(H10),H10,IF($T10="Weights",IF(ISNUMBER(Setup!$D$21),Setup!$D$21,0),IF($T10="Nights",IF(ISNUMBER(Setup!$E$21),Setup!$E$21,0),IF(OR($T10="Exact amounts",$T10="Custom units"),0,1)))))) -> 1 | V10: =IF($T10="",0,IF(OR(Setup!$B$22="",Setup!$C$22="No"),0,IF(ISNUMBER(I10),I10,IF($T10="Weights",IF(ISNUMBER(Setup!$D$22),Setup!$D$22,0),IF($T10="Nights",IF(ISNUMBER(Setup!$E$22),Setup!$E$22,0),IF(OR($T10="Exact amounts",$T10="Custom units"),0,1)))))) -> 1 | W10: =IF($T10="",0,IF(OR(Setup!$B$23="",Setup!$C$23="No"),0,IF(ISNUMBER(J10),J10,IF($T10="Weights",IF(ISNUMBER(Setup!$D$23),Setup!$D$23,0),IF($T10="Nights",IF(ISNUMBER(Setup!$E$23),Setup!$E$23,0),IF(OR($T10="Exact amounts",$T10="Custom units"),0,1)))))) -> 1 | X10: =IF($T10="",0,IF(OR(Setup!$B$24="",Setup!$C$24="No"),0,IF(ISNUMBER(K10),K10,IF($T10="Weights",IF(ISNUMBER(Setup!$D$24),Setup!$D$24,0),IF($T10="Nights",IF(ISNUMBER(Setup!$E$24),Setup!$E$24,0),IF(OR($T10="Exact amounts",$T10="Custom units"),0,1)))))) -> 1 | Y10: =IF($T10="",0,IF(OR(Setup!$B$25="",Setup!$C$25="No"),0,IF(ISNUMBER(L10),L10,IF($T10="Weights",IF(ISNUMBER(Setup!$D$25),Setup!$D$25,0),IF($T10="Nights",IF(ISNUMBER(Setup!$E$25),Setup!$E$25,0),IF(OR($T10="Exact amounts",$T10="Custom units"),0,1)))))) -> 0 | Z10: =IF($T10="",0,IF(OR(Setup!$B$26="",Setup!$C$26="No"),0,IF(ISNUMBER(M10),M10,IF($T10="Weights",IF(ISNUMBER(Setup!$D$26),Setup!$D$26,0),IF($T10="Nights",IF(ISNUMBER(Setup!$E$26),Setup!$E$26,0),IF(OR($T10="Exact amounts",$T10="Custom units"),0,1)))))) -> 0 | AA10: =IF($T10="",0,IF(OR(Setup!$B$27="",Setup!$C$27="No"),0,IF(ISNUMBER(N10),N10,IF($T10="Weights",IF(ISNUMBER(Setup!$D$27),Setup!$D$27,0),IF($T10="Nights",IF(ISNUMBER(Setup!$E$27),Setup!$E$27,0),IF(OR($T10="Exact amounts",$T10="Custom units"),0,1)))))) -> 0 | AB10: =IF($T10="",0,IF(OR(Setup!$B$28="",Setup!$C$28="No"),0,IF(ISNUMBER(O10),O10,IF($T10="Weights",IF(ISNUMBER(Setup!$D$28),Setup!$D$28,0),IF($T10="Nights",IF(ISNUMBER(Setup!$E$28),Setup!$E$28,0),IF(OR($T10="Exact amounts",$T10="Custom units"),0,1)))))) -> 0 | AC10: =IF($T10="",0,IF(OR(Setup!$B$29="",Setup!$C$29="No"),0,IF(ISNUMBER(P10),P10,IF($T10="Weights",IF(ISNUMBER(Setup!$D$29),Setup!$D$29,0),IF($T10="Nights",IF(ISNUMBER(Setup!$E$29),Setup!$E$29,0),IF(OR($T10="Exact amounts",$T10="Custom units"),0,1)))))) -> 0 | AD10: =IF($T10="",0,IF(OR(Setup!$B$30="",Setup!$C$30="No"),0,IF(ISNUMBER(Q10),Q10,IF($T10="Weights",IF(ISNUMBER(Setup!$D$30),Setup!$D$30,0),IF($T10="Nights",IF(ISNUMBER(Setup!$E$30),Setup!$E$30,0),IF(OR($T10="Exact amounts",$T10="Custom units"),0,1)))))) -> 0 | AE10: =IF($T10="",0,SUM($U10:$AD10)) -> 4 | AF10: =IF($AE10<=0,1,$AE10) -> 4 | AG10: =IF(ISNUMBER($E10),$E10,0) -> 94.2
A11: =IF($T11="","—",ROW()-7) -> 4 | B11: =TODAY()-40 -> 46192 | C11: Cleaning supplies + light bulbs | D11: Dana | E11: 38.75 | F11: Household & repairs | G11: Equal | L11: 0 | R11: =IF($T11="","",IF($D11="","Who paid?",IF(SUMPRODUCT((Setup!$B$21:$B$30=$D11)*1)=0,"Payer is not in the member list on Setup",IF($E11="","Amount missing — type the number in column E",IF(NOT(ISNUMBER($E11)),"Amount must be a plain number — no currency symbol, no text",IF(AND($T11="Custom units",$AE11<=0),"Custom units: nobody has units on this row — type a number for at least one person",IF($AE11<=0,"Nobody shares this row — check the person columns H–Q, and the Weight / Nights columns on Setup",IF(AND($T11="Exact amounts",ABS($AE11-$AG11)>0.01),"Exact amounts do not add up to the amount","OK")))))))) -> OK | S11: =IFERROR(IF(OR($T11="",$C$4=""),"—",ROUND($AG11*INDEX($U11:$AD11,1,MATCH($C$4,Setup!$B$21:$B$30,0))/$AF11,2)),"—") -> 9.69 | T11: =IF(AND($C11="",$D11="",NOT(ISNUMBER($E11))),"",IF($G11="",IF(Setup!$C$17="","Equal",Setup!$C$17),$G11)) -> Equal | U11: =IF($T11="",0,IF(OR(Setup!$B$21="",Setup!$C$21="No"),0,IF(ISNUMBER(H11),H11,IF($T11="Weights",IF(ISNUMBER(Setup!$D$21),Setup!$D$21,0),IF($T11="Nights",IF(ISNUMBER(Setup!$E$21),Setup!$E$21,0),IF(OR($T11="Exact amounts",$T11="Custom units"),0,1)))))) -> 1 | V11: =IF($T11="",0,IF(OR(Setup!$B$22="",Setup!$C$22="No"),0,IF(ISNUMBER(I11),I11,IF($T11="Weights",IF(ISNUMBER(Setup!$D$22),Setup!$D$22,0),IF($T11="Nights",IF(ISNUMBER(Setup!$E$22),Setup!$E$22,0),IF(OR($T11="Exact amounts",$T11="Custom units"),0,1)))))) -> 1 | W11: =IF($T11="",0,IF(OR(Setup!$B$23="",Setup!$C$23="No"),0,IF(ISNUMBER(J11),J11,IF($T11="Weights",IF(ISNUMBER(Setup!$D$23),Setup!$D$23,0),IF($T11="Nights",IF(ISNUMBER(Setup!$E$23),Setup!$E$23,0),IF(OR($T11="Exact amounts",$T11="Custom units"),0,1)))))) -> 1 | X11: =IF($T11="",0,IF(OR(Setup!$B$24="",Setup!$C$24="No"),0,IF(ISNUMBER(K11),K11,IF($T11="Weights",IF(ISNUMBER(Setup!$D$24),Setup!$D$24,0),IF($T11="Nights",IF(ISNUMBER(Setup!$E$24),Setup!$E$24,0),IF(OR($T11="Exact amounts",$T11="Custom units"),0,1)))))) -> 1 | Y11: =IF($T11="",0,IF(OR(Setup!$B$25="",Setup!$C$25="No"),0,IF(ISNUMBER(L11),L11,IF($T11="Weights",IF(ISNUMBER(Setup!$D$25),Setup!$D$25,0),IF($T11="Nights",IF(ISNUMBER(Setup!$E$25),Setup!$E$25,0),IF(OR($T11="Exact amounts",$T11="Custom units"),0,1)))))) -> 0 | Z11: =IF($T11="",0,IF(OR(Setup!$B$26="",Setup!$C$26="No"),0,IF(ISNUMBER(M11),M11,IF($T11="Weights",IF(ISNUMBER(Setup!$D$26),Setup!$D$26,0),IF($T11="Nights",IF(ISNUMBER(Setup!$E$26),Setup!$E$26,0),IF(OR($T11="Exact amounts",$T11="Custom units"),0,1)))))) -> 0 | AA11: =IF($T11="",0,IF(OR(Setup!$B$27="",Setup!$C$27="No"),0,IF(ISNUMBER(N11),N11,IF($T11="Weights",IF(ISNUMBER(Setup!$D$27),Setup!$D$27,0),IF($T11="Nights",IF(ISNUMBER(Setup!$E$27),Setup!$E$27,0),IF(OR($T11="Exact amounts",$T11="Custom units"),0,1)))))) -> 0 | AB11: =IF($T11="",0,IF(OR(Setup!$B$28="",Setup!$C$28="No"),0,IF(ISNUMBER(O11),O11,IF($T11="Weights",IF(ISNUMBER(Setup!$D$28),Setup!$D$28,0),IF($T11="Nights",IF(ISNUMBER(Setup!$E$28),Setup!$E$28,0),IF(OR($T11="Exact amounts",$T11="Custom units"),0,1)))))) -> 0 | AC11: =IF($T11="",0,IF(OR(Setup!$B$29="",Setup!$C$29="No"),0,IF(ISNUMBER(P11),P11,IF($T11="Weights",IF(ISNUMBER(Setup!$D$29),Setup!$D$29,0),IF($T11="Nights",IF(ISNUMBER(Setup!$E$29),Setup!$E$29,0),IF(OR($T11="Exact amounts",$T11="Custom units"),0,1)))))) -> 0 | AD11: =IF($T11="",0,IF(OR(Setup!$B$30="",Setup!$C$30="No"),0,IF(ISNUMBER(Q11),Q11,IF($T11="Weights",IF(ISNUMBER(Setup!$D$30),Setup!$D$30,0),IF($T11="Nights",IF(ISNUMBER(Setup!$E$30),Setup!$E$30,0),IF(OR($T11="Exact amounts",$T11="Custom units"),0,1)))))) -> 0 | AE11: =IF($T11="",0,SUM($U11:$AD11)) -> 4 | AF11: =IF($AE11<=0,1,$AE11) -> 4 | AG11: =IF(ISNUMBER($E11),$E11,0) -> 38.75
A12: =IF($T12="","—",ROW()-7) -> 5 | B12: =TODAY()-38 -> 46194 | C12: Plumber — kitchen sink | D12: Anna | E12: 210 | F12: Household & repairs | G12: Equal | L12: 0 | R12: =IF($T12="","",IF($D12="","Who paid?",IF(SUMPRODUCT((Setup!$B$21:$B$30=$D12)*1)=0,"Payer is not in the member list on Setup",IF($E12="","Amount missing — type the number in column E",IF(NOT(ISNUMBER($E12)),"Amount must be a plain number — no currency symbol, no text",IF(AND($T12="Custom units",$AE12<=0),"Custom units: nobody has units on this row — type a number for at least one person",IF($AE12<=0,"Nobody shares this row — check the person columns H–Q, and the Weight / Nights columns on Setup",IF(AND($T12="Exact amounts",ABS($AE12-$AG12)>0.01),"Exact amounts do not add up to the amount","OK")))))))) -> OK | S12: =IFERROR(IF(OR($T12="",$C$4=""),"—",ROUND($AG12*INDEX($U12:$AD12,1,MATCH($C$4,Setup!$B$21:$B$30,0))/$AF12,2)),"—") -> 52.5 | T12: =IF(AND($C12="",$D12="",NOT(ISNUMBER($E12))),"",IF($G12="",IF(Setup!$C$17="","Equal",Setup!$C$17),$G12)) -> Equal | U12: =IF($T12="",0,IF(OR(Setup!$B$21="",Setup!$C$21="No"),0,IF(ISNUMBER(H12),H12,IF($T12="Weights",IF(ISNUMBER(Setup!$D$21),Setup!$D$21,0),IF($T12="Nights",IF(ISNUMBER(Setup!$E$21),Setup!$E$21,0),IF(OR($T12="Exact amounts",$T12="Custom units"),0,1)))))) -> 1 | V12: =IF($T12="",0,IF(OR(Setup!$B$22="",Setup!$C$22="No"),0,IF(ISNUMBER(I12),I12,IF($T12="Weights",IF(ISNUMBER(Setup!$D$22),Setup!$D$22,0),IF($T12="Nights",IF(ISNUMBER(Setup!$E$22),Setup!$E$22,0),IF(OR($T12="Exact amounts",$T12="Custom units"),0,1)))))) -> 1 | W12: =IF($T12="",0,IF(OR(Setup!$B$23="",Setup!$C$23="No"),0,IF(ISNUMBER(J12),J12,IF($T12="Weights",IF(ISNUMBER(Setup!$D$23),Setup!$D$23,0),IF($T12="Nights",IF(ISNUMBER(Setup!$E$23),Setup!$E$23,0),IF(OR($T12="Exact amounts",$T12="Custom units"),0,1)))))) -> 1 | X12: =IF($T12="",0,IF(OR(Setup!$B$24="",Setup!$C$24="No"),0,IF(ISNUMBER(K12),K12,IF($T12="Weights",IF(ISNUMBER(Setup!$D$24),Setup!$D$24,0),IF($T12="Nights",IF(ISNUMBER(Setup!$E$24),Setup!$E$24,0),IF(OR($T12="Exact amounts",$T12="Custom units"),0,1)))))) -> 1 | Y12: =IF($T12="",0,IF(OR(Setup!$B$25="",Setup!$C$25="No"),0,IF(ISNUMBER(L12),L12,IF($T12="Weights",IF(ISNUMBER(Setup!$D$25),Setup!$D$25,0),IF($T12="Nights",IF(ISNUMBER(Setup!$E$25),Setup!$E$25,0),IF(OR($T12="Exact amounts",$T12="Custom units"),0,1)))))) -> 0 | Z12: =IF($T12="",0,IF(OR(Setup!$B$26="",Setup!$C$26="No"),0,IF(ISNUMBER(M12),M12,IF($T12="Weights",IF(ISNUMBER(Setup!$D$26),Setup!$D$26,0),IF($T12="Nights",IF(ISNUMBER(Setup!$E$26),Setup!$E$26,0),IF(OR($T12="Exact amounts",$T12="Custom units"),0,1)))))) -> 0 | AA12: =IF($T12="",0,IF(OR(Setup!$B$27="",Setup!$C$27="No"),0,IF(ISNUMBER(N12),N12,IF($T12="Weights",IF(ISNUMBER(Setup!$D$27),Setup!$D$27,0),IF($T12="Nights",IF(ISNUMBER(Setup!$E$27),Setup!$E$27,0),IF(OR($T12="Exact amounts",$T12="Custom units"),0,1)))))) -> 0 | AB12: =IF($T12="",0,IF(OR(Setup!$B$28="",Setup!$C$28="No"),0,IF(ISNUMBER(O12),O12,IF($T12="Weights",IF(ISNUMBER(Setup!$D$28),Setup!$D$28,0),IF($T12="Nights",IF(ISNUMBER(Setup!$E$28),Setup!$E$28,0),IF(OR($T12="Exact amounts",$T12="Custom units"),0,1)))))) -> 0 | AC12: =IF($T12="",0,IF(OR(Setup!$B$29="",Setup!$C$29="No"),0,IF(ISNUMBER(P12),P12,IF($T12="Weights",IF(ISNUMBER(Setup!$D$29),Setup!$D$29,0),IF($T12="Nights",IF(ISNUMBER(Setup!$E$29),Setup!$E$29,0),IF(OR($T12="Exact amounts",$T12="Custom units"),0,1)))))) -> 0 | AD12: =IF($T12="",0,IF(OR(Setup!$B$30="",Setup!$C$30="No"),0,IF(ISNUMBER(Q12),Q12,IF($T12="Weights",IF(ISNUMBER(Setup!$D$30),Setup!$D$30,0),IF($T12="Nights",IF(ISNUMBER(Setup!$E$30),Setup!$E$30,0),IF(OR($T12="Exact amounts",$T12="Custom units"),0,1)))))) -> 0 | AE12: =IF($T12="",0,SUM($U12:$AD12)) -> 4 | AF12: =IF($AE12<=0,1,$AE12) -> 4 | AG12: =IF(ISNUMBER($E12),$E12,0) -> 210
A13: =IF($T13="","—",ROW()-7) -> 6 | B13: =TODAY()-36 -> 46196 | C13: Weekly groceries | D13: Ben | E13: 112.6 | F13: Groceries | G13: Equal | L13: 0 | R13: =IF($T13="","",IF($D13="","Who paid?",IF(SUMPRODUCT((Setup!$B$21:$B$30=$D13)*1)=0,"Payer is not in the member list on Setup",IF($E13="","Amount missing — type the number in column E",IF(NOT(ISNUMBER($E13)),"Amount must be a plain number — no currency symbol, no text",IF(AND($T13="Custom units",$AE13<=0),"Custom units: nobody has units on this row — type a number for at least one person",IF($AE13<=0,"Nobody shares this row — check the person columns H–Q, and the Weight / Nights columns on Setup",IF(AND($T13="Exact amounts",ABS($AE13-$AG13)>0.01),"Exact amounts do not add up to the amount","OK")))))))) -> OK | S13: =IFERROR(IF(OR($T13="",$C$4=""),"—",ROUND($AG13*INDEX($U13:$AD13,1,MATCH($C$4,Setup!$B$21:$B$30,0))/$AF13,2)),"—") -> 28.15 | T13: =IF(AND($C13="",$D13="",NOT(ISNUMBER($E13))),"",IF($G13="",IF(Setup!$C$17="","Equal",Setup!$C$17),$G13)) -> Equal | U13: =IF($T13="",0,IF(OR(Setup!$B$21="",Setup!$C$21="No"),0,IF(ISNUMBER(H13),H13,IF($T13="Weights",IF(ISNUMBER(Setup!$D$21),Setup!$D$21,0),IF($T13="Nights",IF(ISNUMBER(Setup!$E$21),Setup!$E$21,0),IF(OR($T13="Exact amounts",$T13="Custom units"),0,1)))))) -> 1 | V13: =IF($T13="",0,IF(OR(Setup!$B$22="",Setup!$C$22="No"),0,IF(ISNUMBER(I13),I13,IF($T13="Weights",IF(ISNUMBER(Setup!$D$22),Setup!$D$22,0),IF($T13="Nights",IF(ISNUMBER(Setup!$E$22),Setup!$E$22,0),IF(OR($T13="Exact amounts",$T13="Custom units"),0,1)))))) -> 1 | W13: =IF($T13="",0,IF(OR(Setup!$B$23="",Setup!$C$23="No"),0,IF(ISNUMBER(J13),J13,IF($T13="Weights",IF(ISNUMBER(Setup!$D$23),Setup!$D$23,0),IF($T13="Nights",IF(ISNUMBER(Setup!$E$23),Setup!$E$23,0),IF(OR($T13="Exact amounts",$T13="Custom units"),0,1)))))) -> 1 | X13: =IF($T13="",0,IF(OR(Setup!$B$24="",Setup!$C$24="No"),0,IF(ISNUMBER(K13),K13,IF($T13="Weights",IF(ISNUMBER(Setup!$D$24),Setup!$D$24,0),IF($T13="Nights",IF(ISNUMBER(Setup!$E$24),Setup!$E$24,0),IF(OR($T13="Exact amounts",$T13="Custom units"),0,1)))))) -> 1 | Y13: =IF($T13="",0,IF(OR(Setup!$B$25="",Setup!$C$25="No"),0,IF(ISNUMBER(L13),L13,IF($T13="Weights",IF(ISNUMBER(Setup!$D$25),Setup!$D$25,0),IF($T13="Nights",IF(ISNUMBER(Setup!$E$25),Setup!$E$25,0),IF(OR($T13="Exact amounts",$T13="Custom units"),0,1)))))) -> 0 | Z13: =IF($T13="",0,IF(OR(Setup!$B$26="",Setup!$C$26="No"),0,IF(ISNUMBER(M13),M13,IF($T13="Weights",IF(ISNUMBER(Setup!$D$26),Setup!$D$26,0),IF($T13="Nights",IF(ISNUMBER(Setup!$E$26),Setup!$E$26,0),IF(OR($T13="Exact amounts",$T13="Custom units"),0,1)))))) -> 0 | AA13: =IF($T13="",0,IF(OR(Setup!$B$27="",Setup!$C$27="No"),0,IF(ISNUMBER(N13),N13,IF($T13="Weights",IF(ISNUMBER(Setup!$D$27),Setup!$D$27,0),IF($T13="Nights",IF(ISNUMBER(Setup!$E$27),Setup!$E$27,0),IF(OR($T13="Exact amounts",$T13="Custom units"),0,1)))))) -> 0 | AB13: =IF($T13="",0,IF(OR(Setup!$B$28="",Setup!$C$28="No"),0,IF(ISNUMBER(O13),O13,IF($T13="Weights",IF(ISNUMBER(Setup!$D$28),Setup!$D$28,0),IF($T13="Nights",IF(ISNUMBER(Setup!$E$28),Setup!$E$28,0),IF(OR($T13="Exact amounts",$T13="Custom units"),0,1)))))) -> 0 | AC13: =IF($T13="",0,IF(OR(Setup!$B$29="",Setup!$C$29="No"),0,IF(ISNUMBER(P13),P13,IF($T13="Weights",IF(ISNUMBER(Setup!$D$29),Setup!$D$29,0),IF($T13="Nights",IF(ISNUMBER(Setup!$E$29),Setup!$E$29,0),IF(OR($T13="Exact amounts",$T13="Custom units"),0,1)))))) -> 0 | AD13: =IF($T13="",0,IF(OR(Setup!$B$30="",Setup!$C$30="No"),0,IF(ISNUMBER(Q13),Q13,IF($T13="Weights",IF(ISNUMBER(Setup!$D$30),Setup!$D$30,0),IF($T13="Nights",IF(ISNUMBER(Setup!$E$30),Setup!$E$30,0),IF(OR($T13="Exact amounts",$T13="Custom units"),0,1)))))) -> 0 | AE13: =IF($T13="",0,SUM($U13:$AD13)) -> 4 | AF13: =IF($AE13<=0,1,$AE13) -> 4 | AG13: =IF(ISNUMBER($E13),$E13,0) -> 112.6
A14: =IF($T14="","—",ROW()-7) -> 7 | B14: =TODAY()-34 -> 46198 | C14: Pizza night at home | D14: Dana | E14: 61.5 | F14: Eating out | G14: Equal | L14: 0 | R14: =IF($T14="","",IF($D14="","Who paid?",IF(SUMPRODUCT((Setup!$B$21:$B$30=$D14)*1)=0,"Payer is not in the member list on Setup",IF($E14="","Amount missing — type the number in column E",IF(NOT(ISNUMBER($E14)),"Amount must be a plain number — no currency symbol, no text",IF(AND($T14="Custom units",$AE14<=0),"Custom units: nobody has units on this row — type a number for at least one person",IF($AE14<=0,"Nobody shares this row — check the person columns H–Q, and the Weight / Nights columns on Setup",IF(AND($T14="Exact amounts",ABS($AE14-$AG14)>0.01),"Exact amounts do not add up to the amount","OK")))))))) -> OK | S14: =IFERROR(IF(OR($T14="",$C$4=""),"—",ROUND($AG14*INDEX($U14:$AD14,1,MATCH($C$4,Setup!$B$21:$B$30,0))/$AF14,2)),"—") -> 15.38 | T14: =IF(AND($C14="",$D14="",NOT(ISNUMBER($E14))),"",IF($G14="",IF(Setup!$C$17="","Equal",Setup!$C$17),$G14)) -> Equal | U14: =IF($T14="",0,IF(OR(Setup!$B$21="",Setup!$C$21="No"),0,IF(ISNUMBER(H14),H14,IF($T14="Weights",IF(ISNUMBER(Setup!$D$21),Setup!$D$21,0),IF($T14="Nights",IF(ISNUMBER(Setup!$E$21),Setup!$E$21,0),IF(OR($T14="Exact amounts",$T14="Custom units"),0,1)))))) -> 1 | V14: =IF($T14="",0,IF(OR(Setup!$B$22="",Setup!$C$22="No"),0,IF(ISNUMBER(I14),I14,IF($T14="Weights",IF(ISNUMBER(Setup!$D$22),Setup!$D$22,0),IF($T14="Nights",IF(ISNUMBER(Setup!$E$22),Setup!$E$22,0),IF(OR($T14="Exact amounts",$T14="Custom units"),0,1)))))) -> 1 | W14: =IF($T14="",0,IF(OR(Setup!$B$23="",Setup!$C$23="No"),0,IF(ISNUMBER(J14),J14,IF($T14="Weights",IF(ISNUMBER(Setup!$D$23),Setup!$D$23,0),IF($T14="Nights",IF(ISNUMBER(Setup!$E$23),Setup!$E$23,0),IF(OR($T14="Exact amounts",$T14="Custom units"),0,1)))))) -> 1 | X14: =IF($T14="",0,IF(OR(Setup!$B$24="",Setup!$C$24="No"),0,IF(ISNUMBER(K14),K14,IF($T14="Weights",IF(ISNUMBER(Setup!$D$24),Setup!$D$24,0),IF($T14="Nights",IF(ISNUMBER(Setup!$E$24),Setup!$E$24,0),IF(OR($T14="Exact amounts",$T14="Custom units"),0,1)))))) -> 1 | Y14: =IF($T14="",0,IF(OR(Setup!$B$25="",Setup!$C$25="No"),0,IF(ISNUMBER(L14),L14,IF($T14="Weights",IF(ISNUMBER(Setup!$D$25),Setup!$D$25,0),IF($T14="Nights",IF(ISNUMBER(Setup!$E$25),Setup!$E$25,0),IF(OR($T14="Exact amounts",$T14="Custom units"),0,1)))))) -> 0 | Z14: =IF($T14="",0,IF(OR(Setup!$B$26="",Setup!$C$26="No"),0,IF(ISNUMBER(M14),M14,IF($T14="Weights",IF(ISNUMBER(Setup!$D$26),Setup!$D$26,0),IF($T14="Nights",IF(ISNUMBER(Setup!$E$26),Setup!$E$26,0),IF(OR($T14="Exact amounts",$T14="Custom units"),0,1)))))) -> 0 | AA14: =IF($T14="",0,IF(OR(Setup!$B$27="",Setup!$C$27="No"),0,IF(ISNUMBER(N14),N14,IF($T14="Weights",IF(ISNUMBER(Setup!$D$27),Setup!$D$27,0),IF($T14="Nights",IF(ISNUMBER(Setup!$E$27),Setup!$E$27,0),IF(OR($T14="Exact amounts",$T14="Custom units"),0,1)))))) -> 0 | AB14: =IF($T14="",0,IF(OR(Setup!$B$28="",Setup!$C$28="No"),0,IF(ISNUMBER(O14),O14,IF($T14="Weights",IF(ISNUMBER(Setup!$D$28),Setup!$D$28,0),IF($T14="Nights",IF(ISNUMBER(Setup!$E$28),Setup!$E$28,0),IF(OR($T14="Exact amounts",$T14="Custom units"),0,1)))))) -> 0 | AC14: =IF($T14="",0,IF(OR(Setup!$B$29="",Setup!$C$29="No"),0,IF(ISNUMBER(P14),P14,IF($T14="Weights",IF(ISNUMBER(Setup!$D$29),Setup!$D$29,0),IF($T14="Nights",IF(ISNUMBER(Setup!$E$29),Setup!$E$29,0),IF(OR($T14="Exact amounts",$T14="Custom units"),0,1)))))) -> 0 | AD14: =IF($T14="",0,IF(OR(Setup!$B$30="",Setup!$C$30="No"),0,IF(ISNUMBER(Q14),Q14,IF($T14="Weights",IF(ISNUMBER(Setup!$D$30),Setup!$D$30,0),IF($T14="Nights",IF(ISNUMBER(Setup!$E$30),Setup!$E$30,0),IF(OR($T14="Exact amounts",$T14="Custom units"),0,1)))))) -> 0 | AE14: =IF($T14="",0,SUM($U14:$AD14)) -> 4 | AF14: =IF($AE14<=0,1,$AE14) -> 4 | AG14: =IF(ISNUMBER($E14),$E14,0) -> 61.5
A15: =IF($T15="","—",ROW()-7) -> 8 | B15: =TODAY()-32 -> 46200 | C15: Weekly groceries | D15: Anna | E15: 88.9 | F15: Groceries | G15: Equal | L15: 0 | R15: =IF($T15="","",IF($D15="","Who paid?",IF(SUMPRODUCT((Setup!$B$21:$B$30=$D15)*1)=0,"Payer is not in the member list on Setup",IF($E15="","Amount missing — type the number in column E",IF(NOT(ISNUMBER($E15)),"Amount must be a plain number — no currency symbol, no text",IF(AND($T15="Custom units",$AE15<=0),"Custom units: nobody has units on this row — type a number for at least one person",IF($AE15<=0,"Nobody shares this row — check the person columns H–Q, and the Weight / Nights columns on Setup",IF(AND($T15="Exact amounts",ABS($AE15-$AG15)>0.01),"Exact amounts do not add up to the amount","OK")))))))) -> OK | S15: =IFERROR(IF(OR($T15="",$C$4=""),"—",ROUND($AG15*INDEX($U15:$AD15,1,MATCH($C$4,Setup!$B$21:$B$30,0))/$AF15,2)),"—") -> 22.23 | T15: =IF(AND($C15="",$D15="",NOT(ISNUMBER($E15))),"",IF($G15="",IF(Setup!$C$17="","Equal",Setup!$C$17),$G15)) -> Equal | U15: =IF($T15="",0,IF(OR(Setup!$B$21="",Setup!$C$21="No"),0,IF(ISNUMBER(H15),H15,IF($T15="Weights",IF(ISNUMBER(Setup!$D$21),Setup!$D$21,0),IF($T15="Nights",IF(ISNUMBER(Setup!$E$21),Setup!$E$21,0),IF(OR($T15="Exact amounts",$T15="Custom units"),0,1)))))) -> 1 | V15: =IF($T15="",0,IF(OR(Setup!$B$22="",Setup!$C$22="No"),0,IF(ISNUMBER(I15),I15,IF($T15="Weights",IF(ISNUMBER(Setup!$D$22),Setup!$D$22,0),IF($T15="Nights",IF(ISNUMBER(Setup!$E$22),Setup!$E$22,0),IF(OR($T15="Exact amounts",$T15="Custom units"),0,1)))))) -> 1 | W15: =IF($T15="",0,IF(OR(Setup!$B$23="",Setup!$C$23="No"),0,IF(ISNUMBER(J15),J15,IF($T15="Weights",IF(ISNUMBER(Setup!$D$23),Setup!$D$23,0),IF($T15="Nights",IF(ISNUMBER(Setup!$E$23),Setup!$E$23,0),IF(OR($T15="Exact amounts",$T15="Custom units"),0,1)))))) -> 1 | X15: =IF($T15="",0,IF(OR(Setup!$B$24="",Setup!$C$24="No"),0,IF(ISNUMBER(K15),K15,IF($T15="Weights",IF(ISNUMBER(Setup!$D$24),Setup!$D$24,0),IF($T15="Nights",IF(ISNUMBER(Setup!$E$24),Setup!$E$24,0),IF(OR($T15="Exact amounts",$T15="Custom units"),0,1)))))) -> 1 | Y15: =IF($T15="",0,IF(OR(Setup!$B$25="",Setup!$C$25="No"),0,IF(ISNUMBER(L15),L15,IF($T15="Weights",IF(ISNUMBER(Setup!$D$25),Setup!$D$25,0),IF($T15="Nights",IF(ISNUMBER(Setup!$E$25),Setup!$E$25,0),IF(OR($T15="Exact amounts",$T15="Custom units"),0,1)))))) -> 0 | Z15: =IF($T15="",0,IF(OR(Setup!$B$26="",Setup!$C$26="No"),0,IF(ISNUMBER(M15),M15,IF($T15="Weights",IF(ISNUMBER(Setup!$D$26),Setup!$D$26,0),IF($T15="Nights",IF(ISNUMBER(Setup!$E$26),Setup!$E$26,0),IF(OR($T15="Exact amounts",$T15="Custom units"),0,1)))))) -> 0 | AA15: =IF($T15="",0,IF(OR(Setup!$B$27="",Setup!$C$27="No"),0,IF(ISNUMBER(N15),N15,IF($T15="Weights",IF(ISNUMBER(Setup!$D$27),Setup!$D$27,0),IF($T15="Nights",IF(ISNUMBER(Setup!$E$27),Setup!$E$27,0),IF(OR($T15="Exact amounts",$T15="Custom units"),0,1)))))) -> 0 | AB15: =IF($T15="",0,IF(OR(Setup!$B$28="",Setup!$C$28="No"),0,IF(ISNUMBER(O15),O15,IF($T15="Weights",IF(ISNUMBER(Setup!$D$28),Setup!$D$28,0),IF($T15="Nights",IF(ISNUMBER(Setup!$E$28),Setup!$E$28,0),IF(OR($T15="Exact amounts",$T15="Custom units"),0,1)))))) -> 0 | AC15: =IF($T15="",0,IF(OR(Setup!$B$29="",Setup!$C$29="No"),0,IF(ISNUMBER(P15),P15,IF($T15="Weights",IF(ISNUMBER(Setup!$D$29),Setup!$D$29,0),IF($T15="Nights",IF(ISNUMBER(Setup!$E$29),Setup!$E$29,0),IF(OR($T15="Exact amounts",$T15="Custom units"),0,1)))))) -> 0 | AD15: =IF($T15="",0,IF(OR(Setup!$B$30="",Setup!$C$30="No"),0,IF(ISNUMBER(Q15),Q15,IF($T15="Weights",IF(ISNUMBER(Setup!$D$30),Setup!$D$30,0),IF($T15="Nights",IF(ISNUMBER(Setup!$E$30),Setup!$E$30,0),IF(OR($T15="Exact amounts",$T15="Custom units"),0,1)))))) -> 0 | AE15: =IF($T15="",0,SUM($U15:$AD15)) -> 4 | AF15: =IF($AE15<=0,1,$AE15) -> 4 | AG15: =IF(ISNUMBER($E15),$E15,0) -> 88.9
A16: =IF($T16="","—",ROW()-7) -> 9 | B16: =TODAY()-30 -> 46202 | C16: Supermarket — shared + 2 personal items | D16: Chris | E16: 76.4 | F16: Groceries | G16: Exact amounts | H16: 24.9 | I16: 15 | J16: 15 | K16: 21.5 | R16: =IF($T16="","",IF($D16="","Who paid?",IF(SUMPRODUCT((Setup!$B$21:$B$30=$D16)*1)=0,"Payer is not in the member list on Setup",IF($E16="","Amount missing — type the number in column E",IF(NOT(ISNUMBER($E16)),"Amount must be a plain number — no currency symbol, no text",IF(AND($T16="Custom units",$AE16<=0),"Custom units: nobody has units on this row — type a number for at least one person",IF($AE16<=0,"Nobody shares this row — check the person columns H–Q, and the Weight / Nights columns on Setup",IF(AND($T16="Exact amounts",ABS($AE16-$AG16)>0.01),"Exact amounts do not add up to the amount","OK")))))))) -> OK | S16: =IFERROR(IF(OR($T16="",$C$4=""),"—",ROUND($AG16*INDEX($U16:$AD16,1,MATCH($C$4,Setup!$B$21:$B$30,0))/$AF16,2)),"—") -> 24.9 | T16: =IF(AND($C16="",$D16="",NOT(ISNUMBER($E16))),"",IF($G16="",IF(Setup!$C$17="","Equal",Setup!$C$17),$G16)) -> Exact amounts | U16: =IF($T16="",0,IF(OR(Setup!$B$21="",Setup!$C$21="No"),0,IF(ISNUMBER(H16),H16,IF($T16="Weights",IF(ISNUMBER(Setup!$D$21),Setup!$D$21,0),IF($T16="Nights",IF(ISNUMBER(Setup!$E$21),Setup!$E$21,0),IF(OR($T16="Exact amounts",$T16="Custom units"),0,1)))))) -> 24.9 | V16: =IF($T16="",0,IF(OR(Setup!$B$22="",Setup!$C$22="No"),0,IF(ISNUMBER(I16),I16,IF($T16="Weights",IF(ISNUMBER(Setup!$D$22),Setup!$D$22,0),IF($T16="Nights",IF(ISNUMBER(Setup!$E$22),Setup!$E$22,0),IF(OR($T16="Exact amounts",$T16="Custom units"),0,1)))))) -> 15 | W16: =IF($T16="",0,IF(OR(Setup!$B$23="",Setup!$C$23="No"),0,IF(ISNUMBER(J16),J16,IF($T16="Weights",IF(ISNUMBER(Setup!$D$23),Setup!$D$23,0),IF($T16="Nights",IF(ISNUMBER(Setup!$E$23),Setup!$E$23,0),IF(OR($T16="Exact amounts",$T16="Custom units"),0,1)))))) -> 15 | X16: =IF($T16="",0,IF(OR(Setup!$B$24="",Setup!$C$24="No"),0,IF(ISNUMBER(K16),K16,IF($T16="Weights",IF(ISNUMBER(Setup!$D$24),Setup!$D$24,0),IF($T16="Nights",IF(ISNUMBER(Setup!$E$24),Setup!$E$24,0),IF(OR($T16="Exact amounts",$T16="Custom units"),0,1)))))) -> 21.5 | Y16: =IF($T16="",0,IF(OR(Setup!$B$25="",Setup!$C$25="No"),0,IF(ISNUMBER(L16),L16,IF($T16="Weights",IF(ISNUMBER(Setup!$D$25),Setup!$D$25,0),IF($T16="Nights",IF(ISNUMBER(Setup!$E$25),Setup!$E$25,0),IF(OR($T16="Exact amounts",$T16="Custom units"),0,1)))))) -> 0 | Z16: =IF($T16="",0,IF(OR(Setup!$B$26="",Setup!$C$26="No"),0,IF(ISNUMBER(M16),M16,IF($T16="Weights",IF(ISNUMBER(Setup!$D$26),Setup!$D$26,0),IF($T16="Nights",IF(ISNUMBER(Setup!$E$26),Setup!$E$26,0),IF(OR($T16="Exact amounts",$T16="Custom units"),0,1)))))) -> 0 | AA16: =IF($T16="",0,IF(OR(Setup!$B$27="",Setup!$C$27="No"),0,IF(ISNUMBER(N16),N16,IF($T16="Weights",IF(ISNUMBER(Setup!$D$27),Setup!$D$27,0),IF($T16="Nights",IF(ISNUMBER(Setup!$E$27),Setup!$E$27,0),IF(OR($T16="Exact amounts",$T16="Custom units"),0,1)))))) -> 0 | AB16: =IF($T16="",0,IF(OR(Setup!$B$28="",Setup!$C$28="No"),0,IF(ISNUMBER(O16),O16,IF($T16="Weights",IF(ISNUMBER(Setup!$D$28),Setup!$D$28,0),IF($T16="Nights",IF(ISNUMBER(Setup!$E$28),Setup!$E$28,0),IF(OR($T16="Exact amounts",$T16="Custom units"),0,1)))))) -> 0 | AC16: =IF($T16="",0,IF(OR(Setup!$B$29="",Setup!$C$29="No"),0,IF(ISNUMBER(P16),P16,IF($T16="Weights",IF(ISNUMBER(Setup!$D$29),Setup!$D$29,0),IF($T16="Nights",IF(ISNUMBER(Setup!$E$29),Setup!$E$29,0),IF(OR($T16="Exact amounts",$T16="Custom units"),0,1)))))) -> 0 | AD16: =IF($T16="",0,IF(OR(Setup!$B$30="",Setup!$C$30="No"),0,IF(ISNUMBER(Q16),Q16,IF($T16="Weights",IF(ISNUMBER(Setup!$D$30),Setup!$D$30,0),IF($T16="Nights",IF(ISNUMBER(Setup!$E$30),Setup!$E$30,0),IF(OR($T16="Exact amounts",$T16="Custom units"),0,1)))))) -> 0 | AE16: =IF($T16="",0,SUM($U16:$AD16)) -> 76.4 | AF16: =IF($AE16<=0,1,$AE16) -> 76.4 | AG16: =IF(ISNUMBER($E16),$E16,0) -> 76.4
A17: =IF($T17="","—",ROW()-7) -> 10 | B17: =TODAY()-28 -> 46204 | C17: New wifi router | D17: Ben | E17: 79 | F17: Household & repairs | G17: Equal | L17: 0 | R17: =IF($T17="","",IF($D17="","Who paid?",IF(SUMPRODUCT((Setup!$B$21:$B$30=$D17)*1)=0,"Payer is not in the member list on Setup",IF($E17="","Amount missing — type the number in column E",IF(NOT(ISNUMBER($E17)),"Amount must be a plain number — no currency symbol, no text",IF(AND($T17="Custom units",$AE17<=0),"Custom units: nobody has units on this row — type a number for at least one person",IF($AE17<=0,"Nobody shares this row — check the person columns H–Q, and the Weight / Nights columns on Setup",IF(AND($T17="Exact amounts",ABS($AE17-$AG17)>0.01),"Exact amounts do not add up to the amount","OK")))))))) -> OK | S17: =IFERROR(IF(OR($T17="",$C$4=""),"—",ROUND($AG17*INDEX($U17:$AD17,1,MATCH($C$4,Setup!$B$21:$B$30,0))/$AF17,2)),"—") -> 19.75 | T17: =IF(AND($C17="",$D17="",NOT(ISNUMBER($E17))),"",IF($G17="",IF(Setup!$C$17="","Equal",Setup!$C$17),$G17)) -> Equal | U17: =IF($T17="",0,IF(OR(Setup!$B$21="",Setup!$C$21="No"),0,IF(ISNUMBER(H17),H17,IF($T17="Weights",IF(ISNUMBER(Setup!$D$21),Setup!$D$21,0),IF($T17="Nights",IF(ISNUMBER(Setup!$E$21),Setup!$E$21,0),IF(OR($T17="Exact amounts",$T17="Custom units"),0,1)))))) -> 1 | V17: =IF($T17="",0,IF(OR(Setup!$B$22="",Setup!$C$22="No"),0,IF(ISNUMBER(I17),I17,IF($T17="Weights",IF(ISNUMBER(Setup!$D$22),Setup!$D$22,0),IF($T17="Nights",IF(ISNUMBER(Setup!$E$22),Setup!$E$22,0),IF(OR($T17="Exact amounts",$T17="Custom units"),0,1)))))) -> 1 | W17: =IF($T17="",0,IF(OR(Setup!$B$23="",Setup!$C$23="No"),0,IF(ISNUMBER(J17),J17,IF($T17="Weights",IF(ISNUMBER(Setup!$D$23),Setup!$D$23,0),IF($T17="Nights",IF(ISNUMBER(Setup!$E$23),Setup!$E$23,0),IF(OR($T17="Exact amounts",$T17="Custom units"),0,1)))))) -> 1 | X17: =IF($T17="",0,IF(OR(Setup!$B$24="",Setup!$C$24="No"),0,IF(ISNUMBER(K17),K17,IF($T17="Weights",IF(ISNUMBER(Setup!$D$24),Setup!$D$24,0),IF($T17="Nights",IF(ISNUMBER(Setup!$E$24),Setup!$E$24,0),IF(OR($T17="Exact amounts",$T17="Custom units"),0,1)))))) -> 1 | Y17: =IF($T17="",0,IF(OR(Setup!$B$25="",Setup!$C$25="No"),0,IF(ISNUMBER(L17),L17,IF($T17="Weights",IF(ISNUMBER(Setup!$D$25),Setup!$D$25,0),IF($T17="Nights",IF(ISNUMBER(Setup!$E$25),Setup!$E$25,0),IF(OR($T17="Exact amounts",$T17="Custom units"),0,1)))))) -> 0 | Z17: =IF($T17="",0,IF(OR(Setup!$B$26="",Setup!$C$26="No"),0,IF(ISNUMBER(M17),M17,IF($T17="Weights",IF(ISNUMBER(Setup!$D$26),Setup!$D$26,0),IF($T17="Nights",IF(ISNUMBER(Setup!$E$26),Setup!$E$26,0),IF(OR($T17="Exact amounts",$T17="Custom units"),0,1)))))) -> 0 | AA17: =IF($T17="",0,IF(OR(Setup!$B$27="",Setup!$C$27="No"),0,IF(ISNUMBER(N17),N17,IF($T17="Weights",IF(ISNUMBER(Setup!$D$27),Setup!$D$27,0),IF($T17="Nights",IF(ISNUMBER(Setup!$E$27),Setup!$E$27,0),IF(OR($T17="Exact amounts",$T17="Custom units"),0,1)))))) -> 0 | AB17: =IF($T17="",0,IF(OR(Setup!$B$28="",Setup!$C$28="No"),0,IF(ISNUMBER(O17),O17,IF($T17="Weights",IF(ISNUMBER(Setup!$D$28),Setup!$D$28,0),IF($T17="Nights",IF(ISNUMBER(Setup!$E$28),Setup!$E$28,0),IF(OR($T17="Exact amounts",$T17="Custom units"),0,1)))))) -> 0 | AC17: =IF($T17="",0,IF(OR(Setup!$B$29="",Setup!$C$29="No"),0,IF(ISNUMBER(P17),P17,IF($T17="Weights",IF(ISNUMBER(Setup!$D$29),Setup!$D$29,0),IF($T17="Nights",IF(ISNUMBER(Setup!$E$29),Setup!$E$29,0),IF(OR($T17="Exact amounts",$T17="Custom units"),0,1)))))) -> 0 | AD17: =IF($T17="",0,IF(OR(Setup!$B$30="",Setup!$C$30="No"),0,IF(ISNUMBER(Q17),Q17,IF($T17="Weights",IF(ISNUMBER(Setup!$D$30),Setup!$D$30,0),IF($T17="Nights",IF(ISNUMBER(Setup!$E$30),Setup!$E$30,0),IF(OR($T17="Exact amounts",$T17="Custom units"),0,1)))))) -> 0 | AE17: =IF($T17="",0,SUM($U17:$AD17)) -> 4 | AF17: =IF($AE17<=0,1,$AE17) -> 4 | AG17: =IF(ISNUMBER($E17),$E17,0) -> 79
A18: =IF($T18="","—",ROW()-7) -> 11 | B18: =TODAY()-21 -> 46211 | C18: Flights Munich → Lisbon (5 tickets) | D18: Anna | E18: 745 | F18: Travel & transport | G18: Equal | R18: =IF($T18="","",IF($D18="","Who paid?",IF(SUMPRODUCT((Setup!$B$21:$B$30=$D18)*1)=0,"Payer is not in the member list on Setup",IF($E18="","Amount missing — type the number in column E",IF(NOT(ISNUMBER($E18)),"Amount must be a plain number — no currency symbol, no text",IF(AND($T18="Custom units",$AE18<=0),"Custom units: nobody has units on this row — type a number for at least one person",IF($AE18<=0,"Nobody shares this row — check the person columns H–Q, and the Weight / Nights columns on Setup",IF(AND($T18="Exact amounts",ABS($AE18-$AG18)>0.01),"Exact amounts do not add up to the amount","OK")))))))) -> OK | S18: =IFERROR(IF(OR($T18="",$C$4=""),"—",ROUND($AG18*INDEX($U18:$AD18,1,MATCH($C$4,Setup!$B$21:$B$30,0))/$AF18,2)),"—") -> 149 | T18: =IF(AND($C18="",$D18="",NOT(ISNUMBER($E18))),"",IF($G18="",IF(Setup!$C$17="","Equal",Setup!$C$17),$G18)) -> Equal | U18: =IF($T18="",0,IF(OR(Setup!$B$21="",Setup!$C$21="No"),0,IF(ISNUMBER(H18),H18,IF($T18="Weights",IF(ISNUMBER(Setup!$D$21),Setup!$D$21,0),IF($T18="Nights",IF(ISNUMBER(Setup!$E$21),Setup!$E$21,0),IF(OR($T18="Exact amounts",$T18="Custom units"),0,1)))))) -> 1 | V18: =IF($T18="",0,IF(OR(Setup!$B$22="",Setup!$C$22="No"),0,IF(ISNUMBER(I18),I18,IF($T18="Weights",IF(ISNUMBER(Setup!$D$22),Setup!$D$22,0),IF($T18="Nights",IF(ISNUMBER(Setup!$E$22),Setup!$E$22,0),IF(OR($T18="Exact amounts",$T18="Custom units"),0,1)))))) -> 1 | W18: =IF($T18="",0,IF(OR(Setup!$B$23="",Setup!$C$23="No"),0,IF(ISNUMBER(J18),J18,IF($T18="Weights",IF(ISNUMBER(Setup!$D$23),Setup!$D$23,0),IF($T18="Nights",IF(ISNUMBER(Setup!$E$23),Setup!$E$23,0),IF(OR($T18="Exact amounts",$T18="Custom units"),0,1)))))) -> 1 | X18: =IF($T18="",0,IF(OR(Setup!$B$24="",Setup!$C$24="No"),0,IF(ISNUMBER(K18),K18,IF($T18="Weights",IF(ISNUMBER(Setup!$D$24),Setup!$D$24,0),IF($T18="Nights",IF(ISNUMBER(Setup!$E$24),Setup!$E$24,0),IF(OR($T18="Exact amounts",$T18="Custom units"),0,1)))))) -> 1 | Y18: =IF($T18="",0,IF(OR(Setup!$B$25="",Setup!$C$25="No"),0,IF(ISNUMBER(L18),L18,IF($T18="Weights",IF(ISNUMBER(Setup!$D$25),Setup!$D$25,0),IF($T18="Nights",IF(ISNUMBER(Setup!$E$25),Setup!$E$25,0),IF(OR($T18="Exact amounts",$T18="Custom units"),0,1)))))) -> 1 | Z18: =IF($T18="",0,IF(OR(Setup!$B$26="",Setup!$C$26="No"),0,IF(ISNUMBER(M18),M18,IF($T18="Weights",IF(ISNUMBER(Setup!$D$26),Setup!$D$26,0),IF($T18="Nights",IF(ISNUMBER(Setup!$E$26),Setup!$E$26,0),IF(OR($T18="Exact amounts",$T18="Custom units"),0,1)))))) -> 0 | AA18: =IF($T18="",0,IF(OR(Setup!$B$27="",Setup!$C$27="No"),0,IF(ISNUMBER(N18),N18,IF($T18="Weights",IF(ISNUMBER(Setup!$D$27),Setup!$D$27,0),IF($T18="Nights",IF(ISNUMBER(Setup!$E$27),Setup!$E$27,0),IF(OR($T18="Exact amounts",$T18="Custom units"),0,1)))))) -> 0 | AB18: =IF($T18="",0,IF(OR(Setup!$B$28="",Setup!$C$28="No"),0,IF(ISNUMBER(O18),O18,IF($T18="Weights",IF(ISNUMBER(Setup!$D$28),Setup!$D$28,0),IF($T18="Nights",IF(ISNUMBER(Setup!$E$28),Setup!$E$28,0),IF(OR($T18="Exact amounts",$T18="Custom units"),0,1)))))) -> 0 | AC18: =IF($T18="",0,IF(OR(Setup!$B$29="",Setup!$C$29="No"),0,IF(ISNUMBER(P18),P18,IF($T18="Weights",IF(ISNUMBER(Setup!$D$29),Setup!$D$29,0),IF($T18="Nights",IF(ISNUMBER(Setup!$E$29),Setup!$E$29,0),IF(OR($T18="Exact amounts",$T18="Custom units"),0,1)))))) -> 0 | AD18: =IF($T18="",0,IF(OR(Setup!$B$30="",Setup!$C$30="No"),0,IF(ISNUMBER(Q18),Q18,IF($T18="Weights",IF(ISNUMBER(Setup!$D$30),Setup!$D$30,0),IF($T18="Nights",IF(ISNUMBER(Setup!$E$30),Setup!$E$30,0),IF(OR($T18="Exact amounts",$T18="Custom units"),0,1)))))) -> 0 | AE18: =IF($T18="",0,SUM($U18:$AD18)) -> 5 | AF18: =IF($AE18<=0,1,$AE18) -> 5 | AG18: =IF(ISNUMBER($E18),$E18,0) -> 745
A19: =IF($T19="","—",ROW()-7) -> 12 | B19: =TODAY()-20 -> 46212 | C19: Lisbon apartment, 7 nights | D19: Ben | E19: 980 | F19: Accommodation | G19: Nights | R19: =IF($T19="","",IF($D19="","Who paid?",IF(SUMPRODUCT((Setup!$B$21:$B$30=$D19)*1)=0,"Payer is not in the member list on Setup",IF($E19="","Amount missing — type the number in column E",IF(NOT(ISNUMBER($E19)),"Amount must be a plain number — no currency symbol, no text",IF(AND($T19="Custom units",$AE19<=0),"Custom units: nobody has units on this row — type a number for at least one person",IF($AE19<=0,"Nobody shares this row — check the person columns H–Q, and the Weight / Nights columns on Setup",IF(AND($T19="Exact amounts",ABS($AE19-$AG19)>0.01),"Exact amounts do not add up to the amount","OK")))))))) -> OK | S19: =IFERROR(IF(OR($T19="",$C$4=""),"—",ROUND($AG19*INDEX($U19:$AD19,1,MATCH($C$4,Setup!$B$21:$B$30,0))/$AF19,2)),"—") -> 245 | T19: =IF(AND($C19="",$D19="",NOT(ISNUMBER($E19))),"",IF($G19="",IF(Setup!$C$17="","Equal",Setup!$C$17),$G19)) -> Nights | U19: =IF($T19="",0,IF(OR(Setup!$B$21="",Setup!$C$21="No"),0,IF(ISNUMBER(H19),H19,IF($T19="Weights",IF(ISNUMBER(Setup!$D$21),Setup!$D$21,0),IF($T19="Nights",IF(ISNUMBER(Setup!$E$21),Setup!$E$21,0),IF(OR($T19="Exact amounts",$T19="Custom units"),0,1)))))) -> 7 | V19: =IF($T19="",0,IF(OR(Setup!$B$22="",Setup!$C$22="No"),0,IF(ISNUMBER(I19),I19,IF($T19="Weights",IF(ISNUMBER(Setup!$D$22),Setup!$D$22,0),IF($T19="Nights",IF(ISNUMBER(Setup!$E$22),Setup!$E$22,0),IF(OR($T19="Exact amounts",$T19="Custom units"),0,1)))))) -> 7 | W19: =IF($T19="",0,IF(OR(Setup!$B$23="",Setup!$C$23="No"),0,IF(ISNUMBER(J19),J19,IF($T19="Weights",IF(ISNUMBER(Setup!$D$23),Setup!$D$23,0),IF($T19="Nights",IF(ISNUMBER(Setup!$E$23),Setup!$E$23,0),IF(OR($T19="Exact amounts",$T19="Custom units"),0,1)))))) -> 3 | X19: =IF($T19="",0,IF(OR(Setup!$B$24="",Setup!$C$24="No"),0,IF(ISNUMBER(K19),K19,IF($T19="Weights",IF(ISNUMBER(Setup!$D$24),Setup!$D$24,0),IF($T19="Nights",IF(ISNUMBER(Setup!$E$24),Setup!$E$24,0),IF(OR($T19="Exact amounts",$T19="Custom units"),0,1)))))) -> 4 | Y19: =IF($T19="",0,IF(OR(Setup!$B$25="",Setup!$C$25="No"),0,IF(ISNUMBER(L19),L19,IF($T19="Weights",IF(ISNUMBER(Setup!$D$25),Setup!$D$25,0),IF($T19="Nights",IF(ISNUMBER(Setup!$E$25),Setup!$E$25,0),IF(OR($T19="Exact amounts",$T19="Custom units"),0,1)))))) -> 7 | Z19: =IF($T19="",0,IF(OR(Setup!$B$26="",Setup!$C$26="No"),0,IF(ISNUMBER(M19),M19,IF($T19="Weights",IF(ISNUMBER(Setup!$D$26),Setup!$D$26,0),IF($T19="Nights",IF(ISNUMBER(Setup!$E$26),Setup!$E$26,0),IF(OR($T19="Exact amounts",$T19="Custom units"),0,1)))))) -> 0 | AA19: =IF($T19="",0,IF(OR(Setup!$B$27="",Setup!$C$27="No"),0,IF(ISNUMBER(N19),N19,IF($T19="Weights",IF(ISNUMBER(Setup!$D$27),Setup!$D$27,0),IF($T19="Nights",IF(ISNUMBER(Setup!$E$27),Setup!$E$27,0),IF(OR($T19="Exact amounts",$T19="Custom units"),0,1)))))) -> 0 | AB19: =IF($T19="",0,IF(OR(Setup!$B$28="",Setup!$C$28="No"),0,IF(ISNUMBER(O19),O19,IF($T19="Weights",IF(ISNUMBER(Setup!$D$28),Setup!$D$28,0),IF($T19="Nights",IF(ISNUMBER(Setup!$E$28),Setup!$E$28,0),IF(OR($T19="Exact amounts",$T19="Custom units"),0,1)))))) -> 0 | AC19: =IF($T19="",0,IF(OR(Setup!$B$29="",Setup!$C$29="No"),0,IF(ISNUMBER(P19),P19,IF($T19="Weights",IF(ISNUMBER(Setup!$D$29),Setup!$D$29,0),IF($T19="Nights",IF(ISNUMBER(Setup!$E$29),Setup!$E$29,0),IF(OR($T19="Exact amounts",$T19="Custom units"),0,1)))))) -> 0 | AD19: =IF($T19="",0,IF(OR(Setup!$B$30="",Setup!$C$30="No"),0,IF(ISNUMBER(Q19),Q19,IF($T19="Weights",IF(ISNUMBER(Setup!$D$30),Setup!$D$30,0),IF($T19="Nights",IF(ISNUMBER(Setup!$E$30),Setup!$E$30,0),IF(OR($T19="Exact amounts",$T19="Custom units"),0,1)))))) -> 0 | AE19: =IF($T19="",0,SUM($U19:$AD19)) -> 28 | AF19: =IF($AE19<=0,1,$AE19) -> 28 | AG19: =IF(ISNUMBER($E19),$E19,0) -> 980
A20: =IF($T20="","—",ROW()-7) -> 13 | B20: =TODAY()-19 -> 46213 | C20: Airport transfer | D20: Chris | E20: 48 | F20: Travel & transport | G20: Equal | R20: =IF($T20="","",IF($D20="","Who paid?",IF(SUMPRODUCT((Setup!$B$21:$B$30=$D20)*1)=0,"Payer is not in the member list on Setup",IF($E20="","Amount missing — type the number in column E",IF(NOT(ISNUMBER($E20)),"Amount must be a plain number — no currency symbol, no text",IF(AND($T20="Custom units",$AE20<=0),"Custom units: nobody has units on this row — type a number for at least one person",IF($AE20<=0,"Nobody shares this row — check the person columns H–Q, and the Weight / Nights columns on Setup",IF(AND($T20="Exact amounts",ABS($AE20-$AG20)>0.01),"Exact amounts do not add up to the amount","OK")))))))) -> OK | S20: =IFERROR(IF(OR($T20="",$C$4=""),"—",ROUND($AG20*INDEX($U20:$AD20,1,MATCH($C$4,Setup!$B$21:$B$30,0))/$AF20,2)),"—") -> 9.6 | T20: =IF(AND($C20="",$D20="",NOT(ISNUMBER($E20))),"",IF($G20="",IF(Setup!$C$17="","Equal",Setup!$C$17),$G20)) -> Equal | U20: =IF($T20="",0,IF(OR(Setup!$B$21="",Setup!$C$21="No"),0,IF(ISNUMBER(H20),H20,IF($T20="Weights",IF(ISNUMBER(Setup!$D$21),Setup!$D$21,0),IF($T20="Nights",IF(ISNUMBER(Setup!$E$21),Setup!$E$21,0),IF(OR($T20="Exact amounts",$T20="Custom units"),0,1)))))) -> 1 | V20: =IF($T20="",0,IF(OR(Setup!$B$22="",Setup!$C$22="No"),0,IF(ISNUMBER(I20),I20,IF($T20="Weights",IF(ISNUMBER(Setup!$D$22),Setup!$D$22,0),IF($T20="Nights",IF(ISNUMBER(Setup!$E$22),Setup!$E$22,0),IF(OR($T20="Exact amounts",$T20="Custom units"),0,1)))))) -> 1 | W20: =IF($T20="",0,IF(OR(Setup!$B$23="",Setup!$C$23="No"),0,IF(ISNUMBER(J20),J20,IF($T20="Weights",IF(ISNUMBER(Setup!$D$23),Setup!$D$23,0),IF($T20="Nights",IF(ISNUMBER(Setup!$E$23),Setup!$E$23,0),IF(OR($T20="Exact amounts",$T20="Custom units"),0,1)))))) -> 1 | X20: =IF($T20="",0,IF(OR(Setup!$B$24="",Setup!$C$24="No"),0,IF(ISNUMBER(K20),K20,IF($T20="Weights",IF(ISNUMBER(Setup!$D$24),Setup!$D$24,0),IF($T20="Nights",IF(ISNUMBER(Setup!$E$24),Setup!$E$24,0),IF(OR($T20="Exact amounts",$T20="Custom units"),0,1)))))) -> 1 | Y20: =IF($T20="",0,IF(OR(Setup!$B$25="",Setup!$C$25="No"),0,IF(ISNUMBER(L20),L20,IF($T20="Weights",IF(ISNUMBER(Setup!$D$25),Setup!$D$25,0),IF($T20="Nights",IF(ISNUMBER(Setup!$E$25),Setup!$E$25,0),IF(OR($T20="Exact amounts",$T20="Custom units"),0,1)))))) -> 1 | Z20: =IF($T20="",0,IF(OR(Setup!$B$26="",Setup!$C$26="No"),0,IF(ISNUMBER(M20),M20,IF($T20="Weights",IF(ISNUMBER(Setup!$D$26),Setup!$D$26,0),IF($T20="Nights",IF(ISNUMBER(Setup!$E$26),Setup!$E$26,0),IF(OR($T20="Exact amounts",$T20="Custom units"),0,1)))))) -> 0 | AA20: =IF($T20="",0,IF(OR(Setup!$B$27="",Setup!$C$27="No"),0,IF(ISNUMBER(N20),N20,IF($T20="Weights",IF(ISNUMBER(Setup!$D$27),Setup!$D$27,0),IF($T20="Nights",IF(ISNUMBER(Setup!$E$27),Setup!$E$27,0),IF(OR($T20="Exact amounts",$T20="Custom units"),0,1)))))) -> 0 | AB20: =IF($T20="",0,IF(OR(Setup!$B$28="",Setup!$C$28="No"),0,IF(ISNUMBER(O20),O20,IF($T20="Weights",IF(ISNUMBER(Setup!$D$28),Setup!$D$28,0),IF($T20="Nights",IF(ISNUMBER(Setup!$E$28),Setup!$E$28,0),IF(OR($T20="Exact amounts",$T20="Custom units"),0,1)))))) -> 0 | AC20: =IF($T20="",0,IF(OR(Setup!$B$29="",Setup!$C$29="No"),0,IF(ISNUMBER(P20),P20,IF($T20="Weights",IF(ISNUMBER(Setup!$D$29),Setup!$D$29,0),IF($T20="Nights",IF(ISNUMBER(Setup!$E$29),Setup!$E$29,0),IF(OR($T20="Exact amounts",$T20="Custom units"),0,1)))))) -> 0 | AD20: =IF($T20="",0,IF(OR(Setup!$B$30="",Setup!$C$30="No"),0,IF(ISNUMBER(Q20),Q20,IF($T20="Weights",IF(ISNUMBER(Setup!$D$30),Setup!$D$30,0),IF($T20="Nights",IF(ISNUMBER(Setup!$E$30),Setup!$E$30,0),IF(OR($T20="Exact amounts",$T20="Custom units"),0,1)))))) -> 0 | AE20: =IF($T20="",0,SUM($U20:$AD20)) -> 5 | AF20: =IF($AE20<=0,1,$AE20) -> 5 | AG20: =IF(ISNUMBER($E20),$E20,0) -> 48
